<mujoco model="a1_description">
    <compiler angle="radian" meshdir="meshes/" autolimits="true"/>
    <size njmax="500" nconmax="100" />
    <option gravity='0 0 -9.806' iterations='50' solver='Newton' timestep='0.002'/>

    <default>
        <geom contype="1" conaffinity="1" friction="0.6 0.3 0.3" rgba="0.5 0.6 0.7 1" margin="0.001" group="0"/>

        <light castshadow="false" diffuse="1 1 1"/>
        <camera fovy="60"/>
        <joint damping="0.01" armature="0.01" frictionloss="0.2" />
        <default class="a1">
          <geom friction="0.6" margin="0.001"/>
          <joint axis="0 1 0" damping="2" armature="0.01" frictionloss="0.2"/>
          <position kp="100" forcerange="-33.5 33.5"/>
          <default class="abduction">
            <joint pos="0 0 0" axis="1 0 0" limited="true" range="-0.802851 0.802851" damping="1"/>
            <position ctrlrange="-0.802851 0.802851"/>
          </default>
          <default class="hip">
            <joint pos="0 0 0" axis="0 1 0" limited="true" range="-1.0472 4.18879"/>
            <position ctrlrange="-1.0472 4.18879"/>
          </default>
          <default class="knee">
            <joint pos="0 0 0" axis="0 1 0" limited="true" range="-2.69653 -0.916298" />
            <position ctrlrange="-2.69653 -0.916298"/>
          </default>
          <default class="visual">
            <geom type="mesh" contype="0" conaffinity="0" group="2" material="dark"/>
          </default>
          <default class="collision">
            <geom group="3" type="capsule"/>
            <default class="hip_left">
              <geom size="0.04 0.04" quat="1 1 0 0" type="cylinder" pos="0 0.055 0"/>
            </default>
            <default class="hip_right">
              <geom size="0.04 0.04" quat="1 1 0 0" type="cylinder" pos="0 -0.055 0"/>
            </default>
            <default class="thigh1">
              <geom size="0.015" fromto="-0.02 0 0 -0.02 0 -0.16"/>
            </default>
            <default class="thigh2">
              <geom size="0.015" fromto="0 0 0 -0.02 0 -0.1"/>
            </default>
            <default class="thigh3">
              <geom size="0.015" fromto="-0.02 0 -0.16 0 0 -0.2"/>
            </default>
            <default class="calf1">
              <geom size="0.01" fromto="0 0 0 0.02 0 -0.13"/>
            </default>
            <default class="calf2">
              <geom size="0.01" fromto="0.02 0 -0.13 0 0 -0.2"/>
            </default>
            <default class="foot">
              <geom type="sphere" size="0.02" pos="0 0 -0.2" priority="1" solimp="0.015 1 0.031"
                  condim="6" friction="0.8 0.02 0.01"/>
            </default>
          </default>
        </default>

    </default>

    <asset>
        <mesh name="trunk" file="trunk.stl" />
        <mesh name="hip" file="hip.stl" />
        <mesh name="thigh_mirror" file="thigh_mirror.stl" />
        <mesh name="calf" file="calf.stl" />
        <mesh name="thigh" file="thigh.stl" />
    </asset>

    <asset>
        <texture name="texplane" type="2d" builtin="checker" rgb1=".2 .3 .4" rgb2=".1 0.15 0.2" width="100" height="100"></texture>
        <material name="MatPlane" reflectance="0.5" texture="texplane" texrepeat="1 1" texuniform="true"></material>
        <texture type="skybox" builtin="gradient" rgb1="1.0 1.0 1.0" rgb2="1.0 1.0 1.0" width="512" height="512"/>
        <texture name="plane" type="2d" builtin="flat" rgb1="1 1 1" rgb2="1 1 1" width="512" height="512" mark="cross" markrgb="0 0 0"/>
        <material name="plane" reflectance="0.0" texture="plane" texrepeat="3 3" texuniform="true"/>
    </asset>

    <visual>
        <rgba com="0.502 1.0 0 0.5" contactforce="0.98 0.4 0.4 0.7" contactpoint="1.0 1.0 0.6 0.4"/>
        <scale com="0.2" forcewidth="0.035" contactwidth="0.10" contactheight="0.04"/>
    </visual>

    <worldbody>
        <light directional="true" diffuse=".8 .8 .8" pos="0 0 10" dir="0 0 -10"/>
        <camera name="track" mode="trackcom" pos="0 -1.3 1.6" xyaxes="1 0 0 0 0.707 0.707"/>
        <geom name="floor" pos="0 0 0" size="100 100 0.125" type="plane" material="MatPlane" condim="3" rgba="0.8 0.9 0.8 1"></geom>

        <body name="trunk" pos="0 0 0.32">
            <inertial pos="0.0127283 0.00218554 0.000514891" quat="0.00186575 0.711506 0.000389649 0.702677" mass="4.714" diaginertia="0.0648213 0.0565803 0.0169323" />
            <joint name="trunk_tx" type="slide" pos="0 0 0" axis="       1        0        0" limited="false" range="-500        500" ref="0" armature="0" damping="0" stiffness="0"></joint>
            <joint name="trunk_tz" type="slide" pos="0 0 0" axis="       0        0        1" limited="false" range="-300        300" ref="0" armature="0" damping="0" stiffness="0"></joint>
            <joint name="trunk_ty" type="slide" pos="0 0 0" axis="       0        1        0" limited="false" range="-100        200" ref="0" armature="0" damping="0" stiffness="0"></joint>
            <joint name="trunk_tilt" type="hinge" pos="0 0 0" axis="       0        0        1" limited="false" range=" -1.5708   1.5708" ref="0" armature="0" damping="0" stiffness="0"></joint>
            <joint name="trunk_list" type="hinge" pos="0 0 0" axis="       1        0        0" limited="false" range=" -1.5708   1.5708" ref="0" armature="0" damping="0" stiffness="0"></joint>
            <joint name="trunk_rotation" type="hinge" pos="0 0 0" axis="       0        1        0" limited="false" range=" -1.5708   1.5708" ref="0" armature="0" damping="0" stiffness="0"></joint>

            <geom type="mesh" contype="0" conaffinity="0" group="1" rgba="0.913725 0.913725 0.847059 1" mesh="trunk" />
            <geom size="0.1335 0.066 0.057" type="box" rgba="0.913725 0.913725 0.847059 0" />
            <geom size="0.0005 0.0005 0.0005" type="box" contype="0" conaffinity="0" group="1" rgba="0.8 0 0 0" />
            <geom size="0.0005 0.0005 0.0005" type="box" rgba="0.8 0 0 0" />
            <site name="imu" pos="0 0 0"/>
            <body name="imu_link">
                <inertial pos="0 0 0" mass="0.001"/>
                <body name="FR_hip" pos="0.183 -0.047 0">
                    <inertial pos="-0.003311 -0.000635 3.1e-05" quat="0.507528 0.506268 0.491507 0.494499" mass="0.697" diaginertia="0.000807752 0.00055293 0.000468983" />
                    <joint name="FR_hip_joint" class="abduction"/>
                    <geom quat="0 1 0 0" type="mesh" contype="0" conaffinity="0" group="1" rgba="0.913725 0.913725 0.847059 1" mesh="hip" />
                    <geom size="0.04 0.04" pos="0 -0.055 0" quat="0.707107 0.707107 0 0" type="cylinder" rgba="0.913725 0.913725 0.847059 0" />
                    <body name="FR_thigh" pos="0 -0.08505 0">
                        <inertial pos="-0.003237 0.022327 -0.027326" quat="0.999125 -0.00256393 -0.0409531 -0.00806091" mass="1.013" diaginertia="0.00555739 0.00513936 0.00133944" />
                        <joint name="FR_thigh_joint" class="hip"/>
                        <geom type="mesh" contype="0" conaffinity="0" group="1" rgba="0.913725 0.913725 0.847059 1" mesh="thigh_mirror" />
                        <geom size="0.1 0.01225 0.017" pos="0 0 -0.1" quat="0.707107 0 0.707107 0" type="box" rgba="0.913725 0.913725 0.847059 0" />
                        <body name="FR_calf" pos="0 0 -0.2">
                            <inertial pos="0.006435 0.0 -0.107388" quat="0.706886 0.017653 0.017653 0.706886" mass="0.166" diaginertia="0.00340344 0.00339393 3.54834e-05" />
                            <joint name="FR_calf_joint" class="knee"/>
                            <geom type="mesh" contype="0" conaffinity="0" group="1" rgba="0 0 0 1" mesh="calf" />
                            <geom size="0.1 0.008 0.008" pos="0 0 -0.1" quat="0.707107 0 0.707107 0" type="box" rgba="0 0 0 0" />
                            <geom size="0.01" pos="0 0 -0.2" contype="0" conaffinity="0" group="1" rgba="0 0 0 1" />
                            <geom size="0.02" pos="0 0 -0.2" rgba="0 0 0 1" />
                            <body name="FR_toe" pos="0 0 -0.3">
                                <inertial mass="0.06" pos="0 0 0"/>
                            </body>
                        </body>
                    </body>
                </body>
                <body name="FL_hip" pos="0.183 0.047 0">
                    <inertial pos="-0.003311 0.000635 3.1e-05" quat="0.494499 0.491507 0.506268 0.507528" mass="0.697" diaginertia="0.000807752 0.00055293 0.000468983" />
                    <joint name="FL_hip_joint" class="abduction"/>
                    <geom type="mesh" contype="0" conaffinity="0" group="1" rgba="0.913725 0.913725 0.847059 1" mesh="hip" />
                    <geom size="0.04 0.04" pos="0 0.055 0" quat="0.707107 0.707107 0 0" type="cylinder" rgba="0.913725 0.913725 0.847059 0" />
                    <body name="FL_thigh" pos="0 0.08505 0">
                        <inertial pos="-0.003237 -0.022327 -0.027326" quat="0.999125 0.00256393 -0.0409531 0.00806091" mass="1.013" diaginertia="0.00555739 0.00513936 0.00133944" />
                        <joint name="FL_thigh_joint" class="hip" />
                        <geom type="mesh" contype="0" conaffinity="0" group="1" rgba="0.913725 0.913725 0.847059 1" mesh="thigh" />
                        <geom size="0.1 0.01225 0.017" pos="0 0 -0.1" quat="0.707107 0 0.707107 0" type="box" rgba="0.913725 0.913725 0.847059 0" />
                        <body name="FL_calf" pos="0 0 -0.2">
                            <inertial pos="0.006435 0.0 -0.107388" quat="0.706886 0.017653 0.017653 0.706886" mass="0.166" diaginertia="0.00340344 0.00339393 3.54834e-05" />
                            <joint name="FL_calf_joint" class="knee" />
                            <geom type="mesh" contype="0" conaffinity="0" group="1" rgba="0 0 0 1" mesh="calf" />
                            <geom size="0.1 0.008 0.008" pos="0 0 -0.1" quat="0.707107 0 0.707107 0" type="box" rgba="0 0 0 0" />
                            <geom size="0.01" pos="0 0 -0.2" contype="0" conaffinity="0" group="1" rgba="0 0 0 1" />
                            <geom size="0.02" pos="0 0 -0.2" rgba="0 0 0 1" />
                            <body name="FL_toe" pos="0 0 -0.3">
                                <inertial mass="0.06" pos="0 0 0"/>
                            </body>
                        </body>
                    </body>
                </body>
                <body name="RR_hip" pos="-0.183 -0.047 0">
                    <inertial pos="0.003311 -0.000635 3.1e-05" quat="0.491507 0.494499 0.507528 0.506268" mass="0.697" diaginertia="0.000807752 0.00055293 0.000468983" />
                    <joint name="RR_hip_joint" class="abduction" />
                    <geom quat="0 0 0 -1" type="mesh" contype="0" conaffinity="0" group="1" rgba="0.913725 0.913725 0.847059 1" mesh="hip" />
                    <geom size="0.04 0.04" pos="0 -0.055 0" quat="0.707107 0.707107 0 0" type="cylinder" rgba="0.913725 0.913725 0.847059 0" />
                    <body name="RR_thigh" pos="0 -0.08505 0">
                        <inertial pos="-0.003237 0.022327 -0.027326" quat="0.999125 -0.00256393 -0.0409531 -0.00806091" mass="1.013" diaginertia="0.00555739 0.00513936 0.00133944" />
                        <joint name="RR_thigh_joint" class="hip" />
                        <geom type="mesh" contype="0" conaffinity="0" group="1" rgba="0.913725 0.913725 0.847059 1" mesh="thigh_mirror" />
                        <geom size="0.1 0.01225 0.017" pos="0 0 -0.1" quat="0.707107 0 0.707107 0" type="box" rgba="0.913725 0.913725 0.847059 0" />
                        <body name="RR_calf" pos="0 0 -0.2">
                            <inertial pos="0.006435 0.0 -0.107388" quat="0.706886 0.017653 0.017653 0.706886" mass="0.166" diaginertia="0.00340344 0.00339393 3.54834e-05" />
                            <joint name="RR_calf_joint" class="knee" />
                            <geom type="mesh" contype="0" conaffinity="0" group="1" rgba="0 0 0 1" mesh="calf" />
                            <geom size="0.1 0.008 0.008" pos="0 0 -0.1" quat="0.707107 0 0.707107 0" type="box" rgba="0 0 0 0" />
                            <geom size="0.01" pos="0 0 -0.2" contype="0" conaffinity="0" group="1" rgba="0 0 0 1" />
                            <geom size="0.02" pos="0 0 -0.2" rgba="0 0 0 1" />
                            <body name="RR_toe" pos="0 0 -0.3">
                                <inertial mass="0.06" pos="0 0 0"/>
                            </body>
                        </body>
                    </body>
                </body>
                <body name="RL_hip" pos="-0.183 0.047 0">
                    <inertial pos="0.003311 0.000635 3.1e-05" quat="0.506268 0.507528 0.494499 0.491507" mass="0.697" diaginertia="0.000807752 0.00055293 0.000468983" />
                    <joint name="RL_hip_joint" class="abduction" />
                    <geom quat="0 0 1 0" type="mesh" contype="0" conaffinity="0" group="1" rgba="0.913725 0.913725 0.847059 1" mesh="hip" />
                    <geom size="0.04 0.04" pos="0 0.055 0" quat="0.707107 0.707107 0 0" type="cylinder" rgba="0.913725 0.913725 0.847059 0" />
                    <body name="RL_thigh" pos="0 0.08505 0">
                        <inertial pos="-0.003237 -0.022327 -0.027326" quat="0.999125 0.00256393 -0.0409531 0.00806091" mass="1.013" diaginertia="0.00555739 0.00513936 0.00133944" />
                        <joint name="RL_thigh_joint" class="hip" />
                        <geom type="mesh" contype="0" conaffinity="0" group="1" rgba="0.913725 0.913725 0.847059 1" mesh="thigh" />
                        <geom size="0.1 0.01225 0.017" pos="0 0 -0.1" quat="0.707107 0 0.707107 0" type="box" rgba="0.913725 0.913725 0.847059 0" />
                        <body name="RL_calf" pos="0 0 -0.2">
                            <inertial pos="0.006435 0.0 -0.107388" quat="0.706886 0.017653 0.017653 0.706886" mass="0.166" diaginertia="0.00340344 0.00339393 3.54834e-05" />
                            <joint name="RL_calf_joint" class="knee" />
                            <geom type="mesh" contype="0" conaffinity="0" group="1" rgba="0 0 0 1" mesh="calf" />
                            <geom size="0.1 0.008 0.008" pos="0 0 -0.1" quat="0.707107 0 0.707107 0" type="box" rgba="0 0 0 0" />
                            <geom size="0.01" pos="0 0 -0.2" contype="0" conaffinity="0" group="1" rgba="0 0 0 1" />
                            <geom size="0.02" pos="0 0 -0.2" rgba="0 0 0 1" />
                            <body name="RL_toe" pos="0 0 -0.3">
                                <inertial mass="0.06" pos="0 0 0"/>
                            </body>
                        </body>
                    </body>
                </body>
            </body>
        </body>
    </worldbody>
    <actuator>
        <position class="abduction" name="FR_hip" joint="FR_hip_joint"/>
        <position class="hip" name="FR_thigh" joint="FR_thigh_joint"/>
        <position class="knee" name="FR_calf" joint="FR_calf_joint"/>
        <position class="abduction" name="FL_hip" joint="FL_hip_joint"/>
        <position class="hip" name="FL_thigh" joint="FL_thigh_joint"/>
        <position class="knee" name="FL_calf" joint="FL_calf_joint"/>
        <position class="abduction" name="RR_hip" joint="RR_hip_joint"/>
        <position class="hip" name="RR_thigh" joint="RR_thigh_joint"/>
        <position class="knee" name="RR_calf" joint="RR_calf_joint"/>
        <position class="abduction" name="RL_hip" joint="RL_hip_joint"/>
        <position class="hip" name="RL_thigh" joint="RL_thigh_joint"/>
        <position class="knee" name="RL_calf" joint="RL_calf_joint"/>
    </actuator>

    <sensor>

        <jointpos name="FR_hip_pos"     joint="FR_hip_joint"/>
        <jointpos name="FR_thigh_pos"   joint="FR_thigh_joint"/>
        <jointpos name="FR_calf_pos"    joint="FR_calf_joint"/>
        <jointpos name="FL_hip_pos"     joint="FL_hip_joint"/>
        <jointpos name="FL_thigh_pos"   joint="FL_thigh_joint"/>
        <jointpos name="FL_calf_pos"    joint="FL_calf_joint"/>
        <jointpos name="RR_hip_pos"     joint="RR_hip_joint"/>
        <jointpos name="RR_thigh_pos"   joint="RR_thigh_joint"/>
        <jointpos name="RR_calf_pos"    joint="RR_calf_joint" />
        <jointpos name="RL_hip_pos"     joint="RL_hip_joint"/>
        <jointpos name="RL_thigh_pos"   joint="RL_thigh_joint"/>
        <jointpos name="RL_calf_pos"    joint="RL_calf_joint"/>

        <jointvel name="FR_hip_vel"     joint="FR_hip_joint"/>
        <jointvel name="FR_thigh_vel"   joint="FR_thigh_joint"/>
        <jointvel name="FR_calf_vel"    joint="FR_calf_joint"/>
        <jointvel name="FL_hip_vel"     joint="FL_hip_joint"/>
        <jointvel name="FL_thigh_vel"   joint="FL_thigh_joint"/>
        <jointvel name="FL_calf_vel"    joint="FL_calf_joint"/>
        <jointvel name="RR_hip_vel"     joint="RR_hip_joint"/>
        <jointvel name="RR_thigh_vel"   joint="RR_thigh_joint"/>
        <jointvel name="RR_calf_vel"    joint="RR_calf_joint" />
        <jointvel name="RL_hip_vel"     joint="RL_hip_joint"/>
        <jointvel name="RL_thigh_vel"   joint="RL_thigh_joint"/>
        <jointvel name="RL_calf_vel"    joint="RL_calf_joint"/>

        <accelerometer name="Body_Acc" site="imu"/>

        <gyro name="Body_Gyro" site="imu"/>

        <framepos name="Body_Pos" objtype="site" objname="imu"/>

        <framequat name="Body_Quat" objtype="site" objname="imu"/>


    </sensor>

</mujoco>
