<?xml version="1.0" encoding="utf-8"?>
<mujoco model="FullBodyModel_MuscleActuatedLowerLimb_TorqueActuatedUpperBody">
  <compiler inertiafromgeom="auto" angle="radian" balanceinertia="true" boundmass="0.001" boundinertia="0.001"></compiler>
<!--  <size njmax="8000" nconmax="4000"/>-->
  <default>
    <joint limited="true" damping="0.01" armature="0.01" stiffness="0"></joint>
    <geom contype="1" conaffinity="1" condim="3" rgba="0.8 0.6 .4 1" margin="0.001" solref=".02 1" solimp=".8 .8 .01" material="geom"></geom>
    <site size="0.001"></site>
    <tendon width="0.001" rgba=".95 .3 .3 1" limited="false"></tendon>
    <muscle scale="400" ctrllimited="true"></muscle>
    <motor ctrlrange="-1.0 1.0" ctrllimited="true"></motor>
  </default>
  <option  integrator="RK4" iterations="50" solver="Newton"  timestep="0.001">
    <flag energy="enable"></flag>
  </option>
  <size njmax="1000" nconmax="400" nuser_jnt="1"></size>
  <visual>
    <map fogstart="3" fogend="5" force="0.1"></map>
    <quality shadowsize="2048"></quality>
  </visual>
  <worldbody>
    <geom name="floor" pos="0 0 0" size="100 100 0.125" type="plane" material="MatPlane" condim="3" rgba="0.8 0.9 0.8 1" friction="1 .1 .1"></geom>
    <light cutoff="100" diffuse="1 1 1" dir="-0 0 -1.3" directional="true" exponent="1" pos="0 0 1.3" specular=".1 .1 .1" castshadow="false"/>
    <body name="pelvis" pos="       0        0        0.95" quat="0.7071067811865475 0.7071067811865475 0.0 0.0">
      <camera name="track" mode="trackcom" pos="0 0 3" xyaxes="1 0 0 0 1 0"/>
<!--      <light cutoff="100" diffuse="1 1 1" dir="-0 0 -1.3" directional="true" exponent="1" pos="0 0 1.3" specular=".1 .1 .1"/>-->
      <geom name="r_pelvis" type="mesh" mesh="r_pelvis"></geom>
      <geom name="l_pelvis" type="mesh" mesh="l_pelvis"></geom>
      <geom name="sacrum" type="mesh" mesh="sacrum"></geom>
      <inertial pos=" -0.0707        0        0" mass="11.777" fullinertia="  0.1028   0.0871   0.0579        0        0        0"></inertial>
      <site name="addbrev_r-P1" pos="-0.0191 -0.094 0.0154"></site>
      <site name="addlong_r-P1" pos="-0.00758 -0.0889 0.01888"></site>
      <site name="addmagDist_r-P1" pos="-0.07404 -0.12767 0.03982"></site>
      <site name="addmagIsch_r-P1" pos="-0.08962 -0.12976 0.04171"></site>
      <site name="addmagMid_r-P1" pos="-0.05266 -0.12075 0.02854"></site>
      <site name="addmagProx_r-P1" pos="-0.03098 -0.10755 0.01365"></site>
      <site name="bflh_r-P1" pos="-0.104 -0.1191 0.0586"></site>
      <site name="glmax1_r-P1" pos="-0.1231 0.0345 0.0563"></site>
      <site name="glmax1_r-P2" pos="-0.1257 -0.0242 0.0779"></site>
      <site name="glmax2_r-P1" pos="-0.1317 0.0087 0.0462"></site>
      <site name="glmax2_r-P2" pos="-0.1344 -0.0609 0.0813"></site>
      <site name="glmax3_r-P1" pos="-0.13 -0.0525 0.009"></site>
      <site name="glmax3_r-P2" pos="-0.1273 -0.1263 0.0435"></site>
      <site name="glmed1_r-P1" pos="-0.0445 0.0245 0.1172"></site>
      <site name="glmed2_r-P1" pos="-0.085 0.0316 0.0675"></site>
      <site name="glmed3_r-P1" pos="-0.1152 -0.0073 0.0526"></site>
      <site name="glmin1_r-P1" pos="-0.0464 -0.0149 0.1042"></site>
      <site name="glmin2_r-P1" pos="-0.0616 -0.0142 0.0971"></site>
      <site name="glmin3_r-P1" pos="-0.0789 -0.0155 0.0798"></site>
      <site name="grac_r-P1" pos="-0.04736 -0.12932 0.02456"></site>
      <site name="iliacus_r-P1" pos="-0.0605 0.0309 0.0843"></site>
      <site name="iliacus_r-P2" pos="-0.0135 -0.0557 0.0756"></site>
      <site name="piri_r-P1" pos="-0.10181 -0.00653 0.01351"></site>
      <site name="piri_r-P2" pos="-0.10202 -0.03066 0.06092"></site>
      <site name="psoas_r-P1" pos="-0.0606 0.062 0.039"></site>
      <site name="psoas_r-P2" pos="-0.0205 -0.0654 0.0656"></site>
      <site name="recfem_r-P1" pos="-0.024 -0.0388 0.0933"></site>
      <site name="sart_r-P1" pos="-0.0195 -0.0156 0.1056"></site>
      <site name="semimem_r-P1" pos="-0.0987 -0.114 0.0614"></site>
      <site name="semiten_r-P1" pos="-0.1038 -0.1253 0.0515"></site>
      <site name="tfl_r-P1" pos="-0.0311 0.0214 0.1241"></site>
      <site name="addbrev_l-P1" pos="-0.0191 -0.094 -0.0154"></site>
      <site name="addlong_l-P1" pos="-0.00758 -0.0889 -0.01888"></site>
      <site name="addmagDist_l-P1" pos="-0.07404 -0.12767 -0.03982"></site>
      <site name="addmagIsch_l-P1" pos="-0.08962 -0.12976 -0.04171"></site>
      <site name="addmagMid_l-P1" pos="-0.05266 -0.12075 -0.02854"></site>
      <site name="addmagProx_l-P1" pos="-0.03098 -0.10755 -0.01365"></site>
      <site name="bflh_l-P1" pos="-0.104 -0.1191 -0.0586"></site>
      <site name="glmax1_l-P1" pos="-0.1231 0.0345 -0.0563"></site>
      <site name="glmax1_l-P2" pos="-0.1257 -0.0242 -0.0779"></site>
      <site name="glmax2_l-P1" pos="-0.1317 0.0087 -0.0462"></site>
      <site name="glmax2_l-P2" pos="-0.1344 -0.0609 -0.0813"></site>
      <site name="glmax3_l-P1" pos="-0.13 -0.0525 -0.009"></site>
      <site name="glmax3_l-P2" pos="-0.1273 -0.1263 -0.0435"></site>
      <site name="glmed1_l-P1" pos="-0.0445 0.0245 -0.1172"></site>
      <site name="glmed2_l-P1" pos="-0.085 0.0316 -0.0675"></site>
      <site name="glmed3_l-P1" pos="-0.1152 -0.0073 -0.0526"></site>
      <site name="glmin1_l-P1" pos="-0.0464 -0.0149 -0.1042"></site>
      <site name="glmin2_l-P1" pos="-0.0616 -0.0142 -0.0971"></site>
      <site name="glmin3_l-P1" pos="-0.0789 -0.0155 -0.0798"></site>
      <site name="grac_l-P1" pos="-0.04736 -0.12932 -0.02456"></site>
      <site name="iliacus_l-P1" pos="-0.0605 0.0309 -0.0843"></site>
      <site name="iliacus_l-P2" pos="-0.0135 -0.0557 -0.0756"></site>
      <site name="piri_l-P1" pos="-0.10181 -0.00653 -0.01351"></site>
      <site name="piri_l-P2" pos="-0.10202 -0.03066 -0.06092"></site>
      <site name="psoas_l-P1" pos="-0.0606 0.062 -0.039"></site>
      <site name="psoas_l-P2" pos="-0.0205 -0.0654 -0.0656"></site>
      <site name="recfem_l-P1" pos="-0.024 -0.0388 -0.0933"></site>
      <site name="sart_l-P1" pos="-0.0195 -0.0156 -0.1056"></site>
      <site name="semimem_l-P1" pos="-0.0987 -0.114 -0.0614"></site>
      <site name="semiten_l-P1" pos="-0.1038 -0.1253 -0.0515"></site>
      <site name="tfl_l-P1" pos="-0.0311 0.0214 -0.1241"></site>
      <joint name="pelvis_tx" type="slide" pos="0 0 0" axis="       1        0        0" limited="false" range="-500 500" ref="0" armature="0" damping="0.0" stiffness="0"></joint>
      <joint name="pelvis_tz" type="slide" pos="0 0 0" axis="       0        0        1" limited="false" range="-300 300" ref="0" armature="0" damping="0.0" stiffness="0"></joint>
      <joint name="pelvis_ty" type="slide" pos="0 0 0" axis="       0        1        0" limited="false" range="-100 200" ref="0" armature="0" damping="0.0" stiffness="0"></joint>
      <joint name="pelvis_tilt" type="hinge" pos="0 0 0" axis="       0        0        1" limited="false" range=" -1.5708   1.5708" ref="0" armature="0" damping="0.0" stiffness="0"></joint>
      <joint name="pelvis_list" type="hinge" pos="0 0 0" axis="       1        0        0" limited="false" range=" -1.5708   1.5708" ref="0" armature="0" damping="0.0" stiffness="0"></joint>
      <joint name="pelvis_rotation" type="hinge" pos="0 0 0" axis="       0        1        0" limited="false" range=" -1.5708   1.5708" ref="0" armature="0" damping="0.0" stiffness="0"></joint>
      <body name="femur_r" pos="-0.056276 -0.07849  0.07726" quat="1.0 0.0 0.0 0.0">
        <geom name="r_femur" type="mesh" mesh="r_femur"></geom>
        <inertial pos="       0    -0.17        0" mass="9.3014" fullinertia="  0.1339   0.0351   0.1412        0        0        0"></inertial>
        <site name="addbrev_r-P2" pos="-0.002 -0.118 0.0249"></site>
        <site name="addlong_r-P2" pos="0.01126 -0.23937 0.01583"></site>
        <site name="addmagDist_r-P2" pos="0.01125 -0.2625 0.0193"></site>
        <site name="addmagIsch_r-P2" pos="0.00481 -0.38797 -0.03273"></site>
        <site name="addmagMid_r-P2" pos="0.00242 -0.1624 0.02922"></site>
        <site name="addmagProx_r-P2" pos="-0.01527 -0.07886 0.03202"></site>
        <site name="bfsh_r-P1" pos="0.005 -0.2111 0.0234"></site>
        <site name="gaslat_r-P1" pos="-0.003 -0.3814 0.0277"></site>
        <site name="gasmed_r-P1" pos="0.008 -0.3788 -0.0208"></site>
        <site name="glmax1_r-P3" pos="-0.0444 -0.0326 0.0302"></site>
        <site name="glmax1_r-P4" pos="-0.0277 -0.0566 0.047"></site>
        <site name="glmax2_r-P3" pos="-0.045 -0.0584 0.0252"></site>
        <site name="glmax2_r-P4" pos="-0.0156 -0.1016 0.0419"></site>
        <site name="glmax3_r-P3" pos="-0.0281 -0.1125 0.0094"></site>
        <site name="glmax3_r-P4" pos="-0.006 -0.1419 0.0411"></site>
        <site name="glmed1_r-P2" pos="-0.0218 -0.0117 0.0555"></site>
        <site name="glmed2_r-P2" pos="-0.0258 -0.0058 0.0527"></site>
        <site name="glmed3_r-P2" pos="-0.0309 -0.0047 0.0518"></site>
        <site name="glmin1_r-P2" pos="-0.0072 -0.0104 0.056"></site>
        <site name="glmin2_r-P2" pos="-0.0096 -0.0104 0.056"></site>
        <site name="glmin3_r-P2" pos="-0.0135 -0.0083 0.055"></site>
        <site name="iliacus_r-P3" pos="-0.0023 -0.0565 0.0139"></site>
        <site name="iliacus_r-P4" pos="-0.0122 -0.0637 0.0196"></site>
        <site name="piri_r-P3" pos="-0.0148 -0.0036 0.0437"></site>
        <site name="psoas_r-P3" pos="-0.0132 -0.0467 0.0046"></site>
        <site name="psoas_r-P4" pos="-0.0235 -0.0524 0.0088"></site>
        <site name="sart_r-P2" pos="-0.003 -0.3568 -0.0421"></site>
        <site name="tfl_r-P2" pos="0.0294 -0.0995 0.0597"></site>
        <site name="tfl_r-P3" pos="0.0107 -0.405 0.0324"></site>
        <site name="vasint_r-P1" pos="0.029 -0.1924 0.031"></site>
        <site name="vasint_r-P2" pos="0.0335 -0.2084 0.0285"></site>
        <site name="vaslat_r-P1" pos="0.0048 -0.1854 0.0349"></site>
        <site name="vaslat_r-P2" pos="0.0269 -0.2591 0.0409"></site>
        <site name="vasmed_r-P1" pos="0.014 -0.2099 0.0188"></site>
        <site name="vasmed_r-P2" pos="0.0356 -0.2769 0.0009"></site>
        <joint name="hip_flexion_r" type="hinge" pos="0 0 0" axis="       0        0        1" limited="true" range="-0.523599   2.0944" ref="0"></joint>
        <joint name="hip_adduction_r" type="hinge" pos="0 0 0" axis="       1        0        0" limited="true" range="-0.872665 0.523599" ref="0"></joint>
        <joint name="hip_rotation_r" type="hinge" pos="0 0 0" axis="       0        1        0" limited="true" range="-0.698132 0.698132" ref="0"></joint>
        <body name="tibia_r" pos="-4.6e-07 -0.404425 -0.00126526" quat="1.0 7.240636975890137e-18 -9.456205735995121e-17 -2.960068750797159e-20">
          <geom name="r_tibia" type="mesh" mesh="r_tibia"></geom>
          <geom name="r_fibula" type="mesh" mesh="r_fibula"></geom>
          <inertial pos="       0  -0.1867        0" mass="3.7075" fullinertia="  0.0504   0.0051   0.0511        0        0        0"></inertial>
          <site name="bflh_r-P2" pos="-0.0337 -0.035 0.0253"></site>
          <site name="bflh_r-P3" pos="-0.0287 -0.0455 0.0303"></site>
          <site name="bfsh_r-P2" pos="-0.0301 -0.0419 0.0318"></site>
          <site name="edl_r-P1" pos="-0.016 -0.1157 0.0205"></site>
          <site name="edl_r-P2" pos="0.0164 -0.376 0.0112"></site>
          <site name="ehl_r-P1" pos="-0.014 -0.155 0.0189"></site>
          <site name="ehl_r-P2" pos="0.0071 -0.2909 0.0164"></site>
          <site name="ehl_r-P3" pos="0.02 -0.3693 -0.0028"></site>
          <site name="fdl_r-P1" pos="-0.0023 -0.1832 -0.0018"></site>
          <site name="fdl_r-P2" pos="-0.0176 -0.3645 -0.0124"></site>
          <site name="fhl_r-P1" pos="-0.031 -0.2163 0.02"></site>
          <site name="fhl_r-P2" pos="-0.0242 -0.3671 -0.0076"></site>
          <site name="grac_r-P2" pos="-0.01842 -0.04755 -0.02961"></site>
          <site name="grac_r-P3" pos="0.00178 -0.06962 -0.01573"></site>
          <site name="perbrev_r-P1" pos="-0.0243 -0.2532 0.0251"></site>
          <site name="perbrev_r-P2" pos="-0.0339 -0.3893 0.0249"></site>
          <site name="perbrev_r-P3" pos="-0.0285 -0.4004 0.0255"></site>
          <site name="perlong_r-P1" pos="-0.02 -0.1373 0.0282"></site>
          <site name="perlong_r-P2" pos="-0.0317 -0.39 0.0237"></site>
          <site name="perlong_r-P3" pos="-0.0272 -0.4014 0.024"></site>
          <site name="recfem_r-P5" pos="0.0326 -0.06312 -0.00047"></site>
          <site name="sart_r-P3" pos="-0.0251 -0.0401 -0.0365"></site>
          <site name="sart_r-P4" pos="-0.0159 -0.0599 -0.0264"></site>
          <site name="sart_r-P5" pos="0.0136 -0.081 -0.0026"></site>
          <site name="semimem_r-P2" pos="-0.029 -0.0417 -0.0196"></site>
          <site name="semiten_r-P2" pos="-0.0312 -0.0508 -0.0229"></site>
          <site name="semiten_r-P3" pos="0.0019 -0.0773 -0.0117"></site>
          <site name="soleus_r-P1" pos="-0.0076 -0.0916 0.0098"></site>
          <site name="tfl_r-P4" pos="0.0108 -0.041 0.0346"></site>
          <site name="tibant_r-P1" pos="0.0154 -0.1312 0.0162"></site>
          <site name="tibant_r-P2" pos="0.0251 -0.1906 0.0128"></site>
          <site name="tibant_r-P3" pos="0.0233 -0.3659 -0.0132"></site>
          <site name="tibpost_r-P1" pos="-0.0041 -0.1304 0.0103"></site>
          <site name="tibpost_r-P2" pos="-0.0164 -0.3655 -0.0175"></site>
          <site name="vasint_r-P5" pos="0.03257 -0.0632 0.00043"></site>
          <site name="vaslat_r-P5" pos="0.03254 -0.06338 0.00511"></site>
          <site name="vasmed_r-P5" pos="0.0319 -0.06357 -0.00678"></site>
          <joint name="knee_angle_r_translation2" type="slide" pos="0 0 0" axis="0.992246 0.123982 -0.00878916" limited="true" range="7.69254e-11 0.006792" ref="0"></joint>
          <joint name="knee_angle_r_translation1" type="slide" pos="0 0 0" axis="-0.124293 0.989762 -0.0701648" limited="true" range="9.53733e-08 0.00159883" ref="0"></joint>
          <joint name="knee_angle_r" type="hinge" pos="0 0 0" axis="-3.98373e-10 -0.0707131 -0.997497" limited="true" range="       0   2.0944" ref="0"></joint>
          <joint name="knee_angle_r_rotation2" type="hinge" pos="0 0 0" axis="0.992246 0.123982 -0.00878916" limited="true" range="-0.00167821 0.0335354" ref="0"></joint>
          <joint name="knee_angle_r_rotation3" type="hinge" pos="0 0 0" axis="-0.124293 0.989762 -0.0701648" limited="true" range="1.08939e-08 0.262788" ref="0"></joint>
          <body name="talus_r" pos="   -0.01     -0.4        0" quat="1.0 -6.036754011562992e-18 1.5193252867388614e-18 -2.498419531737724e-19">
            <geom name="r_talus" type="mesh" mesh="r_talus"></geom>
            <inertial pos="       0        0        0" mass="0.1" fullinertia="   0.001    0.001    0.001        0        0        0"></inertial>
            <joint name="ankle_angle_r" type="hinge" pos="0 0 0" axis="-0.105014 -0.174022 0.979126" limited="true" range="-0.698132 0.523599" ref="0"></joint>
            <body name="calcn_r" pos="-0.04877 -0.04195  0.00792" quat="1.0 -5.320429553087796e-19 1.609289071159989e-17 -2.1848634538867752e-17">
              <geom name="r_foot" type="mesh" mesh="r_foot"></geom>
              <inertial pos="     0.1     0.03        0" mass="1.25" fullinertia="  0.0014   0.0039   0.0041        0        0        0"></inertial>
              <site name="edl_r-P3" pos="0.0919 0.036 0.0008"></site>
              <site name="edl_r-P4" pos="0.1616 0.0055 0.013"></site>
              <site name="ehl_r-P4" pos="0.097 0.0389 -0.0211"></site>
              <site name="ehl_r-P5" pos="0.1293 0.0309 -0.0257"></site>
              <site name="ehl_r-P6" pos="0.1734 0.0139 -0.028"></site>
              <site name="fdl_r-P3" pos="0.0436 0.0315 -0.028"></site>
              <site name="fdl_r-P4" pos="0.0708 0.0176 -0.0263"></site>
              <site name="fdl_r-P5" pos="0.1658 -0.0081 0.0116"></site>
              <site name="fhl_r-P3" pos="0.0374 0.0276 -0.0241"></site>
              <site name="fhl_r-P4" pos="0.1038 0.0068 -0.0256"></site>
              <site name="fhl_r-P5" pos="0.1726 -0.0053 -0.0269"></site>
              <site name="gaslat_r-P2" pos="0.0044 0.031 -0.0053"></site>
              <site name="gasmed_r-P2" pos="0.0044 0.031 -0.0053"></site>
              <site name="perbrev_r-P4" pos="0.0471 0.027 0.0233"></site>
              <site name="perbrev_r-P5" pos="0.0677 0.0219 0.0343"></site>
              <site name="perlong_r-P4" pos="0.0438 0.023 0.0221"></site>
              <site name="perlong_r-P5" pos="0.0681 0.0106 0.0284"></site>
              <site name="perlong_r-P6" pos="0.0852 0.0069 0.0118"></site>
              <site name="perlong_r-P7" pos="0.1203 0.0085 -0.0184"></site>
              <site name="soleus_r-P2" pos="0.0044 0.031 -0.0053"></site>
              <site name="tibant_r-P4" pos="0.1166 0.0178 -0.0305"></site>
              <site name="tibpost_r-P3" pos="0.0417 0.0334 -0.0286"></site>
              <site name="tibpost_r-P4" pos="0.0772 0.0159 -0.0281"></site>
              <joint name="subtalar_angle_r" type="hinge" pos="0 0 0" axis=" 0.78718 0.604747 -0.120949" limited="true" range="-0.349066 0.349066" ref="0"></joint>
              <body name="toes_r" pos="  0.1788   -0.002  0.00108" quat="1.0 1.314867274624753e-31 -2.6810890689525335e-17 -3.939849802505862e-32">
                <geom name="r_bofoot" type="mesh" mesh="r_bofoot"></geom>
                <inertial pos="  0.0346    0.006  -0.0175" mass="0.2166" fullinertia="  0.0001   0.0002    0.001        0        0        0"></inertial>
                <site name="edl_r-P5" pos="0.0003 0.0047 0.0153"></site>
                <site name="edl_r-P6" pos="0.0443 -0.0004 0.025"></site>
                <site name="ehl_r-P7" pos="0.0298 0.0041 -0.0245"></site>
                <site name="ehl_r-P8" pos="0.0563 0.0034 -0.0186"></site>
                <site name="fdl_r-P6" pos="-0.0019 -0.0078 0.0147"></site>
                <site name="fdl_r-P7" pos="0.0285 -0.0071 0.0215"></site>
                <site name="fdl_r-P8" pos="0.0441 -0.006 0.0242"></site>
                <site name="fhl_r-P6" pos="0.0155 -0.0064 -0.0265"></site>
                <site name="fhl_r-P7" pos="0.0562 -0.0102 -0.0181"></site>
                <joint name="mtp_angle_r" type="hinge" pos="0 0 0" axis="0.580954 2.6299e-15 -0.813936" limited="true" range="-0.523599 0.523599" ref="0"></joint>
              </body>
            </body>
          </body>
        </body>
        <body name="patella_r" pos="-0.00809 -0.40796        0" quat="1.0 0.0 0.0 0.0">
          <geom name="r_patella" type="mesh" mesh="r_patella"></geom>
          <inertial pos="  0.0018   0.0264        0" mass="0.0862" fullinertia="2.87e-06 1.311e-05 1.311e-05        0        0        0"></inertial>
          <site name="recfem_r-P2" pos="0.01 0.049 0.0007"></site>
          <site name="recfem_r-P3" pos="0.0121 0.0437 -0.001"></site>
          <site name="recfem_r-P4" pos="0.005 0.00247 3e-005"></site>
          <site name="vasint_r-P3" pos="0.0058 0.048 -0.0006"></site>
          <site name="vasint_r-P4" pos="0.005 0.00247 -0.00039"></site>
          <site name="vaslat_r-P3" pos="0.0103 0.0423 0.0141"></site>
          <site name="vaslat_r-P4" pos="0.005 0.00247 0.00733"></site>
          <site name="vasmed_r-P3" pos="0.0063 0.0445 -0.017"></site>
          <site name="vasmed_r-P4" pos="0.005 0.00247 -0.0085"></site>
          <joint name="knee_angle_r_beta_translation2" type="slide" pos="0 0 0" axis="       0        1        0" limited="true" range="-0.0408267 -0.0108281" ref="0"></joint>
          <joint name="knee_angle_r_beta_translation1" type="slide" pos="0 0 0" axis="       1        0        0" limited="true" range="-0.0227731 0.0524192" ref="0"></joint>
          <joint name="knee_angle_r_beta_rotation1" type="hinge" pos="0 0 0" axis="       0        0        1" limited="true" range="-1.79241 0.010506" ref="0"></joint>
        </body>
      </body>
      <body name="femur_l" pos="-0.056276 -0.07849 -0.07726" quat="1.0 0.0 0.0 0.0">
        <geom name="l_femur" type="mesh" mesh="l_femur"></geom>
        <inertial pos="       0    -0.17        0" mass="9.3014" fullinertia="  0.1339   0.0351   0.1412        0        0        0"></inertial>
        <site name="addbrev_l-P2" pos="-0.002 -0.118 -0.0249"></site>
        <site name="addlong_l-P2" pos="0.01126 -0.23937 -0.01583"></site>
        <site name="addmagDist_l-P2" pos="0.01125 -0.2625 -0.0193"></site>
        <site name="addmagIsch_l-P2" pos="0.00481 -0.38797 0.03273"></site>
        <site name="addmagMid_l-P2" pos="0.00242 -0.1624 -0.02922"></site>
        <site name="addmagProx_l-P2" pos="-0.01527 -0.07886 -0.03202"></site>
        <site name="bfsh_l-P1" pos="0.005 -0.2111 -0.0234"></site>
        <site name="gaslat_l-P1" pos="-0.003 -0.3814 -0.0277"></site>
        <site name="gasmed_l-P1" pos="0.008 -0.3788 0.0208"></site>
        <site name="glmax1_l-P3" pos="-0.0444 -0.0326 -0.0302"></site>
        <site name="glmax1_l-P4" pos="-0.0277 -0.0566 -0.047"></site>
        <site name="glmax2_l-P3" pos="-0.045 -0.0584 -0.0252"></site>
        <site name="glmax2_l-P4" pos="-0.0156 -0.1016 -0.0419"></site>
        <site name="glmax3_l-P3" pos="-0.0281 -0.1125 -0.0094"></site>
        <site name="glmax3_l-P4" pos="-0.006 -0.1419 -0.0411"></site>
        <site name="glmed1_l-P2" pos="-0.0218 -0.0117 -0.0555"></site>
        <site name="glmed2_l-P2" pos="-0.0258 -0.0058 -0.0527"></site>
        <site name="glmed3_l-P2" pos="-0.0309 -0.0047 -0.0518"></site>
        <site name="glmin1_l-P2" pos="-0.0072 -0.0104 -0.056"></site>
        <site name="glmin2_l-P2" pos="-0.0096 -0.0104 -0.056"></site>
        <site name="glmin3_l-P2" pos="-0.0135 -0.0083 -0.055"></site>
        <site name="iliacus_l-P3" pos="-0.0023 -0.0565 -0.0139"></site>
        <site name="iliacus_l-P4" pos="-0.0122 -0.0637 -0.0196"></site>
        <site name="piri_l-P3" pos="-0.0148 -0.0036 -0.0437"></site>
        <site name="psoas_l-P3" pos="-0.0132 -0.0467 -0.0046"></site>
        <site name="psoas_l-P4" pos="-0.0235 -0.0524 -0.0088"></site>
        <site name="sart_l-P2" pos="-0.003 -0.3568 0.0421"></site>
        <site name="tfl_l-P2" pos="0.0294 -0.0995 -0.0597"></site>
        <site name="tfl_l-P3" pos="0.0107 -0.405 -0.0324"></site>
        <site name="vasint_l-P1" pos="0.029 -0.1924 -0.031"></site>
        <site name="vasint_l-P2" pos="0.0335 -0.2084 -0.0285"></site>
        <site name="vaslat_l-P1" pos="0.0048 -0.1854 -0.0349"></site>
        <site name="vaslat_l-P2" pos="0.0269 -0.2591 -0.0409"></site>
        <site name="vasmed_l-P1" pos="0.014 -0.2099 -0.0188"></site>
        <site name="vasmed_l-P2" pos="0.0356 -0.2769 -0.0009"></site>
        <joint name="hip_flexion_l" type="hinge" pos="0 0 0" axis="       0        0        1" limited="true" range="-0.523599   2.0944" ref="0"></joint>
        <joint name="hip_adduction_l" type="hinge" pos="0 0 0" axis="       1        0        0" limited="true" range="-0.872665 0.523599" ref="0"></joint>
        <joint name="hip_rotation_l" type="hinge" pos="0 0 0" axis="       0        1        0" limited="true" range="-0.698132 0.698132" ref="0"></joint>
        <body name="tibia_l" pos="-4.6e-07 -0.404425 0.00126526" quat="1.0 -7.240636975890137e-18 9.456205735995121e-17 -2.960068750797159e-20">
          <geom name="l_tibia" type="mesh" mesh="l_tibia"></geom>
          <geom name="l_fibula" type="mesh" mesh="l_fibula"></geom>
          <inertial pos="       0  -0.1867        0" mass="3.7075" fullinertia="  0.0504   0.0051   0.0511        0        0        0"></inertial>
          <site name="bflh_l-P2" pos="-0.0337 -0.035 -0.0253"></site>
          <site name="bflh_l-P3" pos="-0.0287 -0.0455 -0.0303"></site>
          <site name="bfsh_l-P2" pos="-0.0301 -0.0419 -0.0318"></site>
          <site name="edl_l-P1" pos="-0.016 -0.1157 -0.0205"></site>
          <site name="edl_l-P2" pos="0.0164 -0.376 -0.0112"></site>
          <site name="ehl_l-P1" pos="-0.014 -0.155 -0.0189"></site>
          <site name="ehl_l-P2" pos="0.0071 -0.2909 -0.0164"></site>
          <site name="ehl_l-P3" pos="0.02 -0.3693 0.0028"></site>
          <site name="fdl_l-P1" pos="-0.0023 -0.1832 0.0018"></site>
          <site name="fdl_l-P2" pos="-0.0176 -0.3645 0.0124"></site>
          <site name="fhl_l-P1" pos="-0.031 -0.2163 -0.02"></site>
          <site name="fhl_l-P2" pos="-0.0242 -0.3671 0.0076"></site>
          <site name="grac_l-P2" pos="-0.01842 -0.04755 0.02961"></site>
          <site name="grac_l-P3" pos="0.00178 -0.06962 0.01573"></site>
          <site name="perbrev_l-P1" pos="-0.0243 -0.2532 -0.0251"></site>
          <site name="perbrev_l-P2" pos="-0.0339 -0.3893 -0.0249"></site>
          <site name="perbrev_l-P3" pos="-0.0285 -0.4004 -0.0255"></site>
          <site name="perlong_l-P1" pos="-0.02 -0.1373 -0.0282"></site>
          <site name="perlong_l-P2" pos="-0.0317 -0.39 -0.0237"></site>
          <site name="perlong_l-P3" pos="-0.0272 -0.4014 -0.024"></site>
          <site name="recfem_l-P5" pos="0.0326 -0.06312 0.00047"></site>
          <site name="sart_l-P3" pos="-0.0251 -0.0401 0.0365"></site>
          <site name="sart_l-P4" pos="-0.0159 -0.0599 0.0264"></site>
          <site name="sart_l-P5" pos="0.0136 -0.081 0.0026"></site>
          <site name="semimem_l-P2" pos="-0.029 -0.0417 0.0196"></site>
          <site name="semiten_l-P2" pos="-0.0312 -0.0508 0.0229"></site>
          <site name="semiten_l-P3" pos="0.0019 -0.0773 0.0117"></site>
          <site name="soleus_l-P1" pos="-0.0076 -0.0916 -0.0098"></site>
          <site name="tfl_l-P4" pos="0.0108 -0.041 -0.0346"></site>
          <site name="tibant_l-P1" pos="0.0154 -0.1312 -0.0162"></site>
          <site name="tibant_l-P2" pos="0.0251 -0.1906 -0.0128"></site>
          <site name="tibant_l-P3" pos="0.0233 -0.3659 0.0132"></site>
          <site name="tibpost_l-P1" pos="-0.0041 -0.1304 -0.0103"></site>
          <site name="tibpost_l-P2" pos="-0.0164 -0.3655 0.0175"></site>
          <site name="vasint_l-P5" pos="0.03257 -0.0632 -0.00043"></site>
          <site name="vaslat_l-P5" pos="0.03254 -0.06338 -0.00511"></site>
          <site name="vasmed_l-P5" pos="0.0319 -0.06357 0.00678"></site>
          <joint name="knee_angle_l_translation2" type="slide" pos="0 0 0" axis="-0.992246 -0.123982 -0.00878916" limited="true" range="-0.006792 -7.69254e-11" ref="0"></joint>
          <joint name="knee_angle_l_translation1" type="slide" pos="0 0 0" axis="-0.124293 0.989762 0.0701648" limited="true" range="9.53733e-08 0.00159883" ref="0"></joint>
          <joint name="knee_angle_l" type="hinge" pos="0 0 0" axis="3.98373e-10 0.0707131 -0.997497" limited="true" range="       0   2.0944" ref="0"></joint>
          <joint name="knee_angle_l_rotation2" type="hinge" pos="0 0 0" axis="-0.992246 -0.123982 -0.00878916" limited="true" range="-0.00167821 0.0335354" ref="0"></joint>
          <joint name="knee_angle_l_rotation3" type="hinge" pos="0 0 0" axis="-0.124293 0.989762 0.0701648" limited="true" range="-0.262788 -1.08939e-08" ref="0"></joint>
          <body name="talus_l" pos="   -0.01     -0.4        0" quat="1.0 6.036754011562992e-18 -1.5193252867388614e-18 -2.498419531737724e-19">
            <geom name="l_talus" type="mesh" mesh="l_talus"></geom>
            <inertial pos="       0        0        0" mass="0.1" fullinertia="   0.001    0.001    0.001        0        0        0"></inertial>
            <joint name="ankle_angle_l" type="hinge" pos="0 0 0" axis="0.105014 0.174022 0.979126" limited="true" range="-0.698132 0.523599" ref="0"></joint>
            <body name="calcn_l" pos="-0.04877 -0.04195 -0.00792" quat="1.0 5.320429553087796e-19 -1.609289071159989e-17 -2.1848634538867752e-17">
              <geom name="l_foot" type="mesh" mesh="l_foot"></geom>
              <inertial pos="     0.1     0.03        0" mass="1.25" fullinertia="  0.0014   0.0039   0.0041        0        0        0"></inertial>
              <site name="edl_l-P3" pos="0.0919 0.036 -0.0008"></site>
              <site name="edl_l-P4" pos="0.1616 0.0055 -0.013"></site>
              <site name="ehl_l-P4" pos="0.097 0.0389 0.0211"></site>
              <site name="ehl_l-P5" pos="0.1293 0.0309 0.0257"></site>
              <site name="ehl_l-P6" pos="0.1734 0.0139 0.028"></site>
              <site name="fdl_l-P3" pos="0.0436 0.0315 0.028"></site>
              <site name="fdl_l-P4" pos="0.0708 0.0176 0.0263"></site>
              <site name="fdl_l-P5" pos="0.1658 -0.0081 -0.0116"></site>
              <site name="fhl_l-P3" pos="0.0374 0.0276 0.0241"></site>
              <site name="fhl_l-P4" pos="0.1038 0.0068 0.0256"></site>
              <site name="fhl_l-P5" pos="0.1726 -0.0053 0.0269"></site>
              <site name="gaslat_l-P2" pos="0.0044 0.031 0.0053"></site>
              <site name="gasmed_l-P2" pos="0.0044 0.031 0.0053"></site>
              <site name="perbrev_l-P4" pos="0.0471 0.027 -0.0233"></site>
              <site name="perbrev_l-P5" pos="0.0677 0.0219 -0.0343"></site>
              <site name="perlong_l-P4" pos="0.0438 0.023 -0.0221"></site>
              <site name="perlong_l-P5" pos="0.0681 0.0106 -0.0284"></site>
              <site name="perlong_l-P6" pos="0.0852 0.0069 -0.0118"></site>
              <site name="perlong_l-P7" pos="0.1203 0.0085 0.0184"></site>
              <site name="soleus_l-P2" pos="0.0044 0.031 0.0053"></site>
              <site name="tibant_l-P4" pos="0.1166 0.0178 0.0305"></site>
              <site name="tibpost_l-P3" pos="0.0417 0.0334 0.0286"></site>
              <site name="tibpost_l-P4" pos="0.0772 0.0159 0.0281"></site>
              <joint name="subtalar_angle_l" type="hinge" pos="0 0 0" axis="-0.78718 -0.604747 -0.120949" limited="true" range="-0.349066 0.349066" ref="0"></joint>
              <body name="toes_l" pos="  0.1788   -0.002 -0.00108" quat="1.0 1.314867274624753e-31 2.6810890689525335e-17 3.939849802505862e-32">
                <geom name="l_bofoot" type="mesh" mesh="l_bofoot"></geom>
                <inertial pos="  0.0346    0.006   0.0175" mass="0.2166" fullinertia="  0.0001   0.0002    0.001        0        0        0"></inertial>
                <site name="edl_l-P5" pos="0.0003 0.0047 -0.0153"></site>
                <site name="edl_l-P6" pos="0.0443 -0.0004 -0.025"></site>
                <site name="ehl_l-P7" pos="0.0298 0.0041 0.0245"></site>
                <site name="ehl_l-P8" pos="0.0563 0.0034 0.0186"></site>
                <site name="fdl_l-P6" pos="-0.0019 -0.0078 -0.0147"></site>
                <site name="fdl_l-P7" pos="0.0285 -0.0071 -0.0215"></site>
                <site name="fdl_l-P8" pos="0.0441 -0.006 -0.0242"></site>
                <site name="fhl_l-P6" pos="0.0155 -0.0064 0.0265"></site>
                <site name="fhl_l-P7" pos="0.0562 -0.0102 0.0181"></site>
                <joint name="mtp_angle_l" type="hinge" pos="0 0 0" axis="-0.580954 2.6299e-15 -0.813936" limited="true" range="-0.523599 0.523599" ref="0"></joint>
              </body>
            </body>
          </body>
        </body>
        <body name="patella_l" pos="-0.00809 -0.40796        0" quat="1.0 0.0 0.0 0.0">
          <geom name="l_patella" type="mesh" mesh="l_patella"></geom>
          <inertial pos="  0.0018   0.0264        0" mass="0.0862" fullinertia="2.87e-06 1.311e-05 1.311e-05        0        0        0"></inertial>
          <site name="recfem_l-P2" pos="0.01 0.049 -0.0007"></site>
          <site name="recfem_l-P3" pos="0.0121 0.0437 0.001"></site>
          <site name="recfem_l-P4" pos="0.005 0.00247 -3e-005"></site>
          <site name="vasint_l-P3" pos="0.0058 0.048 0.0006"></site>
          <site name="vasint_l-P4" pos="0.005 0.00247 0.00039"></site>
          <site name="vaslat_l-P3" pos="0.0103 0.0423 -0.0141"></site>
          <site name="vaslat_l-P4" pos="0.005 0.00247 -0.00733"></site>
          <site name="vasmed_l-P3" pos="0.0063 0.0445 0.017"></site>
          <site name="vasmed_l-P4" pos="0.005 0.00247 0.0085"></site>
          <joint name="knee_angle_l_beta_translation2" type="slide" pos="0 0 0" axis="       0        1        0" limited="true" range="-0.0408267 -0.0108281" ref="0"></joint>
          <joint name="knee_angle_l_beta_translation1" type="slide" pos="0 0 0" axis="       1        0        0" limited="true" range="-0.0227731 0.0524192" ref="0"></joint>
          <joint name="knee_angle_l_beta_rotation1" type="hinge" pos="0 0 0" axis="       0        0        1" limited="true" range="-1.79241 0.010506" ref="0"></joint>
        </body>
      </body>
      <body name="torso" pos=" -0.1007   0.0815        0" quat="1.0 0.0 0.0 0.0">
        <geom name="hat_spine" type="mesh" mesh="hat_spine"></geom>
        <geom name="hat_jaw" type="mesh" mesh="hat_jaw"></geom>
        <geom name="hat_skull" type="mesh" mesh="hat_skull"></geom>
        <geom name="hat_ribs_scap" type="mesh" mesh="hat_ribs_scap"></geom>
        <inertial pos="   -0.03     0.32        0" mass="26.8266" fullinertia="  1.4745   0.7555   1.4314        0        0        0"></inertial>
        <joint name="lumbar_extension" type="hinge" pos="0 0 0" axis="       0        0        1" limited="true" range=" -1.5708   1.5708" ref="0"></joint>
        <joint name="lumbar_bending" type="hinge" pos="0 0 0" axis="       1        0        0" limited="true" range=" -1.5708   1.5708" ref="0"></joint>
        <joint name="lumbar_rotation" type="hinge" pos="0 0 0" axis="       0        1        0" limited="true" range=" -1.5708   1.5708" ref="0"></joint>
        <body name="humerus_r" pos="0.003155   0.3715     0.17" quat="1.0 0.0 0.0 0.0">
          <geom name="humerus_rv" type="mesh" mesh="humerus_rv"></geom>
          <inertial pos="       0 -0.164502        0" mass="2.0325" fullinertia="0.011946 0.004121 0.013409        0        0        0"></inertial>
          <joint name="arm_flex_r" type="hinge" pos="0 0 0" axis="       0        0        1" limited="true" range=" -1.5708   1.5708" ref="0"></joint>
          <joint name="arm_add_r" type="hinge" pos="0 0 0" axis="       1        0        0" limited="true" range=" -2.0944   1.5708" ref="0"></joint>
          <joint name="arm_rot_r" type="hinge" pos="0 0 0" axis="       0        1        0" limited="true" range=" -1.5708   1.5708" ref="0"></joint>
          <body name="ulna_r" pos="0.013144 -0.286273 -0.009595" quat="1.0 1.6893809785063376e-18 -6.938893903907228e-18 4.155190089080778e-20">
            <geom name="ulna_rv" type="mesh" mesh="ulna_rv"></geom>
            <inertial pos="       0 -0.120525        0" mass="0.6075" fullinertia="0.002962 0.000618 0.003213        0        0        0"></inertial>
            <joint name="elbow_flex_r" type="hinge" pos="0 0 0" axis="0.226047 0.022269 0.973862" limited="true" range="       0    2.618" ref="0"></joint>
            <body name="radius_r" pos="-0.006727 -0.013007 0.026083" quat="1.0 2.301201592641875e-21 -6.933378131686372e-19 1.7489241099837954e-19">
              <geom name="radius_rv" type="mesh" mesh="radius_rv"></geom>
              <inertial pos="       0 -0.120525        0" mass="0.6075" fullinertia="0.002962 0.000618 0.003213        0        0        0"></inertial>
              <joint name="pro_sup_r" type="hinge" pos="0 0 0" axis="0.056398 0.998406 0.001952" limited="true" range="       0   1.5708" ref="0"></joint>
              <body name="hand_r" pos="-0.008797 -0.235841  0.01361" quat="1.0 0.0 8.407790785948892e-45 0.0">
                <geom name="pisiform_rvs" type="mesh" mesh="pisiform_rvs"></geom>
                <geom name="lunate_rvs" type="mesh" mesh="lunate_rvs"></geom>
                <geom name="scaphoid_rvs" type="mesh" mesh="scaphoid_rvs"></geom>
                <geom name="triquetrum_rvs" type="mesh" mesh="triquetrum_rvs"></geom>
                <geom name="hamate_rvs" type="mesh" mesh="hamate_rvs"></geom>
                <geom name="capitate_rvs" type="mesh" mesh="capitate_rvs"></geom>
                <geom name="trapezoid_rvs" type="mesh" mesh="trapezoid_rvs"></geom>
                <geom name="trapezium_rvs" type="mesh" mesh="trapezium_rvs"></geom>
                <geom name="metacarpal2_rvs" type="mesh" mesh="metacarpal2_rvs"></geom>
                <geom name="index_proximal_rvs" type="mesh" mesh="index_proximal_rvs"></geom>
                <geom name="index_medial_rvs" type="mesh" mesh="index_medial_rvs"></geom>
                <geom name="index_distal_rvs" type="mesh" mesh="index_distal_rvs"></geom>
                <geom name="metacarpal3_rvs" type="mesh" mesh="metacarpal3_rvs"></geom>
                <geom name="middle_proximal_rvs" type="mesh" mesh="middle_proximal_rvs"></geom>
                <geom name="middle_medial_rvs" type="mesh" mesh="middle_medial_rvs"></geom>
                <geom name="middle_distal_rvs" type="mesh" mesh="middle_distal_rvs"></geom>
                <geom name="metacarpal4_rvs" type="mesh" mesh="metacarpal4_rvs"></geom>
                <geom name="ring_proximal_rvs" type="mesh" mesh="ring_proximal_rvs"></geom>
                <geom name="ring_medial_rvs" type="mesh" mesh="ring_medial_rvs"></geom>
                <geom name="ring_distal_rvs" type="mesh" mesh="ring_distal_rvs"></geom>
                <geom name="metacarpal5_rvs" type="mesh" mesh="metacarpal5_rvs"></geom>
                <geom name="little_proximal_rvs" type="mesh" mesh="little_proximal_rvs"></geom>
                <geom name="little_medial_rvs" type="mesh" mesh="little_medial_rvs"></geom>
                <geom name="little_distal_rvs" type="mesh" mesh="little_distal_rvs"></geom>
                <geom name="metacarpal1_rvs" type="mesh" mesh="metacarpal1_rvs"></geom>
                <geom name="thumb_proximal_rvs" type="mesh" mesh="thumb_proximal_rvs"></geom>
                <geom name="thumb_distal_rvs" type="mesh" mesh="thumb_distal_rvs"></geom>
                <inertial pos="       0 -0.068095        0" mass="0.4575" fullinertia="0.000892 0.000547  0.00134        0        0        0"></inertial>
                <joint name="wrist_flex_r" type="hinge" pos="0 0 0" axis="-3.55271e-15 3.55271e-15        1" limited="true" range="-1.22173  1.22173" ref="0"></joint>
                <joint name="wrist_dev_r" type="hinge" pos="0 0 0" axis="       1        0 3.55271e-15" limited="true" range="-0.436332 0.610865" ref="0"></joint>
              </body>
            </body>
          </body>
        </body>
        <body name="humerus_l" pos="0.003155   0.3715    -0.17" quat="1.0 0.0 0.0 0.0">
          <geom name="humerus_lv" type="mesh" mesh="humerus_lv"></geom>
          <inertial pos="       0 -0.164502        0" mass="2.0325" fullinertia="0.011946 0.004121 0.013409        0        0        0"></inertial>
          <joint name="arm_flex_l" type="hinge" pos="0 0 0" axis="       0        0        1" limited="true" range=" -1.5708   1.5708" ref="0"></joint>
          <joint name="arm_add_l" type="hinge" pos="0 0 0" axis="      -1        0        0" limited="true" range=" -2.0944   1.5708" ref="0"></joint>
          <joint name="arm_rot_l" type="hinge" pos="0 0 0" axis="       0       -1        0" limited="true" range=" -1.5708   1.5708" ref="0"></joint>
          <body name="ulna_l" pos="0.013144 -0.286273 0.009595" quat="1.0 -1.6893809785063376e-18 6.938893903907228e-18 4.155190089080778e-20">
            <geom name="ulna_lv" type="mesh" mesh="ulna_lv"></geom>
            <inertial pos="       0 -0.120525        0" mass="0.6075" fullinertia="0.002962 0.000618 0.003213        0        0        0"></inertial>
            <joint name="elbow_flex_l" type="hinge" pos="0 0 0" axis="-0.226047 -0.022269 0.973862" limited="true" range="       0    2.618" ref="0"></joint>
            <body name="radius_l" pos="-0.006727 -0.013007 -0.026083" quat="1.0 -2.301201592641875e-21 6.933378131686372e-19 1.7489241099837954e-19">
              <geom name="radius_lv" type="mesh" mesh="radius_lv"></geom>
              <inertial pos="       0 -0.120525        0" mass="0.6075" fullinertia="0.002962 0.000618 0.003213        0        0        0"></inertial>
              <joint name="pro_sup_l" type="hinge" pos="0 0 0" axis="-0.056398 -0.998406 0.001952" limited="true" range="       0   1.5708" ref="0"></joint>
              <body name="hand_l" pos="-0.008797 -0.235841 -0.01361" quat="1.0 0.0 8.407790785948892e-45 0.0">
                <geom name="pisiform_lvs" type="mesh" mesh="pisiform_lvs"></geom>
                <geom name="lunate_lvs" type="mesh" mesh="lunate_lvs"></geom>
                <geom name="scaphoid_lvs" type="mesh" mesh="scaphoid_lvs"></geom>
                <geom name="triquetrum_lvs" type="mesh" mesh="triquetrum_lvs"></geom>
                <geom name="hamate_lvs" type="mesh" mesh="hamate_lvs"></geom>
                <geom name="capitate_lvs" type="mesh" mesh="capitate_lvs"></geom>
                <geom name="trapezoid_lvs" type="mesh" mesh="trapezoid_lvs"></geom>
                <geom name="trapezium_lvs" type="mesh" mesh="trapezium_lvs"></geom>
                <geom name="metacarpal2_lvs" type="mesh" mesh="metacarpal2_lvs"></geom>
                <geom name="index_proximal_lvs" type="mesh" mesh="index_proximal_lvs"></geom>
                <geom name="index_medial_lvs" type="mesh" mesh="index_medial_lvs"></geom>
                <geom name="index_distal_lvs" type="mesh" mesh="index_distal_lvs"></geom>
                <geom name="metacarpal3_lvs" type="mesh" mesh="metacarpal3_lvs"></geom>
                <geom name="middle_proximal_lvs" type="mesh" mesh="middle_proximal_lvs"></geom>
                <geom name="middle_medial_lvs" type="mesh" mesh="middle_medial_lvs"></geom>
                <geom name="middle_distal_lvs" type="mesh" mesh="middle_distal_lvs"></geom>
                <geom name="metacarpal4_lvs" type="mesh" mesh="metacarpal4_lvs"></geom>
                <geom name="ring_proximal_lvs" type="mesh" mesh="ring_proximal_lvs"></geom>
                <geom name="ring_medial_lvs" type="mesh" mesh="ring_medial_lvs"></geom>
                <geom name="ring_distal_lvs" type="mesh" mesh="ring_distal_lvs"></geom>
                <geom name="metacarpal5_lvs" type="mesh" mesh="metacarpal5_lvs"></geom>
                <geom name="little_proximal_lvs" type="mesh" mesh="little_proximal_lvs"></geom>
                <geom name="little_medial_lvs" type="mesh" mesh="little_medial_lvs"></geom>
                <geom name="little_distal_lvs" type="mesh" mesh="little_distal_lvs"></geom>
                <geom name="metacarpal1_lvs" type="mesh" mesh="metacarpal1_lvs"></geom>
                <geom name="thumb_proximal_lvs" type="mesh" mesh="thumb_proximal_lvs"></geom>
                <geom name="thumb_distal_lvs" type="mesh" mesh="thumb_distal_lvs"></geom>
                <inertial pos="       0 -0.068095        0" mass="0.4575" fullinertia="0.000892 0.000547  0.00134        0        0        0"></inertial>
                <joint name="wrist_flex_l" type="hinge" pos="0 0 0" axis="-3.55271e-15 -3.55271e-15        1" limited="true" range="-1.22173  1.22173" ref="0"></joint>
                <joint name="wrist_dev_l" type="hinge" pos="0 0 0" axis="      -1        0 -3.55271e-15" limited="true" range="-0.436332 0.610865" ref="0"></joint>
              </body>
            </body>
          </body>
        </body>
      </body>
    </body>
  </worldbody>
  <asset>
    <mesh name="r_pelvis" file="meshes/r_pelvis.stl" scale="       1        1        1"></mesh>
    <mesh name="l_pelvis" file="meshes/l_pelvis.stl" scale="       1        1        1"></mesh>
    <mesh name="sacrum" file="meshes/sacrum.stl" scale="       1        1        1"></mesh>
    <mesh name="r_femur" file="meshes/r_femur.stl" scale="       1        1        1"></mesh>
    <mesh name="r_tibia" file="meshes/r_tibia.stl" scale="       1        1        1"></mesh>
    <mesh name="r_fibula" file="meshes/r_fibula.stl" scale="       1        1        1"></mesh>
    <mesh name="r_talus" file="meshes/r_talus.stl" scale="       1        1        1"></mesh>
    <mesh name="r_foot" file="meshes/r_foot.stl" scale="       1        1        1"></mesh>
    <mesh name="r_bofoot" file="meshes/r_bofoot.stl" scale="       1        1        1"></mesh>
    <mesh name="r_patella" file="meshes/r_patella.stl" scale="       1        1        1"></mesh>
    <mesh name="l_femur" file="meshes/l_femur.stl" scale="       1        1        1"></mesh>
    <mesh name="l_tibia" file="meshes/l_tibia.stl" scale="       1        1        1"></mesh>
    <mesh name="l_fibula" file="meshes/l_fibula.stl" scale="       1        1        1"></mesh>
    <mesh name="l_talus" file="meshes/l_talus.stl" scale="       1        1        1"></mesh>
    <mesh name="l_foot" file="meshes/l_foot.stl" scale="       1        1        1"></mesh>
    <mesh name="l_bofoot" file="meshes/l_bofoot.stl" scale="       1        1        1"></mesh>
    <mesh name="l_patella" file="meshes/l_patella.stl" scale="       1        1        1"></mesh>
    <mesh name="hat_spine" file="meshes/hat_spine.stl" scale="       1        1        1"></mesh>
    <mesh name="hat_jaw" file="meshes/hat_jaw.stl" scale="       1        1        1"></mesh>
    <mesh name="hat_skull" file="meshes/hat_skull.stl" scale="       1        1        1"></mesh>
    <mesh name="hat_ribs_scap" file="meshes/hat_ribs_scap.stl" scale="       1        1        1"></mesh>
    <mesh name="humerus_rv" file="meshes/humerus_rv.stl" scale="       1        1        1"></mesh>
    <mesh name="ulna_rv" file="meshes/ulna_rv.stl" scale="       1        1        1"></mesh>
    <mesh name="radius_rv" file="meshes/radius_rv.stl" scale="       1        1        1"></mesh>
    <mesh name="pisiform_rvs" file="meshes/pisiform_rvs.stl" scale="    0.85     0.85     0.85"></mesh>
    <mesh name="lunate_rvs" file="meshes/lunate_rvs.stl" scale="    0.85     0.85     0.85"></mesh>
    <mesh name="scaphoid_rvs" file="meshes/scaphoid_rvs.stl" scale="    0.85     0.85     0.85"></mesh>
    <mesh name="triquetrum_rvs" file="meshes/triquetrum_rvs.stl" scale="    0.85     0.85     0.85"></mesh>
    <mesh name="hamate_rvs" file="meshes/hamate_rvs.stl" scale="    0.85     0.85     0.85"></mesh>
    <mesh name="capitate_rvs" file="meshes/capitate_rvs.stl" scale="    0.85     0.85     0.85"></mesh>
    <mesh name="trapezoid_rvs" file="meshes/trapezoid_rvs.stl" scale="    0.85     0.85     0.85"></mesh>
    <mesh name="trapezium_rvs" file="meshes/trapezium_rvs.stl" scale="    0.85     0.85     0.85"></mesh>
    <mesh name="metacarpal2_rvs" file="meshes/metacarpal2_rvs.stl" scale="    0.85     0.85     0.85"></mesh>
    <mesh name="index_proximal_rvs" file="meshes/index_proximal_rvs.stl" scale="    0.85     0.85     0.85"></mesh>
    <mesh name="index_medial_rvs" file="meshes/index_medial_rvs.stl" scale="    0.85     0.85     0.85"></mesh>
    <mesh name="index_distal_rvs" file="meshes/index_distal_rvs.stl" scale="    0.85     0.85     0.85"></mesh>
    <mesh name="metacarpal3_rvs" file="meshes/metacarpal3_rvs.stl" scale="    0.85     0.85     0.85"></mesh>
    <mesh name="middle_proximal_rvs" file="meshes/middle_proximal_rvs.stl" scale="    0.85     0.85     0.85"></mesh>
    <mesh name="middle_medial_rvs" file="meshes/middle_medial_rvs.stl" scale="    0.85     0.85     0.85"></mesh>
    <mesh name="middle_distal_rvs" file="meshes/middle_distal_rvs.stl" scale="    0.85     0.85     0.85"></mesh>
    <mesh name="metacarpal4_rvs" file="meshes/metacarpal4_rvs.stl" scale="    0.85     0.85     0.85"></mesh>
    <mesh name="ring_proximal_rvs" file="meshes/ring_proximal_rvs.stl" scale="    0.85     0.85     0.85"></mesh>
    <mesh name="ring_medial_rvs" file="meshes/ring_medial_rvs.stl" scale="    0.85     0.85     0.85"></mesh>
    <mesh name="ring_distal_rvs" file="meshes/ring_distal_rvs.stl" scale="    0.85     0.85     0.85"></mesh>
    <mesh name="metacarpal5_rvs" file="meshes/metacarpal5_rvs.stl" scale="    0.85     0.85     0.85"></mesh>
    <mesh name="little_proximal_rvs" file="meshes/little_proximal_rvs.stl" scale="    0.85     0.85     0.85"></mesh>
    <mesh name="little_medial_rvs" file="meshes/little_medial_rvs.stl" scale="    0.85     0.85     0.85"></mesh>
    <mesh name="little_distal_rvs" file="meshes/little_distal_rvs.stl" scale="    0.85     0.85     0.85"></mesh>
    <mesh name="metacarpal1_rvs" file="meshes/metacarpal1_rvs.stl" scale="    0.85     0.85     0.85"></mesh>
    <mesh name="thumb_proximal_rvs" file="meshes/thumb_proximal_rvs.stl" scale="    0.85     0.85     0.85"></mesh>
    <mesh name="thumb_distal_rvs" file="meshes/thumb_distal_rvs.stl" scale="    0.85     0.85     0.85"></mesh>
    <mesh name="humerus_lv" file="meshes/humerus_lv.stl" scale="       1        1        1"></mesh>
    <mesh name="ulna_lv" file="meshes/ulna_lv.stl" scale="       1        1        1"></mesh>
    <mesh name="radius_lv" file="meshes/radius_lv.stl" scale="       1        1        1"></mesh>
    <mesh name="pisiform_lvs" file="meshes/pisiform_lvs.stl" scale="    0.85     0.85     0.85"></mesh>
    <mesh name="lunate_lvs" file="meshes/lunate_lvs.stl" scale="    0.85     0.85     0.85"></mesh>
    <mesh name="scaphoid_lvs" file="meshes/scaphoid_lvs.stl" scale="    0.85     0.85     0.85"></mesh>
    <mesh name="triquetrum_lvs" file="meshes/triquetrum_lvs.stl" scale="    0.85     0.85     0.85"></mesh>
    <mesh name="hamate_lvs" file="meshes/hamate_lvs.stl" scale="    0.85     0.85     0.85"></mesh>
    <mesh name="capitate_lvs" file="meshes/capitate_lvs.stl" scale="    0.85     0.85     0.85"></mesh>
    <mesh name="trapezoid_lvs" file="meshes/trapezoid_lvs.stl" scale="    0.85     0.85     0.85"></mesh>
    <mesh name="trapezium_lvs" file="meshes/trapezium_lvs.stl" scale="    0.85     0.85     0.85"></mesh>
    <mesh name="metacarpal2_lvs" file="meshes/metacarpal2_lvs.stl" scale="    0.85     0.85     0.85"></mesh>
    <mesh name="index_proximal_lvs" file="meshes/index_proximal_lvs.stl" scale="    0.85     0.85     0.85"></mesh>
    <mesh name="index_medial_lvs" file="meshes/index_medial_lvs.stl" scale="    0.85     0.85     0.85"></mesh>
    <mesh name="index_distal_lvs" file="meshes/index_distal_lvs.stl" scale="    0.85     0.85     0.85"></mesh>
    <mesh name="metacarpal3_lvs" file="meshes/metacarpal3_lvs.stl" scale="    0.85     0.85     0.85"></mesh>
    <mesh name="middle_proximal_lvs" file="meshes/middle_proximal_lvs.stl" scale="    0.85     0.85     0.85"></mesh>
    <mesh name="middle_medial_lvs" file="meshes/middle_medial_lvs.stl" scale="    0.85     0.85     0.85"></mesh>
    <mesh name="middle_distal_lvs" file="meshes/middle_distal_lvs.stl" scale="    0.85     0.85     0.85"></mesh>
    <mesh name="metacarpal4_lvs" file="meshes/metacarpal4_lvs.stl" scale="    0.85     0.85     0.85"></mesh>
    <mesh name="ring_proximal_lvs" file="meshes/ring_proximal_lvs.stl" scale="    0.85     0.85     0.85"></mesh>
    <mesh name="ring_medial_lvs" file="meshes/ring_medial_lvs.stl" scale="    0.85     0.85     0.85"></mesh>
    <mesh name="ring_distal_lvs" file="meshes/ring_distal_lvs.stl" scale="    0.85     0.85     0.85"></mesh>
    <mesh name="metacarpal5_lvs" file="meshes/metacarpal5_lvs.stl" scale="    0.85     0.85     0.85"></mesh>
    <mesh name="little_proximal_lvs" file="meshes/little_proximal_lvs.stl" scale="    0.85     0.85     0.85"></mesh>
    <mesh name="little_medial_lvs" file="meshes/little_medial_lvs.stl" scale="    0.85     0.85     0.85"></mesh>
    <mesh name="little_distal_lvs" file="meshes/little_distal_lvs.stl" scale="    0.85     0.85     0.85"></mesh>
    <mesh name="metacarpal1_lvs" file="meshes/metacarpal1_lvs.stl" scale="    0.85     0.85     0.85"></mesh>
    <mesh name="thumb_proximal_lvs" file="meshes/thumb_proximal_lvs.stl" scale="    0.85     0.85     0.85"></mesh>
    <mesh name="thumb_distal_lvs" file="meshes/thumb_distal_lvs.stl" scale="    0.85     0.85     0.85"></mesh>
    <texture builtin="gradient" height="100" rgb1=".4 .5 .6" rgb2="0 0 0" type="skybox" width="100"/>
    <texture name="texplane" type="2d" builtin="checker" rgb1=".2 .3 .4" rgb2=".1 0.15 0.2" width="100" height="100"></texture>
    <texture name="texgeom" type="cube" builtin="flat" mark="cross" width="127" height="1278" rgb1="0.8 0.6 0.4" rgb2="0.8 0.6 0.4" markrgb="1 1 1" random="0.01"></texture>
    <material name="MatPlane" reflectance="0.5" texture="texplane" texrepeat="1 1" texuniform="true"></material>
    <material name="geom" texture="texgeom" texuniform="true"></material>
  </asset>
  <tendon>
    <spatial name="addbrev_r_tendon" springlength="0.035450291324676">
      <site site="addbrev_r-P1"></site>
      <site site="addbrev_r-P2"></site>
    </spatial>
    <spatial name="addlong_r_tendon" springlength="0.131799363342026">
      <site site="addlong_r-P1"></site>
      <site site="addlong_r-P2"></site>
    </spatial>
    <spatial name="addmagDist_r_tendon" springlength="0.0873806954617727">
      <site site="addmagDist_r-P1"></site>
      <site site="addmagDist_r-P2"></site>
    </spatial>
    <spatial name="addmagIsch_r_tendon" springlength="0.216343023454343">
      <site site="addmagIsch_r-P1"></site>
      <site site="addmagIsch_r-P2"></site>
    </spatial>
    <spatial name="addmagMid_r_tendon" springlength="0.0466276999070464">
      <site site="addmagMid_r-P1"></site>
      <site site="addmagMid_r-P2"></site>
    </spatial>
    <spatial name="addmagProx_r_tendon" springlength="0.0403240979232675">
      <site site="addmagProx_r-P1"></site>
      <site site="addmagProx_r-P2"></site>
    </spatial>
    <spatial name="bflh_r_tendon" springlength="0.325226647516457">
      <site site="bflh_r-P1"></site>
      <site site="bflh_r-P2"></site>
      <site site="bflh_r-P3"></site>
    </spatial>
    <spatial name="bfsh_r_tendon" springlength="0.105817218589115">
      <site site="bfsh_r-P1"></site>
      <site site="bfsh_r-P2"></site>
    </spatial>
    <spatial name="edl_r_tendon" springlength="0.368875245465225">
      <site site="edl_r-P1"></site>
      <site site="edl_r-P2"></site>
      <site site="edl_r-P3"></site>
      <site site="edl_r-P4"></site>
      <site site="edl_r-P5"></site>
      <site site="edl_r-P6"></site>
    </spatial>
    <spatial name="ehl_r_tendon" springlength="0.326795279537187">
      <site site="ehl_r-P1"></site>
      <site site="ehl_r-P2"></site>
      <site site="ehl_r-P3"></site>
      <site site="ehl_r-P4"></site>
      <site site="ehl_r-P5"></site>
      <site site="ehl_r-P6"></site>
      <site site="ehl_r-P7"></site>
      <site site="ehl_r-P8"></site>
    </spatial>
    <spatial name="fdl_r_tendon" springlength="0.378772856793842">
      <site site="fdl_r-P1"></site>
      <site site="fdl_r-P2"></site>
      <site site="fdl_r-P3"></site>
      <site site="fdl_r-P4"></site>
      <site site="fdl_r-P5"></site>
      <site site="fdl_r-P6"></site>
      <site site="fdl_r-P7"></site>
      <site site="fdl_r-P8"></site>
    </spatial>
    <spatial name="fhl_r_tendon" springlength="0.354339676836818">
      <site site="fhl_r-P1"></site>
      <site site="fhl_r-P2"></site>
      <site site="fhl_r-P3"></site>
      <site site="fhl_r-P4"></site>
      <site site="fhl_r-P5"></site>
      <site site="fhl_r-P6"></site>
      <site site="fhl_r-P7"></site>
    </spatial>
    <spatial name="gaslat_r_tendon" springlength="0.376070169933794">
      <site site="gaslat_r-P1"></site>
      <site site="gaslat_r-P2"></site>
    </spatial>
    <spatial name="gasmed_r_tendon" springlength="0.398716332626429">
      <site site="gasmed_r-P1"></site>
      <site site="gasmed_r-P2"></site>
    </spatial>
    <spatial name="glmax1_r_tendon" springlength="0.0488408889462853">
      <site site="glmax1_r-P1"></site>
      <site site="glmax1_r-P2"></site>
      <site site="glmax1_r-P3"></site>
      <site site="glmax1_r-P4"></site>
    </spatial>
    <spatial name="glmax2_r_tendon" springlength="0.0678871511792641">
      <site site="glmax2_r-P1"></site>
      <site site="glmax2_r-P2"></site>
      <site site="glmax2_r-P3"></site>
      <site site="glmax2_r-P4"></site>
    </spatial>
    <spatial name="glmax3_r_tendon" springlength="0.0697166058843707">
      <site site="glmax3_r-P1"></site>
      <site site="glmax3_r-P2"></site>
      <site site="glmax3_r-P3"></site>
      <site site="glmax3_r-P4"></site>
    </spatial>
    <spatial name="glmed1_r_tendon" springlength="0.0558168319436554">
      <site site="glmed1_r-P1"></site>
      <site site="glmed1_r-P2"></site>
    </spatial>
    <spatial name="glmed2_r_tendon" springlength="0.0652488111992348">
      <site site="glmed2_r-P1"></site>
      <site site="glmed2_r-P2"></site>
    </spatial>
    <spatial name="glmed3_r_tendon" springlength="0.0452328436013583">
      <site site="glmed3_r-P1"></site>
      <site site="glmed3_r-P2"></site>
    </spatial>
    <spatial name="glmin1_r_tendon" springlength="0.0161377823749703">
      <site site="glmin1_r-P1"></site>
      <site site="glmin1_r-P2"></site>
    </spatial>
    <spatial name="glmin2_r_tendon" springlength="0.0260990524098789">
      <site site="glmin2_r-P1"></site>
      <site site="glmin2_r-P2"></site>
    </spatial>
    <spatial name="glmin3_r_tendon" springlength="0.0508725">
      <site site="glmin3_r-P1"></site>
      <site site="glmin3_r-P2"></site>
    </spatial>
    <spatial name="grac_r_tendon" springlength="0.172013810564373">
      <site site="grac_r-P1"></site>
      <site site="grac_r-P2"></site>
      <site site="grac_r-P3"></site>
    </spatial>
    <spatial name="iliacus_r_tendon" springlength="0.0961207083983258">
      <site site="iliacus_r-P1"></site>
      <site site="iliacus_r-P2"></site>
      <site site="iliacus_r-P3"></site>
      <site site="iliacus_r-P4"></site>
    </spatial>
    <spatial name="perbrev_r_tendon" springlength="0.147527533956538">
      <site site="perbrev_r-P1"></site>
      <site site="perbrev_r-P2"></site>
      <site site="perbrev_r-P3"></site>
      <site site="perbrev_r-P4"></site>
      <site site="perbrev_r-P5"></site>
    </spatial>
    <spatial name="perlong_r_tendon" springlength="0.332220762637978">
      <site site="perlong_r-P1"></site>
      <site site="perlong_r-P2"></site>
      <site site="perlong_r-P3"></site>
      <site site="perlong_r-P4"></site>
      <site site="perlong_r-P5"></site>
      <site site="perlong_r-P6"></site>
      <site site="perlong_r-P7"></site>
    </spatial>
    <spatial name="piri_r_tendon" springlength="0.114906238342785">
      <site site="piri_r-P1"></site>
      <site site="piri_r-P2"></site>
      <site site="piri_r-P3"></site>
    </spatial>
    <spatial name="psoas_r_tendon" springlength="0.0995431658555083">
      <site site="psoas_r-P1"></site>
      <site site="psoas_r-P2"></site>
      <site site="psoas_r-P3"></site>
      <site site="psoas_r-P4"></site>
    </spatial>
    <spatial name="recfem_r_tendon" springlength="0.448493537399412">
      <site site="recfem_r-P1"></site>
      <site site="recfem_r-P2"></site>
      <site site="recfem_r-P3"></site>
      <site site="recfem_r-P4"></site>
      <site site="recfem_r-P5"></site>
    </spatial>
    <spatial name="sart_r_tendon" springlength="0.123999830194402">
      <site site="sart_r-P1"></site>
      <site site="sart_r-P2"></site>
      <site site="sart_r-P3"></site>
      <site site="sart_r-P4"></site>
      <site site="sart_r-P5"></site>
    </spatial>
    <spatial name="semimem_r_tendon" springlength="0.347585979533214">
      <site site="semimem_r-P1"></site>
      <site site="semimem_r-P2"></site>
    </spatial>
    <spatial name="semiten_r_tendon" springlength="0.24719894503751">
      <site site="semiten_r-P1"></site>
      <site site="semiten_r-P2"></site>
      <site site="semiten_r-P3"></site>
    </spatial>
    <spatial name="soleus_r_tendon" springlength="0.276755872375976">
      <site site="soleus_r-P1"></site>
      <site site="soleus_r-P2"></site>
    </spatial>
    <spatial name="tfl_r_tendon" springlength="0.449497053805428">
      <site site="tfl_r-P1"></site>
      <site site="tfl_r-P2"></site>
      <site site="tfl_r-P3"></site>
      <site site="tfl_r-P4"></site>
    </spatial>
    <spatial name="tibant_r_tendon" springlength="0.240461026409367">
      <site site="tibant_r-P1"></site>
      <site site="tibant_r-P2"></site>
      <site site="tibant_r-P3"></site>
      <site site="tibant_r-P4"></site>
    </spatial>
    <spatial name="tibpost_r_tendon" springlength="0.280779613883954">
      <site site="tibpost_r-P1"></site>
      <site site="tibpost_r-P2"></site>
      <site site="tibpost_r-P3"></site>
      <site site="tibpost_r-P4"></site>
    </spatial>
    <spatial name="vasint_r_tendon" springlength="0.202210670345763">
      <site site="vasint_r-P1"></site>
      <site site="vasint_r-P2"></site>
      <site site="vasint_r-P3"></site>
      <site site="vasint_r-P4"></site>
      <site site="vasint_r-P5"></site>
    </spatial>
    <spatial name="vaslat_r_tendon" springlength="0.220601284834603">
      <site site="vaslat_r-P1"></site>
      <site site="vaslat_r-P2"></site>
      <site site="vaslat_r-P3"></site>
      <site site="vaslat_r-P4"></site>
      <site site="vaslat_r-P5"></site>
    </spatial>
    <spatial name="vasmed_r_tendon" springlength="0.199904270842317">
      <site site="vasmed_r-P1"></site>
      <site site="vasmed_r-P2"></site>
      <site site="vasmed_r-P3"></site>
      <site site="vasmed_r-P4"></site>
      <site site="vasmed_r-P5"></site>
    </spatial>
    <spatial name="addbrev_l_tendon" springlength="0.035450291324676">
      <site site="addbrev_l-P1"></site>
      <site site="addbrev_l-P2"></site>
    </spatial>
    <spatial name="addlong_l_tendon" springlength="0.131799363342026">
      <site site="addlong_l-P1"></site>
      <site site="addlong_l-P2"></site>
    </spatial>
    <spatial name="addmagDist_l_tendon" springlength="0.0873806954617727">
      <site site="addmagDist_l-P1"></site>
      <site site="addmagDist_l-P2"></site>
    </spatial>
    <spatial name="addmagIsch_l_tendon" springlength="0.216343023454343">
      <site site="addmagIsch_l-P1"></site>
      <site site="addmagIsch_l-P2"></site>
    </spatial>
    <spatial name="addmagMid_l_tendon" springlength="0.0466276999070464">
      <site site="addmagMid_l-P1"></site>
      <site site="addmagMid_l-P2"></site>
    </spatial>
    <spatial name="addmagProx_l_tendon" springlength="0.0403240979232675">
      <site site="addmagProx_l-P1"></site>
      <site site="addmagProx_l-P2"></site>
    </spatial>
    <spatial name="bflh_l_tendon" springlength="0.325226647516457">
      <site site="bflh_l-P1"></site>
      <site site="bflh_l-P2"></site>
      <site site="bflh_l-P3"></site>
    </spatial>
    <spatial name="bfsh_l_tendon" springlength="0.105817218589115">
      <site site="bfsh_l-P1"></site>
      <site site="bfsh_l-P2"></site>
    </spatial>
    <spatial name="edl_l_tendon" springlength="0.368875245465225">
      <site site="edl_l-P1"></site>
      <site site="edl_l-P2"></site>
      <site site="edl_l-P3"></site>
      <site site="edl_l-P4"></site>
      <site site="edl_l-P5"></site>
      <site site="edl_l-P6"></site>
    </spatial>
    <spatial name="ehl_l_tendon" springlength="0.326795279537187">
      <site site="ehl_l-P1"></site>
      <site site="ehl_l-P2"></site>
      <site site="ehl_l-P3"></site>
      <site site="ehl_l-P4"></site>
      <site site="ehl_l-P5"></site>
      <site site="ehl_l-P6"></site>
      <site site="ehl_l-P7"></site>
      <site site="ehl_l-P8"></site>
    </spatial>
    <spatial name="fdl_l_tendon" springlength="0.378772856793842">
      <site site="fdl_l-P1"></site>
      <site site="fdl_l-P2"></site>
      <site site="fdl_l-P3"></site>
      <site site="fdl_l-P4"></site>
      <site site="fdl_l-P5"></site>
      <site site="fdl_l-P6"></site>
      <site site="fdl_l-P7"></site>
      <site site="fdl_l-P8"></site>
    </spatial>
    <spatial name="fhl_l_tendon" springlength="0.354339676836818">
      <site site="fhl_l-P1"></site>
      <site site="fhl_l-P2"></site>
      <site site="fhl_l-P3"></site>
      <site site="fhl_l-P4"></site>
      <site site="fhl_l-P5"></site>
      <site site="fhl_l-P6"></site>
      <site site="fhl_l-P7"></site>
    </spatial>
    <spatial name="gaslat_l_tendon" springlength="0.376070169933794">
      <site site="gaslat_l-P1"></site>
      <site site="gaslat_l-P2"></site>
    </spatial>
    <spatial name="gasmed_l_tendon" springlength="0.398716332626429">
      <site site="gasmed_l-P1"></site>
      <site site="gasmed_l-P2"></site>
    </spatial>
    <spatial name="glmax1_l_tendon" springlength="0.0488408889462853">
      <site site="glmax1_l-P1"></site>
      <site site="glmax1_l-P2"></site>
      <site site="glmax1_l-P3"></site>
      <site site="glmax1_l-P4"></site>
    </spatial>
    <spatial name="glmax2_l_tendon" springlength="0.0678871511792641">
      <site site="glmax2_l-P1"></site>
      <site site="glmax2_l-P2"></site>
      <site site="glmax2_l-P3"></site>
      <site site="glmax2_l-P4"></site>
    </spatial>
    <spatial name="glmax3_l_tendon" springlength="0.0697166058843707">
      <site site="glmax3_l-P1"></site>
      <site site="glmax3_l-P2"></site>
      <site site="glmax3_l-P3"></site>
      <site site="glmax3_l-P4"></site>
    </spatial>
    <spatial name="glmed1_l_tendon" springlength="0.0558168319436554">
      <site site="glmed1_l-P1"></site>
      <site site="glmed1_l-P2"></site>
    </spatial>
    <spatial name="glmed2_l_tendon" springlength="0.0652488111992348">
      <site site="glmed2_l-P1"></site>
      <site site="glmed2_l-P2"></site>
    </spatial>
    <spatial name="glmed3_l_tendon" springlength="0.0452328436013583">
      <site site="glmed3_l-P1"></site>
      <site site="glmed3_l-P2"></site>
    </spatial>
    <spatial name="glmin1_l_tendon" springlength="0.0161377823749703">
      <site site="glmin1_l-P1"></site>
      <site site="glmin1_l-P2"></site>
    </spatial>
    <spatial name="glmin2_l_tendon" springlength="0.0260990524098789">
      <site site="glmin2_l-P1"></site>
      <site site="glmin2_l-P2"></site>
    </spatial>
    <spatial name="glmin3_l_tendon" springlength="0.0508725">
      <site site="glmin3_l-P1"></site>
      <site site="glmin3_l-P2"></site>
    </spatial>
    <spatial name="grac_l_tendon" springlength="0.172013810564373">
      <site site="grac_l-P1"></site>
      <site site="grac_l-P2"></site>
      <site site="grac_l-P3"></site>
    </spatial>
    <spatial name="iliacus_l_tendon" springlength="0.0961207083983258">
      <site site="iliacus_l-P1"></site>
      <site site="iliacus_l-P2"></site>
      <site site="iliacus_l-P3"></site>
      <site site="iliacus_l-P4"></site>
    </spatial>
    <spatial name="perbrev_l_tendon" springlength="0.147527533956538">
      <site site="perbrev_l-P1"></site>
      <site site="perbrev_l-P2"></site>
      <site site="perbrev_l-P3"></site>
      <site site="perbrev_l-P4"></site>
      <site site="perbrev_l-P5"></site>
    </spatial>
    <spatial name="perlong_l_tendon" springlength="0.332220762637978">
      <site site="perlong_l-P1"></site>
      <site site="perlong_l-P2"></site>
      <site site="perlong_l-P3"></site>
      <site site="perlong_l-P4"></site>
      <site site="perlong_l-P5"></site>
      <site site="perlong_l-P6"></site>
      <site site="perlong_l-P7"></site>
    </spatial>
    <spatial name="piri_l_tendon" springlength="0.114906238342785">
      <site site="piri_l-P1"></site>
      <site site="piri_l-P2"></site>
      <site site="piri_l-P3"></site>
    </spatial>
    <spatial name="psoas_l_tendon" springlength="0.0995431658555083">
      <site site="psoas_l-P1"></site>
      <site site="psoas_l-P2"></site>
      <site site="psoas_l-P3"></site>
      <site site="psoas_l-P4"></site>
    </spatial>
    <spatial name="recfem_l_tendon" springlength="0.448493537399412">
      <site site="recfem_l-P1"></site>
      <site site="recfem_l-P2"></site>
      <site site="recfem_l-P3"></site>
      <site site="recfem_l-P4"></site>
      <site site="recfem_l-P5"></site>
    </spatial>
    <spatial name="sart_l_tendon" springlength="0.123999830194402">
      <site site="sart_l-P1"></site>
      <site site="sart_l-P2"></site>
      <site site="sart_l-P3"></site>
      <site site="sart_l-P4"></site>
      <site site="sart_l-P5"></site>
    </spatial>
    <spatial name="semimem_l_tendon" springlength="0.347585979533214">
      <site site="semimem_l-P1"></site>
      <site site="semimem_l-P2"></site>
    </spatial>
    <spatial name="semiten_l_tendon" springlength="0.24719894503751">
      <site site="semiten_l-P1"></site>
      <site site="semiten_l-P2"></site>
      <site site="semiten_l-P3"></site>
    </spatial>
    <spatial name="soleus_l_tendon" springlength="0.276755872375976">
      <site site="soleus_l-P1"></site>
      <site site="soleus_l-P2"></site>
    </spatial>
    <spatial name="tfl_l_tendon" springlength="0.449497053805428">
      <site site="tfl_l-P1"></site>
      <site site="tfl_l-P2"></site>
      <site site="tfl_l-P3"></site>
      <site site="tfl_l-P4"></site>
    </spatial>
    <spatial name="tibant_l_tendon" springlength="0.240461026409367">
      <site site="tibant_l-P1"></site>
      <site site="tibant_l-P2"></site>
      <site site="tibant_l-P3"></site>
      <site site="tibant_l-P4"></site>
    </spatial>
    <spatial name="tibpost_l_tendon" springlength="0.280779613883954">
      <site site="tibpost_l-P1"></site>
      <site site="tibpost_l-P2"></site>
      <site site="tibpost_l-P3"></site>
      <site site="tibpost_l-P4"></site>
    </spatial>
    <spatial name="vasint_l_tendon" springlength="0.202210670345763">
      <site site="vasint_l-P1"></site>
      <site site="vasint_l-P2"></site>
      <site site="vasint_l-P3"></site>
      <site site="vasint_l-P4"></site>
      <site site="vasint_l-P5"></site>
    </spatial>
    <spatial name="vaslat_l_tendon" springlength="0.220601284834603">
      <site site="vaslat_l-P1"></site>
      <site site="vaslat_l-P2"></site>
      <site site="vaslat_l-P3"></site>
      <site site="vaslat_l-P4"></site>
      <site site="vaslat_l-P5"></site>
    </spatial>
    <spatial name="vasmed_l_tendon" springlength="0.199904270842317">
      <site site="vasmed_l-P1"></site>
      <site site="vasmed_l-P2"></site>
      <site site="vasmed_l-P3"></site>
      <site site="vasmed_l-P4"></site>
      <site site="vasmed_l-P5"></site>
    </spatial>
  </tendon>
  <actuator>
    <motor name="lumbar_ext" gear="160" joint="lumbar_extension"></motor>
    <motor name="lumbar_bend" gear="160" joint="lumbar_bending"></motor>
    <motor name="lumbar_rot" gear="100" joint="lumbar_rotation"></motor>
    <motor name="shoulder_flex_r" gear="10" joint="arm_flex_r"></motor>
    <motor name="shoulder_add_r" gear="10" joint="arm_add_r"></motor>
    <motor name="shoulder_rot_r" gear="10" joint="arm_rot_r"></motor>
    <motor name="elbow_flex_r" gear="10" joint="elbow_flex_r"></motor>
    <motor name="pro_sup_r" gear="10" joint="pro_sup_r"></motor>
    <motor name="wrist_flex_r" gear="10" joint="wrist_flex_r"></motor>
    <motor name="wrist_dev_r" gear="10" joint="wrist_dev_r"></motor>
    <motor name="shoulder_flex_l" gear="10" joint="arm_flex_l"></motor>
    <motor name="shoulder_add_l" gear="10" joint="arm_add_l"></motor>
    <motor name="shoulder_rot_l" gear="10" joint="arm_rot_l"></motor>
    <motor name="elbow_flex_l" gear="10" joint="elbow_flex_l"></motor>
    <motor name="pro_sup_l" gear="10" joint="pro_sup_l"></motor>
    <motor name="wrist_flex_l" gear="10" joint="wrist_flex_l"></motor>
    <motor name="wrist_dev_l" gear="10" joint="wrist_dev_l"></motor>
    <muscle name="addbrev_r" tendon="addbrev_r_tendon" lengthrange="0.000886257  1.41801" ctrllimited="true" ctrlrange="0.0 1.0"></muscle>
    <muscle name="addlong_r" tendon="addlong_r_tendon" lengthrange="0.00329498  5.27197" ctrllimited="true" ctrlrange="0.0 1.0"></muscle>
    <muscle name="addmagDist_r" tendon="addmagDist_r_tendon" lengthrange="0.00218452  3.49523" ctrllimited="true" ctrlrange="0.0 1.0"></muscle>
    <muscle name="addmagIsch_r" tendon="addmagIsch_r_tendon" lengthrange="0.00540858  8.65372" ctrllimited="true" ctrlrange="0.0 1.0"></muscle>
    <muscle name="addmagMid_r" tendon="addmagMid_r_tendon" lengthrange="0.00116569  1.86511" ctrllimited="true" ctrlrange="0.0 1.0"></muscle>
    <muscle name="addmagProx_r" tendon="addmagProx_r_tendon" lengthrange="0.0010081  1.61296" ctrllimited="true" ctrlrange="0.0 1.0"></muscle>
    <muscle name="bflh_r" tendon="bflh_r_tendon" lengthrange="0.00813067  13.0091" ctrllimited="true" ctrlrange="0.0 1.0"></muscle>
    <muscle name="bfsh_r" tendon="bfsh_r_tendon" lengthrange="0.00264543  4.23269" ctrllimited="true" ctrlrange="0.0 1.0"></muscle>
    <muscle name="edl_r" tendon="edl_r_tendon" lengthrange="0.00922188   14.755" ctrllimited="true" ctrlrange="0.0 1.0"></muscle>
    <muscle name="ehl_r" tendon="ehl_r_tendon" lengthrange="0.00816988  13.0718" ctrllimited="true" ctrlrange="0.0 1.0"></muscle>
    <muscle name="fdl_r" tendon="fdl_r_tendon" lengthrange="0.00946932  15.1509" ctrllimited="true" ctrlrange="0.0 1.0"></muscle>
    <muscle name="fhl_r" tendon="fhl_r_tendon" lengthrange="0.00885849  14.1736" ctrllimited="true" ctrlrange="0.0 1.0"></muscle>
    <muscle name="gaslat_r" tendon="gaslat_r_tendon" lengthrange="0.00940175  15.0428" ctrllimited="true" ctrlrange="0.0 1.0"></muscle>
    <muscle name="gasmed_r" tendon="gasmed_r_tendon" lengthrange="0.00996791  15.9487" ctrllimited="true" ctrlrange="0.0 1.0"></muscle>
    <muscle name="glmax1_r" tendon="glmax1_r_tendon" lengthrange="0.00122102  1.95364" ctrllimited="true" ctrlrange="0.0 1.0"></muscle>
    <muscle name="glmax2_r" tendon="glmax2_r_tendon" lengthrange="0.00169718  2.71549" ctrllimited="true" ctrlrange="0.0 1.0"></muscle>
    <muscle name="glmax3_r" tendon="glmax3_r_tendon" lengthrange="0.00174292  2.78866" ctrllimited="true" ctrlrange="0.0 1.0"></muscle>
    <muscle name="glmed1_r" tendon="glmed1_r_tendon" lengthrange="0.00139542  2.23267" ctrllimited="true" ctrlrange="0.0 1.0"></muscle>
    <muscle name="glmed2_r" tendon="glmed2_r_tendon" lengthrange="0.00163122  2.60995" ctrllimited="true" ctrlrange="0.0 1.0"></muscle>
    <muscle name="glmed3_r" tendon="glmed3_r_tendon" lengthrange="0.00113082  1.80931" ctrllimited="true" ctrlrange="0.0 1.0"></muscle>
    <muscle name="glmin1_r" tendon="glmin1_r_tendon" lengthrange="0.000403445 0.645511" ctrllimited="true" ctrlrange="0.0 1.0"></muscle>
    <muscle name="glmin2_r" tendon="glmin2_r_tendon" lengthrange="0.000652476  1.04396" ctrllimited="true" ctrlrange="0.0 1.0"></muscle>
    <muscle name="glmin3_r" tendon="glmin3_r_tendon" lengthrange="0.00127181   2.0349" ctrllimited="true" ctrlrange="0.0 1.0"></muscle>
    <muscle name="grac_r" tendon="grac_r_tendon" lengthrange="0.00430035  6.88055" ctrllimited="true" ctrlrange="0.0 1.0"></muscle>
    <muscle name="iliacus_r" tendon="iliacus_r_tendon" lengthrange="0.00240302  3.84483" ctrllimited="true" ctrlrange="0.0 1.0"></muscle>
    <muscle name="perbrev_r" tendon="perbrev_r_tendon" lengthrange="0.00368819   5.9011" ctrllimited="true" ctrlrange="0.0 1.0"></muscle>
    <muscle name="perlong_r" tendon="perlong_r_tendon" lengthrange="0.00830552  13.2888" ctrllimited="true" ctrlrange="0.0 1.0"></muscle>
    <muscle name="piri_r" tendon="piri_r_tendon" lengthrange="0.00287266  4.59625" ctrllimited="true" ctrlrange="0.0 1.0"></muscle>
    <muscle name="psoas_r" tendon="psoas_r_tendon" lengthrange="0.00248858  3.98173" ctrllimited="true" ctrlrange="0.0 1.0"></muscle>
    <muscle name="recfem_r" tendon="recfem_r_tendon" lengthrange="0.0112123  17.9397" ctrllimited="true" ctrlrange="0.0 1.0"></muscle>
    <muscle name="sart_r" tendon="sart_r_tendon" lengthrange="  0.0031  4.95999" ctrllimited="true" ctrlrange="0.0 1.0"></muscle>
    <muscle name="semimem_r" tendon="semimem_r_tendon" lengthrange="0.00868965  13.9034" ctrllimited="true" ctrlrange="0.0 1.0"></muscle>
    <muscle name="semiten_r" tendon="semiten_r_tendon" lengthrange="0.00617997  9.88796" ctrllimited="true" ctrlrange="0.0 1.0"></muscle>
    <muscle name="soleus_r" tendon="soleus_r_tendon" lengthrange="0.0069189  11.0702" ctrllimited="true" ctrlrange="0.0 1.0"></muscle>
    <muscle name="tfl_r" tendon="tfl_r_tendon" lengthrange="0.0112374  17.9799" ctrllimited="true" ctrlrange="0.0 1.0"></muscle>
    <muscle name="tibant_r" tendon="tibant_r_tendon" lengthrange="0.00601153  9.61844" ctrllimited="true" ctrlrange="0.0 1.0"></muscle>
    <muscle name="tibpost_r" tendon="tibpost_r_tendon" lengthrange="0.00701949  11.2312" ctrllimited="true" ctrlrange="0.0 1.0"></muscle>
    <muscle name="vasint_r" tendon="vasint_r_tendon" lengthrange="0.00505527  8.08843" ctrllimited="true" ctrlrange="0.0 1.0"></muscle>
    <muscle name="vaslat_r" tendon="vaslat_r_tendon" lengthrange="0.00551503  8.82405" ctrllimited="true" ctrlrange="0.0 1.0"></muscle>
    <muscle name="vasmed_r" tendon="vasmed_r_tendon" lengthrange="0.00499761  7.99617" ctrllimited="true" ctrlrange="0.0 1.0"></muscle>
    <muscle name="addbrev_l" tendon="addbrev_l_tendon" lengthrange="0.000886257  1.41801" ctrllimited="true" ctrlrange="0.0 1.0"></muscle>
    <muscle name="addlong_l" tendon="addlong_l_tendon" lengthrange="0.00329498  5.27197" ctrllimited="true" ctrlrange="0.0 1.0"></muscle>
    <muscle name="addmagDist_l" tendon="addmagDist_l_tendon" lengthrange="0.00218452  3.49523" ctrllimited="true" ctrlrange="0.0 1.0"></muscle>
    <muscle name="addmagIsch_l" tendon="addmagIsch_l_tendon" lengthrange="0.00540858  8.65372" ctrllimited="true" ctrlrange="0.0 1.0"></muscle>
    <muscle name="addmagMid_l" tendon="addmagMid_l_tendon" lengthrange="0.00116569  1.86511" ctrllimited="true" ctrlrange="0.0 1.0"></muscle>
    <muscle name="addmagProx_l" tendon="addmagProx_l_tendon" lengthrange="0.0010081  1.61296" ctrllimited="true" ctrlrange="0.0 1.0"></muscle>
    <muscle name="bflh_l" tendon="bflh_l_tendon" lengthrange="0.00813067  13.0091" ctrllimited="true" ctrlrange="0.0 1.0"></muscle>
    <muscle name="bfsh_l" tendon="bfsh_l_tendon" lengthrange="0.00264543  4.23269" ctrllimited="true" ctrlrange="0.0 1.0"></muscle>
    <muscle name="edl_l" tendon="edl_l_tendon" lengthrange="0.00922188   14.755" ctrllimited="true" ctrlrange="0.0 1.0"></muscle>
    <muscle name="ehl_l" tendon="ehl_l_tendon" lengthrange="0.00816988  13.0718" ctrllimited="true" ctrlrange="0.0 1.0"></muscle>
    <muscle name="fdl_l" tendon="fdl_l_tendon" lengthrange="0.00946932  15.1509" ctrllimited="true" ctrlrange="0.0 1.0"></muscle>
    <muscle name="fhl_l" tendon="fhl_l_tendon" lengthrange="0.00885849  14.1736" ctrllimited="true" ctrlrange="0.0 1.0"></muscle>
    <muscle name="gaslat_l" tendon="gaslat_l_tendon" lengthrange="0.00940175  15.0428" ctrllimited="true" ctrlrange="0.0 1.0"></muscle>
    <muscle name="gasmed_l" tendon="gasmed_l_tendon" lengthrange="0.00996791  15.9487" ctrllimited="true" ctrlrange="0.0 1.0"></muscle>
    <muscle name="glmax1_l" tendon="glmax1_l_tendon" lengthrange="0.00122102  1.95364" ctrllimited="true" ctrlrange="0.0 1.0"></muscle>
    <muscle name="glmax2_l" tendon="glmax2_l_tendon" lengthrange="0.00169718  2.71549" ctrllimited="true" ctrlrange="0.0 1.0"></muscle>
    <muscle name="glmax3_l" tendon="glmax3_l_tendon" lengthrange="0.00174292  2.78866" ctrllimited="true" ctrlrange="0.0 1.0"></muscle>
    <muscle name="glmed1_l" tendon="glmed1_l_tendon" lengthrange="0.00139542  2.23267" ctrllimited="true" ctrlrange="0.0 1.0"></muscle>
    <muscle name="glmed2_l" tendon="glmed2_l_tendon" lengthrange="0.00163122  2.60995" ctrllimited="true" ctrlrange="0.0 1.0"></muscle>
    <muscle name="glmed3_l" tendon="glmed3_l_tendon" lengthrange="0.00113082  1.80931" ctrllimited="true" ctrlrange="0.0 1.0"></muscle>
    <muscle name="glmin1_l" tendon="glmin1_l_tendon" lengthrange="0.000403445 0.645511" ctrllimited="true" ctrlrange="0.0 1.0"></muscle>
    <muscle name="glmin2_l" tendon="glmin2_l_tendon" lengthrange="0.000652476  1.04396" ctrllimited="true" ctrlrange="0.0 1.0"></muscle>
    <muscle name="glmin3_l" tendon="glmin3_l_tendon" lengthrange="0.00127181   2.0349" ctrllimited="true" ctrlrange="0.0 1.0"></muscle>
    <muscle name="grac_l" tendon="grac_l_tendon" lengthrange="0.00430035  6.88055" ctrllimited="true" ctrlrange="0.0 1.0"></muscle>
    <muscle name="iliacus_l" tendon="iliacus_l_tendon" lengthrange="0.00240302  3.84483" ctrllimited="true" ctrlrange="0.0 1.0"></muscle>
    <muscle name="perbrev_l" tendon="perbrev_l_tendon" lengthrange="0.00368819   5.9011" ctrllimited="true" ctrlrange="0.0 1.0"></muscle>
    <muscle name="perlong_l" tendon="perlong_l_tendon" lengthrange="0.00830552  13.2888" ctrllimited="true" ctrlrange="0.0 1.0"></muscle>
    <muscle name="piri_l" tendon="piri_l_tendon" lengthrange="0.00287266  4.59625" ctrllimited="true" ctrlrange="0.0 1.0"></muscle>
    <muscle name="psoas_l" tendon="psoas_l_tendon" lengthrange="0.00248858  3.98173" ctrllimited="true" ctrlrange="0.0 1.0"></muscle>
    <muscle name="recfem_l" tendon="recfem_l_tendon" lengthrange="0.0112123  17.9397" ctrllimited="true" ctrlrange="0.0 1.0"></muscle>
    <muscle name="sart_l" tendon="sart_l_tendon" lengthrange="  0.0031  4.95999" ctrllimited="true" ctrlrange="0.0 1.0"></muscle>
    <muscle name="semimem_l" tendon="semimem_l_tendon" lengthrange="0.00868965  13.9034" ctrllimited="true" ctrlrange="0.0 1.0"></muscle>
    <muscle name="semiten_l" tendon="semiten_l_tendon" lengthrange="0.00617997  9.88796" ctrllimited="true" ctrlrange="0.0 1.0"></muscle>
    <muscle name="soleus_l" tendon="soleus_l_tendon" lengthrange="0.0069189  11.0702" ctrllimited="true" ctrlrange="0.0 1.0"></muscle>
    <muscle name="tfl_l" tendon="tfl_l_tendon" lengthrange="0.0112374  17.9799" ctrllimited="true" ctrlrange="0.0 1.0"></muscle>
    <muscle name="tibant_l" tendon="tibant_l_tendon" lengthrange="0.00601153  9.61844" ctrllimited="true" ctrlrange="0.0 1.0"></muscle>
    <muscle name="tibpost_l" tendon="tibpost_l_tendon" lengthrange="0.00701949  11.2312" ctrllimited="true" ctrlrange="0.0 1.0"></muscle>
    <muscle name="vasint_l" tendon="vasint_l_tendon" lengthrange="0.00505527  8.08843" ctrllimited="true" ctrlrange="0.0 1.0"></muscle>
    <muscle name="vaslat_l" tendon="vaslat_l_tendon" lengthrange="0.00551503  8.82405" ctrllimited="true" ctrlrange="0.0 1.0"></muscle>
    <muscle name="vasmed_l" tendon="vasmed_l_tendon" lengthrange="0.00499761  7.99617" ctrllimited="true" ctrlrange="0.0 1.0"></muscle>
  </actuator>
  <equality>
    <joint name="knee_angle_r_translation2_constraint" active="true" joint1="knee_angle_r_translation2" joint2="knee_angle_r" polycoef="7.69254e-11 0.00587971 -0.00125622 -2.61846e-06 6.24355e-07" solimp="0.9999 0.9999 0.001 0.5 2"></joint>
    <joint name="knee_angle_r_translation1_constraint" active="true" joint1="knee_angle_r_translation1" joint2="knee_angle_r" polycoef="9.53733e-08 0.00312879 -0.00230804 0.000561561 5.68366e-07" solimp="0.9999 0.9999 0.001 0.5 2"></joint>
    <joint name="knee_angle_r_rotation2_constraint" active="true" joint1="knee_angle_r_rotation2" joint2="knee_angle_r" polycoef="-1.47325e-08   0.0791 -0.0328478 -0.0252183 0.0108321" solimp="0.9999 0.9999 0.001 0.5 2"></joint>
    <joint name="knee_angle_r_rotation3_constraint" active="true" joint1="knee_angle_r_rotation3" joint2="knee_angle_r" polycoef="1.08939e-08 0.369499 -0.169478 0.0251643 3.50498e-07" solimp="0.9999 0.9999 0.001 0.5 2"></joint>
    <joint name="knee_angle_r_beta_translation2_constraint" active="true" joint1="knee_angle_r_beta_translation2" joint2="knee_angle_r" polycoef="-0.0108281 -0.0487847 0.00927644 0.0131673 -0.00349673" solimp="0.9999 0.9999 0.001 0.5 2"></joint>
    <joint name="knee_angle_r_beta_translation1_constraint" active="true" joint1="knee_angle_r_beta_translation1" joint2="knee_angle_r" polycoef="0.0524192 -0.0150188 -0.0340522 0.0133393 -0.000879151" solimp="0.9999 0.9999 0.001 0.5 2"></joint>
    <joint name="knee_angle_r_beta_rotation1_constraint" active="true" joint1="knee_angle_r_beta_rotation1" joint2="knee_angle_r" polycoef="0.010506 0.0247615 -1.31647 0.716337 -0.138302" solimp="0.9999 0.9999 0.001 0.5 2"></joint>
    <joint name="subtalar_angle_r_constraint" active="true" joint1="subtalar_angle_r" polycoef="       0        0        0        0        0"></joint>
    <joint name="mtp_angle_r_constraint" active="true" joint1="mtp_angle_r" polycoef="       0        0        0        0        0"></joint>
    <joint name="knee_angle_l_translation2_constraint" active="true" joint1="knee_angle_l_translation2" joint2="knee_angle_l" polycoef="-7.69254e-11 -0.00587971 0.00125622 2.61846e-06 -6.24355e-07" solimp="0.9999 0.9999 0.001 0.5 2"></joint>
    <joint name="knee_angle_l_translation1_constraint" active="true" joint1="knee_angle_l_translation1" joint2="knee_angle_l" polycoef="9.53733e-08 0.00312879 -0.00230804 0.000561561 5.68366e-07" solimp="0.9999 0.9999 0.001 0.5 2"></joint>
    <joint name="knee_angle_l_rotation2_constraint" active="true" joint1="knee_angle_l_rotation2" joint2="knee_angle_l" polycoef="-1.47325e-08   0.0791 -0.0328478 -0.0252183 0.0108321" solimp="0.9999 0.9999 0.001 0.5 2"></joint>
    <joint name="knee_angle_l_rotation3_constraint" active="true" joint1="knee_angle_l_rotation3" joint2="knee_angle_l" polycoef="-1.08939e-08 -0.369499 0.169478 -0.0251643 -3.50498e-07" solimp="0.9999 0.9999 0.001 0.5 2"></joint>
    <joint name="knee_angle_l_beta_translation2_constraint" active="true" joint1="knee_angle_l_beta_translation2" joint2="knee_angle_l" polycoef="-0.0108281 -0.0487847 0.00927644 0.0131673 -0.00349673" solimp="0.9999 0.9999 0.001 0.5 2"></joint>
    <joint name="knee_angle_l_beta_translation1_constraint" active="true" joint1="knee_angle_l_beta_translation1" joint2="knee_angle_l" polycoef="0.0524192 -0.0150188 -0.0340522 0.0133393 -0.000879151" solimp="0.9999 0.9999 0.001 0.5 2"></joint>
    <joint name="knee_angle_l_beta_rotation1_constraint" active="true" joint1="knee_angle_l_beta_rotation1" joint2="knee_angle_l" polycoef="0.010506 0.0247615 -1.31647 0.716337 -0.138302" solimp="0.9999 0.9999 0.001 0.5 2"></joint>
    <joint name="subtalar_angle_l_constraint" active="true" joint1="subtalar_angle_l" polycoef="       0        0        0        0        0"></joint>
    <joint name="mtp_angle_l_constraint" active="true" joint1="mtp_angle_l" polycoef="       0        0        0        0        0"></joint>
    <joint name="wrist_flex_r_constraint" active="true" joint1="wrist_flex_r" polycoef="       0        0        0        0        0"></joint>
    <joint name="wrist_dev_r_constraint" active="true" joint1="wrist_dev_r" polycoef="       0        0        0        0        0"></joint>
    <joint name="wrist_flex_l_constraint" active="true" joint1="wrist_flex_l" polycoef="       0        0        0        0        0"></joint>
    <joint name="wrist_dev_l_constraint" active="true" joint1="wrist_dev_l" polycoef="       0        0        0        0        0"></joint>
    <weld name="origin_to_worldbody" body1="pelvis" active="false"></weld>
  </equality>
</mujoco>
