<?xml version="1.0" encoding="utf-8"?>
<!--Created by Guoping Zhao, Lauflabor, TU Darmstadt.-->
<!--Based on Hamner2010 OpenSim model.-->
<!--No muscles.-->
<!--Simplify knee joint to a single DoF revolution joint.-->
<!--This model parameters (e.g. contact detection etc.) haven't been optimized.-->
<mujoco model="GZ_DW_sub01">
  <compiler inertiafromgeom="auto" angle="radian" balanceinertia="true" boundmass="0.001" boundinertia="0.001">
    <lengthrange inttotal="50" useexisting="true"></lengthrange>
  </compiler>
  <default>
    <joint limited="true" damping="1.0" armature="0.01" stiffness="1.0"></joint>
    <geom rgba="0.8 0.6 .4 1" margin="0.001" condim="1" group="0"></geom>
    <site size="0.001"></site>
    <tendon width="0.001" rgba=".95 .3 .3 1" limited="false"></tendon>
    <motor ctrllimited="true" ctrlrange="-1.0 1.0"/>
  </default>
  <option integrator="RK4" iterations="50" timestep="0.001"></option>
  <size njmax="1000" nconmax="400" nuser_jnt="1"></size>
  <worldbody>
    <geom name="floor" pos="0 0 0" size="500 500 0.125" type="plane" material="MatPlane" condim="3" group="2" rgba="0.8 0.9 0.8 1"></geom>
    <light cutoff="100" diffuse="1 1 1" dir="-0 0 -1.3" directional="true" exponent="1" pos="0 0 1.3" specular=".1 .1 .1" castshadow="false"/>
    <body name="pelvis" pos="       0 6.73556e-17      0.975" quat="0.7071067811865475 0.7071067811865475 0.0 0.0">
      <light name="spotlight" mode="trackcom" pos="0 10 2" dir="0 -1 0"/>
      <geom name="sacrum" type="mesh" mesh="sacrum"></geom>
      <geom name="pelvis" type="mesh" mesh="pelvis"></geom>
      <geom name="l_pelvis" type="mesh" mesh="l_pelvis"></geom>
      <inertial pos="-0.0721882        0        0" mass="13.5729922649758" fullinertia="0.123517 0.104653 0.0695686        0        0        0"></inertial>
      <camera name="track" mode="trackcom" pos="0 0 4" xyaxes="1 0 0 0 1 0"/>
      <joint name="pelvis_tx" type="slide" pos="0 0 0" axis="       1        0        0" limited="false" range="-500        500" ref="0" armature="0" damping="0" stiffness="0"></joint>
      <joint name="pelvis_tz" type="slide" pos="0 0 0" axis="       0        0        1" limited="false" range="-300        300" ref="0" armature="0" damping="0" stiffness="0"></joint>
      <joint name="pelvis_ty" type="slide" pos="0 0 0" axis="       0        1        0" limited="false" range="-100        200" ref="0" armature="0" damping="0" stiffness="0"></joint>
      <joint name="pelvis_tilt" type="hinge" pos="0 0 0" axis="       0        0        1" limited="false" range=" -1.5708   1.5708" ref="0" armature="0" damping="0" stiffness="0"></joint>
      <joint name="pelvis_list" type="hinge" pos="0 0 0" axis="       1        0        0" limited="false" range=" -1.5708   1.5708" ref="0" armature="0" damping="0" stiffness="0"></joint>
      <joint name="pelvis_rotation" type="hinge" pos="0 0 0" axis="       0        1        0" limited="false" range=" -1.5708   1.5708" ref="0" armature="0" damping="0" stiffness="0"></joint>
      <body name="femur_r" pos="-0.0721882 -0.0674914 0.0852576" quat="1.0 0.0 0.0 0.0">
        <geom name="femur_r" type="mesh" mesh="femur_r"></geom>
        <inertial pos="       0 -0.154514        0" mass="10.7198633143794" fullinertia="0.127486 0.0334185 0.134436        0        0        0"></inertial>
        <joint name="hip_flexion_r" damping="5" stiffness="10" type="hinge" pos="0 0 0" axis="       0        0        1" limited="true" range=" -0.787   0.787" ref="0"></joint>
        <joint name="hip_adduction_r" damping="5" stiffness="10" type="hinge" pos="0 0 0" axis="       1        0        0" limited="true" range=" -0.524   0.524" ref="0"></joint>
        <joint name="hip_rotation_r" damping="5" stiffness="20" type="hinge" pos="0 0 0" axis="       0        1        0" limited="true" range=" -2.0944   2.0944" ref="0"></joint>
        <body name="tibia_r" pos="-0.00167398 -0.365545        0" quat="1.0 0.0 0.0 0.0">
          <geom name="tibia_r" type="mesh" mesh="tibia_r"></geom>
          <geom name="fibula_r" type="mesh" mesh="fibula_r"></geom>
          <inertial pos="       0 -0.208485        0" mass="4.27289367601238" fullinertia="0.072432 0.00732943 0.073438        0        0        0"></inertial>
          <joint name="knee_angle_r" type="hinge" pos="0 0 0" axis="       0        0        1" limited="true" range=" -2.0944 0.174533" ref="0"></joint>
          <body name="talus_r" pos="       0 -0.480173        0" quat="1.0 0.0 0.0 0.0">
            <geom name="talus_rv" type="mesh" mesh="talus_rv"></geom>
            <inertial pos="       0        0        0" mass="0.11524999800438" fullinertia="0.00143714 0.00143714 0.00143714        0        0        0"></inertial>
            <joint name="ankle_angle_r" stiffness="10" damping="1" type="hinge" pos="0 0 0" axis="-0.105014 -0.174022 0.979126" limited="true" range=" -1.5708   1.5708" ref="0"></joint>
            <body name="calcn_r" pos="-0.0544606 -0.0468448 0.00884412" quat="1.0 0.0 0.0 0.0">
              <geom name="r_foot" type="mesh" mesh="foot"></geom>
              <inertial pos="0.106552 0.0319656        0" mass="1.44062497505475" fullinertia="0.00183186 0.00510303 0.00536472        0        0        0"></inertial>
              <joint name="subtalar_angle_r" armature="0.01" type="hinge" pos="0 0 0" axis=" 0.78718 0.604747 -0.120949" limited="true" range=" -1.5708   1.5708" ref="0"></joint>
              <body name="toes_r" pos="0.190515 -0.00213104 0.00115076" quat="1.0 0.0 0.0 0.0">
                <geom name="r_bofoot" type="mesh" mesh="bofoot"></geom>
                <inertial pos="0.036867 0.00639311 -0.0186466" mass="0.249631495677486" fullinertia="0.000130847 0.000261694 0.00130847        0        0        0"></inertial>
                <joint name="mtp_angle_r" armature="0.01" type="hinge" pos="0 0 0" axis="-0.580954        0 0.813936" limited="true" range=" -1.5708   1.5708" ref="0"></joint>
              </body>
            </body>
          </body>
        </body>
      </body>
      <body name="femur_l" pos="-0.0721882 -0.0674914 -0.0852576" quat="1.0 0.0 0.0 0.0">
        <geom name="femur_l" type="mesh" mesh="femur_l"></geom>
        <inertial pos="       0 -0.154514        0" mass="10.7198633143794" fullinertia="0.127486 0.0334185 0.134436        0        0        0"></inertial>
        <joint name="hip_flexion_l" damping="5" stiffness="10" type="hinge" pos="0 0 0" axis="       0        0        1" limited="true" range=" -0.787   0.787" ref="0"></joint>
        <joint name="hip_adduction_l" damping="5" stiffness="10" type="hinge" pos="0 0 0" axis="      -1        0        0" limited="true" range=" -0.524   0.524" ref="0"></joint>
        <joint name="hip_rotation_l" damping="5" stiffness="20" type="hinge" pos="0 0 0" axis="       0       -1        0" limited="true" range=" -2.0944   2.0944" ref="0"></joint>
        <body name="tibia_l" pos="-0.00167398 -0.365545        0" quat="1.0 0.0 0.0 0.0">
          <geom name="tibia_l" type="mesh" mesh="tibia_l"></geom>
          <geom name="fibula_l" type="mesh" mesh="fibula_l"></geom>
          <inertial pos="       0 -0.208485        0" mass="4.27289367601238" fullinertia="0.072432 0.00732943 0.073438        0        0        0"></inertial>
          <joint name="knee_angle_l" type="hinge" pos="0 0 0" axis="       0        0        1" limited="true" range=" -2.0944 0.174533" ref="0"></joint>
          <body name="talus_l" pos="       0 -0.480173        0" quat="1.0 0.0 0.0 0.0">
            <geom name="talus_lv" type="mesh" mesh="talus_lv"></geom>
            <inertial pos="       0        0        0" mass="0.11524999800438" fullinertia="0.00143714 0.00143714 0.00143714        0        0        0"></inertial>
            <joint name="ankle_angle_l"  stiffness="10" damping="1" type="hinge" pos="0 0 0" axis="0.105014 0.174022 0.979126" limited="true" range=" -1.0472   1.0472" ref="0"></joint>
            <body name="calcn_l" pos="-0.0544606 -0.0468448 -0.00884412" quat="1.0 0.0 0.0 0.0">
              <geom name="l_foot" type="mesh" mesh="l_foot"></geom>
              <inertial pos="0.106552 0.0319656        0" mass="1.44062497505475" fullinertia="0.00183186 0.00510303 0.00536472        0        0        0"></inertial>
              <joint name="subtalar_angle_l" armature="0.01" type="hinge" pos="0 0 0" axis="-0.78718 -0.604747 -0.120949" limited="true" range=" -1.5708   1.5708" ref="0"></joint>
              <body name="toes_l" pos="0.190515 -0.00213104 -0.00115076" quat="1.0 0.0 0.0 0.0">
                <geom name="l_bofoot" type="mesh" mesh="l_bofoot"></geom>
                <inertial pos="0.036867 0.00639311 0.0186466" mass="0.249631495677486" fullinertia="0.000130847 0.000261694 0.00130847        0        0        0"></inertial>
                <joint name="mtp_angle_l" armature="0.01" type="hinge" pos="0 0 0" axis="0.580954        0 0.813936" limited="true" range=" -1.0472   1.0472" ref="0"></joint>
              </body>
            </body>
          </body>
        </body>
      </body>
      <body name="torso" pos="-0.10282 0.0832155        0" quat="1.0 0.0 0.0 0.0">
        <geom name="hat_spine" type="mesh" mesh="hat_spine"></geom>
        <geom name="hat_jaw" type="mesh" mesh="hat_jaw"></geom>
        <geom name="hat_skull" type="mesh" mesh="hat_skull"></geom>
        <geom name="hat_ribs_scap" type="mesh" mesh="hat_ribs_scap"></geom>
        <inertial pos="-0.0323208 0.344755        0" mass="30.9176559646429" fullinertia=" 1.97246  1.01064   1.9148        0        0        0"></inertial>
        <joint name="lumbar_extension" stiffness="10" damping="5" type="hinge" pos="0 0 0" axis="       0        0        1" limited="true" range=" -1.5708   0.377" ref="0"></joint>
        <joint name="lumbar_bending" stiffness="10" damping="5" type="hinge" pos="0 0 0" axis="       1        0        0" limited="true" range=" -0.754   0.754" ref="0"></joint>
        <joint name="lumbar_rotation" stiffness="20" damping="5" type="hinge" pos="0 0 0" axis="       0        1        0" limited="true" range=" -0.754   0.754" ref="0"></joint>
        <body name="humerus_r" pos="0.00339907 0.400239 0.183151" quat="1.0 0.0 0.0 0.0">
          <geom name="humerus_rv" type="mesh" mesh="humerus_rv"></geom>
          <inertial pos="       0 -0.193252        0" mass="2.34245620943902" fullinertia="0.0190007 0.00655464 0.0213276        0        0        0"></inertial>
          <joint name="arm_flex_r" type="hinge" pos="0 0 0" axis="       0        0        1" limited="true" range=" -1.5708   1.5708" ref="0"></joint>
          <joint name="arm_add_r" type="hinge" pos="0 0 0" axis="       1        0        0" limited="true" range=" -2.0944   1.5708" ref="0"></joint>
          <joint name="arm_rot_r" type="hinge" pos="0 0 0" axis="       0        1        0" limited="true" range=" -1.5708   1.5708" ref="0"></joint>
          <body name="ulna_r" pos="0.0154412 -0.336305 -0.0112719" quat="1.0 0.0 0.0 0.0">
            <geom name="ulna_rv" type="mesh" mesh="ulna_rv"></geom>
            <inertial pos="       0 -0.133575        0" mass="0.700143737876607" fullinertia="0.00419295 0.000874829 0.00454826        0        0        0"></inertial>
            <joint name="elbow_flex_r" stiffness="0" type="hinge" pos="0 0 0" axis="0.226047 0.022269 0.973862" limited="true" range="       -0.3    2.618" ref="0"></joint>
            <body name="radius_r" pos="-0.00745535 -0.0144153 0.0289071" quat="1.0 0.0 0.0 0.0">
              <geom name="radius_rv" type="mesh" mesh="radius_rv"></geom>
              <inertial pos="       0 -0.133575        0" mass="0.700143737876607" fullinertia="0.00419295 0.000874829 0.00454826        0        0        0"></inertial>
              <joint name="pro_sup_r" stiffness="0" type="hinge" pos="0 0 0" axis="0.056398 0.998406 0.001952" limited="true" range="       -0.6   1.5708" ref="0"></joint>
              <body name="hand_r" pos="-0.00974948 -0.261376 0.0150836" quat="1.0 0.0 0.0 0.0">
                <geom name="pisiform_rvs" type="mesh" mesh="pisiform_rvs"></geom>
                <geom name="lunate_rvs" type="mesh" mesh="lunate_rvs"></geom>
                <geom name="scaphoid_rvs" type="mesh" mesh="scaphoid_rvs"></geom>
                <geom name="triquetrum_rvs" type="mesh" mesh="triquetrum_rvs"></geom>
                <geom name="hamate_rvs" type="mesh" mesh="hamate_rvs"></geom>
                <geom name="capitate_rvs" type="mesh" mesh="capitate_rvs"></geom>
                <geom name="trapezoid_rvs" type="mesh" mesh="trapezoid_rvs"></geom>
                <geom name="trapezium_rvs" type="mesh" mesh="trapezium_rvs"></geom>
                <geom name="metacarpal2_rvs" type="mesh" mesh="metacarpal2_rvs"></geom>
                <geom name="index_proximal_rvs" type="mesh" mesh="index_proximal_rvs"></geom>
                <geom name="index_medial_rvs" type="mesh" mesh="index_medial_rvs"></geom>
                <geom name="index_distal_rvs" type="mesh" mesh="index_distal_rvs"></geom>
                <geom name="metacarpal3_rvs" type="mesh" mesh="metacarpal3_rvs"></geom>
                <geom name="middle_proximal_rvs" type="mesh" mesh="middle_proximal_rvs"></geom>
                <geom name="middle_medial_rvs" type="mesh" mesh="middle_medial_rvs"></geom>
                <geom name="middle_distal_rvs" type="mesh" mesh="middle_distal_rvs"></geom>
                <geom name="metacarpal4_rvs" type="mesh" mesh="metacarpal4_rvs"></geom>
                <geom name="ring_proximal_rvs" type="mesh" mesh="ring_proximal_rvs"></geom>
                <geom name="ring_medial_rvs" type="mesh" mesh="ring_medial_rvs"></geom>
                <geom name="ring_distal_rvs" type="mesh" mesh="ring_distal_rvs"></geom>
                <geom name="metacarpal5_rvs" type="mesh" mesh="metacarpal5_rvs"></geom>
                <geom name="little_proximal_rvs" type="mesh" mesh="little_proximal_rvs"></geom>
                <geom name="little_medial_rvs" type="mesh" mesh="little_medial_rvs"></geom>
                <geom name="little_distal_rvs" type="mesh" mesh="little_distal_rvs"></geom>
                <geom name="metacarpal1_rvs" type="mesh" mesh="metacarpal1_rvs"></geom>
                <geom name="thumb_proximal_rvs" type="mesh" mesh="thumb_proximal_rvs"></geom>
                <geom name="thumb_distal_rvs" type="mesh" mesh="thumb_distal_rvs"></geom>
                <inertial pos="       0 -0.0725565        0" mass="0.527268740870037" fullinertia="0.00116715 0.000715732 0.00175335        0        0        0"></inertial>
                <joint name="wrist_flex_r" stiffness="0" type="hinge" pos="0 0 0" axis="       0        0        1" limited="true" range="-1.22173  1.22173" ref="0"></joint>
                <joint name="wrist_dev_r" stiffness="0" type="hinge" pos="0 0 0" axis="       1        0        0" limited="true" range="-0.436332 0.610865" ref="0"></joint>
              </body>
            </body>
          </body>
        </body>
        <body name="humerus_l" pos="0.00339907 0.400239 -0.183151" quat="1.0 0.0 0.0 0.0">
          <geom name="humerus_lv" type="mesh" mesh="humerus_lv"></geom>
          <inertial pos="       0 -0.193252        0" mass="2.34245620943902" fullinertia="0.0190007 0.00655464 0.0213276        0        0        0"></inertial>
          <joint name="arm_flex_l" type="hinge" pos="0 0 0" axis="       0        0        1" limited="true" range=" -1.5708   1.5708" ref="0"></joint>
          <joint name="arm_add_l" type="hinge" pos="0 0 0" axis="      -1        0        0" limited="true" range=" -2.0944   1.5708" ref="0"></joint>
          <joint name="arm_rot_l" type="hinge" pos="0 0 0" axis="       0       -1        0" limited="true" range=" -1.5708   1.5708" ref="0"></joint>
          <body name="ulna_l" pos="0.0154412 -0.336305 0.0112719" quat="1.0 0.0 0.0 0.0">
            <geom name="ulna_lv" type="mesh" mesh="ulna_lv"></geom>
            <inertial pos="       0 -0.133575        0" mass="0.700143737876607" fullinertia="0.00419295 0.000874829 0.00454826        0        0        0"></inertial>
            <joint name="elbow_flex_l" stiffness="0" type="hinge" pos="0 0 0" axis="-0.226047 -0.022269 0.973862" limited="true" range="       -0.3    2.618" ref="0"></joint>
            <body name="radius_l" pos="-0.00745535 -0.0144153 -0.0289071" quat="1.0 0.0 0.0 0.0">
              <geom name="radius_lv" type="mesh" mesh="radius_lv"></geom>
              <inertial pos="       0 -0.133575        0" mass="0.700143737876607" fullinertia="0.00419295 0.000874829 0.00454826        0        0        0"></inertial>
              <joint name="pro_sup_l" stiffness="0" type="hinge" pos="0 0 0" axis="-0.056398 -0.998406 0.001952" limited="true" range="       -0.60   1.5708" ref="0"></joint>
              <body name="hand_l" pos="-0.00974948 -0.261376 -0.0150836" quat="1.0 0.0 0.0 0.0">
                <geom name="pisiform_lvs" type="mesh" mesh="pisiform_lvs"></geom>
                <geom name="lunate_lvs" type="mesh" mesh="lunate_lvs"></geom>
                <geom name="scaphoid_lvs" type="mesh" mesh="scaphoid_lvs"></geom>
                <geom name="triquetrum_lvs" type="mesh" mesh="triquetrum_lvs"></geom>
                <geom name="hamate_lvs" type="mesh" mesh="hamate_lvs"></geom>
                <geom name="capitate_lvs" type="mesh" mesh="capitate_lvs"></geom>
                <geom name="trapezoid_lvs" type="mesh" mesh="trapezoid_lvs"></geom>
                <geom name="trapezium_lvs" type="mesh" mesh="trapezium_lvs"></geom>
                <geom name="metacarpal2_lvs" type="mesh" mesh="metacarpal2_lvs"></geom>
                <geom name="index_proximal_lvs" type="mesh" mesh="index_proximal_lvs"></geom>
                <geom name="index_medial_lvs" type="mesh" mesh="index_medial_lvs"></geom>
                <geom name="index_distal_lvs" type="mesh" mesh="index_distal_lvs"></geom>
                <geom name="metacarpal3_lvs" type="mesh" mesh="metacarpal3_lvs"></geom>
                <geom name="middle_proximal_lvs" type="mesh" mesh="middle_proximal_lvs"></geom>
                <geom name="middle_medial_lvs" type="mesh" mesh="middle_medial_lvs"></geom>
                <geom name="middle_distal_lvs" type="mesh" mesh="middle_distal_lvs"></geom>
                <geom name="metacarpal4_lvs" type="mesh" mesh="metacarpal4_lvs"></geom>
                <geom name="ring_proximal_lvs" type="mesh" mesh="ring_proximal_lvs"></geom>
                <geom name="ring_medial_lvs" type="mesh" mesh="ring_medial_lvs"></geom>
                <geom name="ring_distal_lvs" type="mesh" mesh="ring_distal_lvs"></geom>
                <geom name="metacarpal5_lvs" type="mesh" mesh="metacarpal5_lvs"></geom>
                <geom name="little_proximal_lvs" type="mesh" mesh="little_proximal_lvs"></geom>
                <geom name="little_medial_lvs" type="mesh" mesh="little_medial_lvs"></geom>
                <geom name="little_distal_lvs" type="mesh" mesh="little_distal_lvs"></geom>
                <geom name="metacarpal1_lvs" type="mesh" mesh="metacarpal1_lvs"></geom>
                <geom name="thumb_proximal_lvs" type="mesh" mesh="thumb_proximal_lvs"></geom>
                <geom name="thumb_distal_lvs" type="mesh" mesh="thumb_distal_lvs"></geom>
                <inertial pos="       0 -0.0725565        0" mass="0.527268740870037" fullinertia="0.00116715 0.000715732 0.00175335        0        0        0"></inertial>
                <joint name="wrist_flex_l" stiffness="0" type="hinge" pos="0 0 0" axis="       0        0        1" limited="true" range="-1.22173  1.22173" ref="0"></joint>
                <joint name="wrist_dev_l" stiffness="0" type="hinge" pos="0 0 0" axis="      -1        0        0" limited="true" range="-0.436332 0.610865" ref="0"></joint>
              </body>
            </body>
          </body>
        </body>
      </body>
    </body>
  </worldbody>
  <asset>
    <mesh name="sacrum" file="meshes/sacrum.stl" scale=" 1.02105  1.02105  1.02105"></mesh>
    <mesh name="pelvis" file="meshes/pelvis.stl" scale=" 1.02105  1.02105  1.02105"></mesh>
    <mesh name="l_pelvis" file="meshes/l_pelvis.stl" scale=" 1.02105  1.02105  1.02105"></mesh>
    <mesh name="femur_r" file="meshes/femur_r.stl" scale="0.908907 0.908907 0.908907"></mesh>
    <mesh name="tibia_r" file="meshes/tibia_r.stl" scale=" 1.11668  1.11668  1.11668"></mesh>
    <mesh name="fibula_r" file="meshes/fibula_r.stl" scale=" 1.11668  1.11668  1.11668"></mesh>
    <mesh name="talus_rv" file="meshes/talus_rv.stl" scale=" 1.11668  1.11668  1.11668"></mesh>
    <mesh name="foot" file="meshes/foot.stl" scale=" 1.06552  1.06552  1.06552"></mesh>
    <mesh name="bofoot" file="meshes/bofoot.stl" scale=" 1.06552  1.06552  1.06552"></mesh>
    <mesh name="femur_l" file="meshes/femur_l.stl" scale="0.908907 0.908907 0.908907"></mesh>
    <mesh name="tibia_l" file="meshes/tibia_l.stl" scale=" 1.11668  1.11668  1.11668"></mesh>
    <mesh name="fibula_l" file="meshes/fibula_l.stl" scale=" 1.11668  1.11668  1.11668"></mesh>
    <mesh name="talus_lv" file="meshes/talus_lv.stl" scale=" 1.11668  1.11668  1.11668"></mesh>
    <mesh name="l_foot" file="meshes/l_foot.stl" scale=" 1.06552  1.06552  1.06552"></mesh>
    <mesh name="l_bofoot" file="meshes/l_bofoot.stl" scale=" 1.06552  1.06552  1.06552"></mesh>
    <mesh name="hat_spine" file="meshes/hat_spine.stl" scale=" 1.07736  1.07736  1.07736"></mesh>
    <mesh name="hat_jaw" file="meshes/hat_jaw.stl" scale=" 1.07736  1.07736  1.07736"></mesh>
    <mesh name="hat_skull" file="meshes/hat_skull.stl" scale=" 1.07736  1.07736  1.07736"></mesh>
    <mesh name="hat_ribs_scap" file="meshes/hat_ribs_scap.stl" scale=" 1.07736  1.07736  1.07736"></mesh>
    <mesh name="humerus_rv" file="meshes/humerus_rv.stl" scale=" 1.17477  1.17477  1.17477"></mesh>
    <mesh name="ulna_rv" file="meshes/ulna_rv.stl" scale=" 1.10827  1.10827  1.10827"></mesh>
    <mesh name="radius_rv" file="meshes/radius_rv.stl" scale=" 1.10827  1.10827  1.10827"></mesh>
    <mesh name="pisiform_rvs" file="meshes/pisiform_rvs.stl" scale="0.905691 0.905691 0.905691"></mesh>
    <mesh name="lunate_rvs" file="meshes/lunate_rvs.stl" scale="0.905691 0.905691 0.905691"></mesh>
    <mesh name="scaphoid_rvs" file="meshes/scaphoid_rvs.stl" scale="0.905691 0.905691 0.905691"></mesh>
    <mesh name="triquetrum_rvs" file="meshes/triquetrum_rvs.stl" scale="0.905691 0.905691 0.905691"></mesh>
    <mesh name="hamate_rvs" file="meshes/hamate_rvs.stl" scale="0.905691 0.905691 0.905691"></mesh>
    <mesh name="capitate_rvs" file="meshes/capitate_rvs.stl" scale="0.905691 0.905691 0.905691"></mesh>
    <mesh name="trapezoid_rvs" file="meshes/trapezoid_rvs.stl" scale="0.905691 0.905691 0.905691"></mesh>
    <mesh name="trapezium_rvs" file="meshes/trapezium_rvs.stl" scale="0.905691 0.905691 0.905691"></mesh>
    <mesh name="metacarpal2_rvs" file="meshes/metacarpal2_rvs.stl" scale="0.905691 0.905691 0.905691"></mesh>
    <mesh name="index_proximal_rvs" file="meshes/index_proximal_rvs.stl" scale="0.905691 0.905691 0.905691"></mesh>
    <mesh name="index_medial_rvs" file="meshes/index_medial_rvs.stl" scale="0.905691 0.905691 0.905691"></mesh>
    <mesh name="index_distal_rvs" file="meshes/index_distal_rvs.stl" scale="0.905691 0.905691 0.905691"></mesh>
    <mesh name="metacarpal3_rvs" file="meshes/metacarpal3_rvs.stl" scale="0.905691 0.905691 0.905691"></mesh>
    <mesh name="middle_proximal_rvs" file="meshes/middle_proximal_rvs.stl" scale="0.905691 0.905691 0.905691"></mesh>
    <mesh name="middle_medial_rvs" file="meshes/middle_medial_rvs.stl" scale="0.905691 0.905691 0.905691"></mesh>
    <mesh name="middle_distal_rvs" file="meshes/middle_distal_rvs.stl" scale="0.905691 0.905691 0.905691"></mesh>
    <mesh name="metacarpal4_rvs" file="meshes/metacarpal4_rvs.stl" scale="0.905691 0.905691 0.905691"></mesh>
    <mesh name="ring_proximal_rvs" file="meshes/ring_proximal_rvs.stl" scale="0.905691 0.905691 0.905691"></mesh>
    <mesh name="ring_medial_rvs" file="meshes/ring_medial_rvs.stl" scale="0.905691 0.905691 0.905691"></mesh>
    <mesh name="ring_distal_rvs" file="meshes/ring_distal_rvs.stl" scale="0.905691 0.905691 0.905691"></mesh>
    <mesh name="metacarpal5_rvs" file="meshes/metacarpal5_rvs.stl" scale="0.905691 0.905691 0.905691"></mesh>
    <mesh name="little_proximal_rvs" file="meshes/little_proximal_rvs.stl" scale="0.905691 0.905691 0.905691"></mesh>
    <mesh name="little_medial_rvs" file="meshes/little_medial_rvs.stl" scale="0.905691 0.905691 0.905691"></mesh>
    <mesh name="little_distal_rvs" file="meshes/little_distal_rvs.stl" scale="0.905691 0.905691 0.905691"></mesh>
    <mesh name="metacarpal1_rvs" file="meshes/metacarpal1_rvs.stl" scale="0.905691 0.905691 0.905691"></mesh>
    <mesh name="thumb_proximal_rvs" file="meshes/thumb_proximal_rvs.stl" scale="0.905691 0.905691 0.905691"></mesh>
    <mesh name="thumb_distal_rvs" file="meshes/thumb_distal_rvs.stl" scale="0.905691 0.905691 0.905691"></mesh>
    <mesh name="humerus_lv" file="meshes/humerus_lv.stl" scale=" 1.17477  1.17477  1.17477"></mesh>
    <mesh name="ulna_lv" file="meshes/ulna_lv.stl" scale=" 1.10827  1.10827  1.10827"></mesh>
    <mesh name="radius_lv" file="meshes/radius_lv.stl" scale=" 1.10827  1.10827  1.10827"></mesh>
    <mesh name="pisiform_lvs" file="meshes/pisiform_lvs.stl" scale="0.905691 0.905691 0.905691"></mesh>
    <mesh name="lunate_lvs" file="meshes/lunate_lvs.stl" scale="0.905691 0.905691 0.905691"></mesh>
    <mesh name="scaphoid_lvs" file="meshes/scaphoid_lvs.stl" scale="0.905691 0.905691 0.905691"></mesh>
    <mesh name="triquetrum_lvs" file="meshes/triquetrum_lvs.stl" scale="0.905691 0.905691 0.905691"></mesh>
    <mesh name="hamate_lvs" file="meshes/hamate_lvs.stl" scale="0.905691 0.905691 0.905691"></mesh>
    <mesh name="capitate_lvs" file="meshes/capitate_lvs.stl" scale="0.905691 0.905691 0.905691"></mesh>
    <mesh name="trapezoid_lvs" file="meshes/trapezoid_lvs.stl" scale="0.905691 0.905691 0.905691"></mesh>
    <mesh name="trapezium_lvs" file="meshes/trapezium_lvs.stl" scale="0.905691 0.905691 0.905691"></mesh>
    <mesh name="metacarpal2_lvs" file="meshes/metacarpal2_lvs.stl" scale="0.905691 0.905691 0.905691"></mesh>
    <mesh name="index_proximal_lvs" file="meshes/index_proximal_lvs.stl" scale="0.905691 0.905691 0.905691"></mesh>
    <mesh name="index_medial_lvs" file="meshes/index_medial_lvs.stl" scale="0.905691 0.905691 0.905691"></mesh>
    <mesh name="index_distal_lvs" file="meshes/index_distal_lvs.stl" scale="0.905691 0.905691 0.905691"></mesh>
    <mesh name="metacarpal3_lvs" file="meshes/metacarpal3_lvs.stl" scale="0.905691 0.905691 0.905691"></mesh>
    <mesh name="middle_proximal_lvs" file="meshes/middle_proximal_lvs.stl" scale="0.905691 0.905691 0.905691"></mesh>
    <mesh name="middle_medial_lvs" file="meshes/middle_medial_lvs.stl" scale="0.905691 0.905691 0.905691"></mesh>
    <mesh name="middle_distal_lvs" file="meshes/middle_distal_lvs.stl" scale="0.905691 0.905691 0.905691"></mesh>
    <mesh name="metacarpal4_lvs" file="meshes/metacarpal4_lvs.stl" scale="0.905691 0.905691 0.905691"></mesh>
    <mesh name="ring_proximal_lvs" file="meshes/ring_proximal_lvs.stl" scale="0.905691 0.905691 0.905691"></mesh>
    <mesh name="ring_medial_lvs" file="meshes/ring_medial_lvs.stl" scale="0.905691 0.905691 0.905691"></mesh>
    <mesh name="ring_distal_lvs" file="meshes/ring_distal_lvs.stl" scale="0.905691 0.905691 0.905691"></mesh>
    <mesh name="metacarpal5_lvs" file="meshes/metacarpal5_lvs.stl" scale="0.905691 0.905691 0.905691"></mesh>
    <mesh name="little_proximal_lvs" file="meshes/little_proximal_lvs.stl" scale="0.905691 0.905691 0.905691"></mesh>
    <mesh name="little_medial_lvs" file="meshes/little_medial_lvs.stl" scale="0.905691 0.905691 0.905691"></mesh>
    <mesh name="little_distal_lvs" file="meshes/little_distal_lvs.stl" scale="0.905691 0.905691 0.905691"></mesh>
    <mesh name="metacarpal1_lvs" file="meshes/metacarpal1_lvs.stl" scale="0.905691 0.905691 0.905691"></mesh>
    <mesh name="thumb_proximal_lvs" file="meshes/thumb_proximal_lvs.stl" scale="0.905691 0.905691 0.905691"></mesh>
    <mesh name="thumb_distal_lvs" file="meshes/thumb_distal_lvs.stl" scale="0.905691 0.905691 0.905691"></mesh>
    <texture builtin="gradient" height="100" rgb1=".4 .5 .6" rgb2="0 0 0" type="skybox" width="100"/>
    <texture name="texgeom" type="cube" builtin="flat" mark="cross" width="127" height="1278" rgb1="0.8 0.6 0.4" rgb2="0.8 0.6 0.4" markrgb="1 1 1" random="0.01"></texture>
    <texture name="texplane" type="2d" builtin="checker" rgb1=".2 .3 .4" rgb2=".1 0.15 0.2" width="100" height="100"></texture>
    <material name="MatPlane" reflectance="0.5" texture="texplane" texrepeat="1 1" texuniform="true"></material>
    <material name="geom" texture="texgeom" texuniform="true"></material> </asset>
  <tendon>
  </tendon>
  <actuator>
    <motor name="mot_lumbar_ext" gear="160" joint="lumbar_extension"></motor>
    <motor name="mot_lumbar_bend" gear="160" joint="lumbar_bending"></motor>
    <motor name="mot_lumbar_rot" gear="100" joint="lumbar_rotation"></motor>
    <motor name="mot_shoulder_flex_r" gear="250" joint="arm_flex_r"></motor>
    <motor name="mot_shoulder_add_r" gear="250" joint="arm_add_r"></motor>
    <motor name="mot_shoulder_rot_r" gear="250" joint="arm_rot_r"></motor>
    <motor name="mot_elbow_flex_r" gear="250" joint="elbow_flex_r"></motor>
    <motor name="mot_pro_sup_r" gear="250" joint="pro_sup_r"></motor>
    <motor name="mot_wrist_flex_r" gear="50" joint="wrist_flex_r"></motor>
    <motor name="mot_wrist_dev_r" gear="50" joint="wrist_dev_r"></motor>
    <motor name="mot_shoulder_flex_l" gear="250" joint="arm_flex_l"></motor>
    <motor name="mot_shoulder_add_l" gear="250" joint="arm_add_l"></motor>
    <motor name="mot_shoulder_rot_l" gear="250" joint="arm_rot_l"></motor>
    <motor name="mot_elbow_flex_l" gear="250" joint="elbow_flex_l"></motor>
    <motor name="mot_pro_sup_l" gear="250" joint="pro_sup_l"></motor>
    <motor name="mot_wrist_flex_l" gear="50" joint="wrist_flex_l"></motor>
    <motor name="mot_wrist_dev_l" gear="50" joint="wrist_dev_l"></motor>
    <motor name="mot_hip_flexion_r" gear="275" joint="hip_flexion_r"></motor>
    <motor name="mot_hip_adduction_r" gear="530" joint="hip_adduction_r"></motor>
    <motor name="mot_hip_rotation_r" gear="600" joint="hip_rotation_r"></motor>
    <motor name="mot_knee_angle_r" gear="600" joint="knee_angle_r"></motor>
    <motor name="mot_ankle_angle_r" gear="500" joint="ankle_angle_r"></motor>
    <motor name="mot_subtalar_angle_r" gear="50" joint="subtalar_angle_r"></motor>
    <motor name="mot_mtp_angle_r" gear="50" joint="mtp_angle_r"></motor>
    <motor name="mot_hip_flexion_l" gear="275" joint="hip_flexion_l"></motor>
    <motor name="mot_hip_adduction_l" gear="530" joint="hip_adduction_l"></motor>
    <motor name="mot_hip_rotation_l" gear="600" joint="hip_rotation_l"></motor>
    <motor name="mot_knee_angle_l" gear="600" joint="knee_angle_l"></motor>
    <motor name="mot_ankle_angle_l" gear="500" joint="ankle_angle_l"></motor>
    <motor name="mot_subtalar_angle_l" gear="50" joint="subtalar_angle_l"></motor>
    <motor name="mot_mtp_angle_l" gear="50" joint="mtp_angle_l"></motor>
  </actuator>
  <equality>
    <joint name="subtalar_angle_r_constraint" active="true" joint1="subtalar_angle_r" polycoef="       0        0        0        0        0"></joint>
    <joint name="mtp_angle_r_constraint" active="true" joint1="mtp_angle_r" polycoef="       0        0        0        0        0"></joint>
    <joint name="subtalar_angle_l_constraint" active="true" joint1="subtalar_angle_l" polycoef="       0        0        0        0        0"></joint>
    <joint name="mtp_angle_l_constraint" active="true" joint1="mtp_angle_l" polycoef="       0        0        0        0        0"></joint>
    <joint name="wrist_flex_r_constraint" active="true" joint1="wrist_flex_r" polycoef="       0        0        0        0        0"></joint>
    <joint name="wrist_dev_r_constraint" active="true" joint1="wrist_dev_r" polycoef="       0        0        0        0        0"></joint>
    <joint name="wrist_flex_l_constraint" active="true" joint1="wrist_flex_l" polycoef="       0        0        0        0        0"></joint>
    <joint name="wrist_dev_l_constraint" active="true" joint1="wrist_dev_l" polycoef="       0        0        0        0        0"></joint>
    <weld name="origin_to_worldbody" body1="pelvis" active="false"></weld>
  </equality>
</mujoco>
