<?xml version="1.0" encoding="utf-8"?>
<!-- This URDF was automatically created by SolidWorks to URDF Exporter! Originally created by Stephen Brawner (brawner@gmail.com) 
     Commit Version: 1.6.0-4-g7f85cfe  Build Version: 1.6.7995.38578
     For more information, please see http://wiki.ros.org/sw_urdf_exporter -->
<robot
  name="kuavo">
  <link
    name="base_link">
    <inertial>
      <origin
        xyz="-0.00699293960383802 0.00155633220268026 0.152865943474551"
        rpy="0 0 0" />
      <mass
        value="7.71324827879796" />
      <inertia
        ixx="0.0426865291658434"
        ixy="1.85724164379468E-06"
        ixz="0.0010941107421191"
        iyy="0.020412125396821"
        iyz="-3.14875771284261E-06"
        izz="0.0372747742844986" />
    </inertial>
    <visual>
      <origin
        xyz="0 0 0"
        rpy="0 0 0" />
      <geometry>
        <mesh
          filename="./meshes/base_link.STL" />
      </geometry>
      <material
        name="">
        <color
          rgba="0.862745098039216 0.933333333333333 0.929411764705882 1" />
      </material>
    </visual>
    <collision>
      <origin
        xyz="0 0 0"
        rpy="0 0 0" />
      <geometry>
        <mesh
          filename="./meshes/base_link.STL" />
      </geometry>
    </collision>
  </link>
  <link
    name="l_leg_roll">
    <inertial>
      <origin
        xyz="0.0607642758367597 0.00014034128720411 0.00228371917512799"
        rpy="0 0 0" />
      <mass
        value="0.118529537524385" />
      <inertia
        ixx="0.000100527370735922"
        ixy="-1.21001269445094E-09"
        ixz="-5.73994022636998E-06"
        iyy="0.000266846737510275"
        iyz="-1.09965529112337E-07"
        izz="0.000326428442604199" />
    </inertial>
    <visual>
      <origin
        xyz="0 0 0"
        rpy="0 0 0" />
      <geometry>
        <mesh
          filename="./meshes/l_leg_roll.STL" />
      </geometry>
      <material
        name="">
        <color
          rgba="0.862745098039216 0.933333333333333 0.929411764705882 1" />
      </material>
    </visual>
    <collision>
      <origin
        xyz="0 0 0"
        rpy="0 0 0" />
      <geometry>
        <mesh
          filename="./meshes/l_leg_roll.STL" />
      </geometry>
    </collision>
  </link>
  <joint
    name="l_leg_roll"
    type="continuous">
    <origin
      xyz="-0.0756149468145449 0.087 -0.0720754569616772"
      rpy="0 0 0" />
    <parent
      link="base_link" />
    <child
      link="l_leg_roll" />
    <axis
      xyz="-1 0 0" />
  </joint>
  <link
    name="l_leg_yaw">
    <inertial>
      <origin
        xyz="0.000290902697264877 0.0405087424467619 -0.100846923361789"
        rpy="0 0 0" />
      <mass
        value="0.20405278020544" />
      <inertia
        ixx="0.000304319732135481"
        ixy="6.81277324993593E-07"
        ixz="5.14353295201488E-07"
        iyy="0.000364082147695825"
        iyz="2.16417948537574E-06"
        izz="0.000267287713044087" />
    </inertial>
    <visual>
      <origin
        xyz="0 0 0"
        rpy="0 0 0" />
      <geometry>
        <mesh
          filename="./meshes/l_leg_yaw.STL" />
      </geometry>
      <material
        name="">
        <color
          rgba="0.862745098039216 0.933333333333333 0.929411764705882 1" />
      </material>
    </visual>
    <collision>
      <origin
        xyz="0 0 0"
        rpy="0 0 0" />
      <geometry>
        <mesh
          filename="./meshes/l_leg_yaw.STL" />
      </geometry>
    </collision>
  </link>
  <joint
    name="l_leg_yaw"
    type="continuous">
    <origin
      xyz="0.0735 0 0.0130000000000001"
      rpy="0 0 0" />
    <parent
      link="l_leg_roll" />
    <child
      link="l_leg_yaw" />
    <axis
      xyz="0 0 1" />
  </joint>
  <link
    name="l_leg_pitch">
    <inertial>
      <origin
        xyz="-0.00528235933691826 -0.0878849862537982 -0.056800998667162"
        rpy="0 0 0" />
      <mass
        value="0.45065011418642" />
      <inertia
        ixx="0.00148456678733155"
        ixy="-2.29184752662021E-05"
        ixz="0.000131476982175566"
        iyy="0.00177807990369305"
        iyz="7.48554604302084E-06"
        izz="0.000394925298656241" />
    </inertial>
    <visual>
      <origin
        xyz="0 0 0"
        rpy="0 0 0" />
      <geometry>
        <mesh
          filename="./meshes/l_leg_pitch.STL" />
      </geometry>
      <material
        name="">
        <color
          rgba="0.807843137254902 0.843137254901961 0.905882352941176 1" />
      </material>
    </visual>
    <collision>
      <origin
        xyz="0 0 0"
        rpy="0 0 0" />
      <geometry>
        <mesh
          filename="./meshes/l_leg_pitch.STL" />
      </geometry>
    </collision>
  </link>
  <joint
    name="l_leg_pitch"
    type="continuous">
    <origin
      xyz="0 0.0939999999999999 -0.13645"
      rpy="0 0 0" />
    <parent
      link="l_leg_yaw" />
    <child
      link="l_leg_pitch" />
    <axis
      xyz="0 -1 0" />
  </joint>
  <link
    name="l_knee">
    <inertial>
      <origin
        xyz="0.000868873637859806 -5.03011046766588E-05 -0.13314742049396"
        rpy="0 0 0" />
      <mass
        value="0.817175320465059" />
      <inertia
        ixx="0.00786383933470876"
        ixy="-3.13623718617422E-08"
        ixz="-7.89544117443064E-05"
        iyy="0.0081080818905141"
        iyz="-6.80654926871359E-05"
        izz="0.000441233410542845" />
    </inertial>
    <visual>
      <origin
        xyz="0 0 0"
        rpy="0 0 0" />
      <geometry>
        <mesh
          filename="./meshes/l_knee.STL" />
      </geometry>
      <material
        name="">
        <color
          rgba="0.898039215686275 0.917647058823529 0.929411764705882 1" />
      </material>
    </visual>
    <collision>
      <origin
        xyz="0 0 0"
        rpy="0 0 0" />
      <geometry>
        <mesh
          filename="./meshes/l_knee.STL" />
      </geometry>
    </collision>
  </link>
  <joint
    name="l_knee"
    type="continuous">
    <origin
      xyz="0.00413596009601052 -0.0686389599620252 -0.249965785326798"
      rpy="0 0 0" />
    <parent
      link="l_leg_pitch" />
    <child
      link="l_knee" />
    <axis
      xyz="0 1 0" />
  </joint>
  <link
    name="l_foot_pitch">
    <inertial>
      <origin
        xyz="-2.2094915482114E-07 -0.0210002209491548 0.000142421968554962"
        rpy="0 0 0" />
      <mass
        value="0.00898868764931505" />
      <inertia
        ixx="8.64757693496474E-07"
        ixy="4.38814003822459E-16"
        ixz="3.49395618884054E-11"
        iyy="8.64757693496479E-07"
        iyz="-3.54041160032427E-11"
        izz="1.52124214524266E-06" />
    </inertial>
    <visual>
      <origin
        xyz="0 0 0"
        rpy="0 0 0" />
      <geometry>
        <mesh
          filename="./meshes/l_foot_pitch.STL" />
      </geometry>
      <material
        name="">
        <color
          rgba="0.807843137254902 0.843137254901961 0.905882352941176 1" />
      </material>
    </visual>
    <collision>
      <origin
        xyz="0 0 0"
        rpy="0 0 0" />
      <geometry>
        <mesh
          filename="./meshes/l_foot_pitch.STL" />
      </geometry>
    </collision>
  </link>
  <joint
    name="l_foot_pitch"
    type="continuous">
    <origin
      xyz="9.39839333040909E-05 0.0209999999999999 -0.346142421968556"
      rpy="0 0 0" />
    <parent
      link="l_knee" />
    <child
      link="l_foot_pitch" />
    <axis
      xyz="0 -1 0" />
  </joint>
  <link
    name="l_foot_roll">
    <inertial>
      <origin
        xyz="-0.0432253086252035 -8.83109141272542E-06 -0.0231900309646781"
        rpy="0 0 0" />
      <mass
        value="0.48595336841054" />
      <inertia
        ixx="0.000157873471834251"
        ixy="1.96472635084532E-08"
        ixz="2.65605381022489E-06"
        iyy="0.000645275398662566"
        iyz="1.31456982241222E-08"
        izz="0.000765587215075718" />
    </inertial>
    <visual>
      <origin
        xyz="0 0 0"
        rpy="0 0 0" />
      <geometry>
        <mesh
          filename="./meshes/l_foot_roll.STL" />
      </geometry>
      <material
        name="">
        <color
          rgba="0.807843137254902 0.843137254901961 0.905882352941176 1" />
      </material>
    </visual>
    <collision>
      <origin
        xyz="0 0 0"
        rpy="0 0 0" />
      <geometry>
        <mesh
          filename="./meshes/l_foot_roll.STL" />
      </geometry>
    </collision>
  </link>
  <joint
    name="l_foot_roll"
    type="continuous">
    <origin
      xyz="0.021 -0.021 0.000142421968555073"
      rpy="0 0 0" />
    <parent
      link="l_foot_pitch" />
    <child
      link="l_foot_roll" />
    <axis
      xyz="-1 0 0" />
  </joint>
  <link
    name="l_l_bar">
    <inertial>
      <origin
        xyz="-0.0181620534088889 0.00538550541831453 0.00188897487292894"
        rpy="0 0 0" />
      <mass
        value="0.00874829869457794" />
      <inertia
        ixx="1.10769540266514E-06"
        ixy="-5.91415258727675E-07"
        ixz="4.29488265882082E-07"
        iyy="5.99983084859914E-06"
        iyz="6.15112516111373E-08"
        izz="5.19245227970593E-06" />
    </inertial>
    <visual>
      <origin
        xyz="0 0 0"
        rpy="0 0 0" />
      <geometry>
        <mesh
          filename="./meshes/l_l_bar.STL" />
      </geometry>
      <material
        name="">
        <color
          rgba="0.807843137254902 0.843137254901961 0.905882352941176 1" />
      </material>
    </visual>
    <collision>
      <origin
        xyz="0 0 0"
        rpy="0 0 0" />
      <geometry>
        <mesh
          filename="./meshes/l_l_bar.STL" />
      </geometry>
    </collision>
  </link>
  <joint
    name="l_l_bar"
    type="continuous">
    <origin
      xyz="9.39839333040753E-05 0.0294999999999999 -0.090000000000001"
      rpy="0 0 0" />
    <parent
      link="l_knee" />
    <child
      link="l_l_bar" />
    <axis
      xyz="0 -1 0" />
  </joint>
  <link
    name="l_l_tendon">
    <inertial>
      <origin
        xyz="0.00118321709757755 3.75294202364929E-06 -0.20744528844336"
        rpy="0 0 0" />
      <mass
        value="0.083522124317674" />
      <inertia
        ixx="0.000108457869310121"
        ixy="6.02846811569308E-13"
        ixz="3.21348766559881E-09"
        iyy="0.000108256478541275"
        iyz="-5.12951685911342E-08"
        izz="3.33663310062301E-06" />
    </inertial>
    <visual>
      <origin
        xyz="0 0 0"
        rpy="0 0 0" />
      <geometry>
        <mesh
          filename="./meshes/l_l_tendon.STL" />
      </geometry>
      <material
        name="">
        <color
          rgba="0.807843137254902 0.843137254901961 0.905882352941176 1" />
      </material>
    </visual>
    <collision>
      <origin
        xyz="0 0 0"
        rpy="0 0 0" />
      <geometry>
        <mesh
          filename="./meshes/l_l_tendon.STL" />
      </geometry>
    </collision>
  </link>
  <joint
    name="l_l_tendon"
    type="continuous">
    <origin
      xyz="-0.0576888204074241 -0.00450000000000017 0.00599999999999978"
      rpy="0 0 0" />
    <parent
      link="l_l_bar" />
    <child
      link="l_l_tendon" />
    <axis
      xyz="0 1 0" />
  </joint>
  <link
    name="l_r_bar">
    <inertial>
      <origin
        xyz="-0.0181620475591471 -0.00340146093872844 0.00188896088462942"
        rpy="0 0 0" />
      <mass
        value="0.00874829655091912" />
      <inertia
        ixx="1.10769463312904E-06"
        ixy="5.9141495517061E-07"
        ixz="4.29484605237304E-07"
        iyy="5.99982880791329E-06"
        iyz="-6.15105156434383E-08"
        izz="5.19245102488259E-06" />
    </inertial>
    <visual>
      <origin
        xyz="0 0 0"
        rpy="0 0 0" />
      <geometry>
        <mesh
          filename="./meshes/l_r_bar.STL" />
      </geometry>
      <material
        name="">
        <color
          rgba="0.807843137254902 0.843137254901961 0.905882352941176 1" />
      </material>
    </visual>
    <collision>
      <origin
        xyz="0 0 0"
        rpy="0 0 0" />
      <geometry>
        <mesh
          filename="./meshes/l_r_bar.STL" />
      </geometry>
    </collision>
  </link>
  <joint
    name="l_r_bar"
    type="continuous">
    <origin
      xyz="9.39839333042539E-05 -0.0295 -0.153000000000001"
      rpy="0 0 0" />
    <parent
      link="l_knee" />
    <child
      link="l_r_bar" />
    <axis
      xyz="0 1 0" />
  </joint>
  <link
    name="l_r_tendon">
    <inertial>
      <origin
        xyz="0.00127016481106113 -0.000442399471844768 -0.157756039462114"
        rpy="0 0 0" />
      <mass
        value="0.0780668768936421" />
      <inertia
        ixx="4.62186588509114E-05"
        ixy="-1.94286496924929E-08"
        ixz="-2.70858374718146E-09"
        iyy="4.61278857103081E-05"
        iyz="3.66611708941701E-08"
        izz="3.1548728466647E-06" />
    </inertial>
    <visual>
      <origin
        xyz="0 0 0"
        rpy="0 0 0" />
      <geometry>
        <mesh
          filename="./meshes/l_r_tendon.STL" />
      </geometry>
      <material
        name="">
        <color
          rgba="0.807843137254902 0.843137254901961 0.905882352941176 1" />
      </material>
    </visual>
    <collision>
      <origin
        xyz="0 0 0"
        rpy="0 0 0" />
      <geometry>
        <mesh
          filename="./meshes/l_r_tendon.STL" />
      </geometry>
    </collision>
  </link>
  <joint
    name="l_r_tendon"
    type="continuous">
    <origin
      xyz="-0.0576888204074239 0.00508602348130947 0.00600000000000012"
      rpy="0 0 0" />
    <parent
      link="l_r_bar" />
    <child
      link="l_r_tendon" />
    <axis
      xyz="0 -1 0" />
  </joint>
  <link
    name="r_leg_roll">
    <inertial>
      <origin
        xyz="0.0607646044341523 -0.000140365546816248 0.00228377101431822"
        rpy="0 0 0" />
      <mass
        value="0.11853067519234" />
      <inertia
        ixx="0.000100528224800769"
        ixy="8.59267223920867E-10"
        ixz="-5.7400764839374E-06"
        iyy="0.000266849167485496"
        iyz="1.09990636769441E-07"
        izz="0.000326431795353994" />
    </inertial>
    <visual>
      <origin
        xyz="0 0 0"
        rpy="0 0 0" />
      <geometry>
        <mesh
          filename="./meshes/r_leg_roll.STL" />
      </geometry>
      <material
        name="">
        <color
          rgba="0.807843137254902 0.843137254901961 0.905882352941176 1" />
      </material>
    </visual>
    <collision>
      <origin
        xyz="0 0 0"
        rpy="0 0 0" />
      <geometry>
        <mesh
          filename="./meshes/r_leg_roll.STL" />
      </geometry>
    </collision>
  </link>
  <joint
    name="r_leg_roll"
    type="continuous">
    <origin
      xyz="-0.0756149468145449 -0.087 -0.0720754569616772"
      rpy="0 0 0" />
    <parent
      link="base_link" />
    <child
      link="r_leg_roll" />
    <axis
      xyz="-1 0 0" />
  </joint>
  <link
    name="r_leg_yaw">
    <inertial>
      <origin
        xyz="0.000290901694932051 -0.0405086843275825 -0.100847259224443"
        rpy="0 0 0" />
      <mass
        value="0.204051628397563" />
      <inertia
        ixx="0.000304316594072443"
        ixy="-6.81313422907994E-07"
        ixz="5.14348465322562E-07"
        iyy="0.000364082222889467"
        iyz="-2.16425891305065E-06"
        izz="0.000267284560559922" />
    </inertial>
    <visual>
      <origin
        xyz="0 0 0"
        rpy="0 0 0" />
      <geometry>
        <mesh
          filename="./meshes/r_leg_yaw.STL" />
      </geometry>
      <material
        name="">
        <color
          rgba="0.862745098039216 0.933333333333333 0.929411764705882 1" />
      </material>
    </visual>
    <collision>
      <origin
        xyz="0 0 0"
        rpy="0 0 0" />
      <geometry>
        <mesh
          filename="./meshes/r_leg_yaw.STL" />
      </geometry>
    </collision>
  </link>
  <joint
    name="r_leg_yaw"
    type="continuous">
    <origin
      xyz="0.0735 0 0.0130000000000001"
      rpy="0 0 0" />
    <parent
      link="r_leg_roll" />
    <child
      link="r_leg_yaw" />
    <axis
      xyz="0 0 1" />
  </joint>
  <link
    name="r_leg_pitch">
    <inertial>
      <origin
        xyz="-0.00530844800069375 0.0879625104980525 -0.0562054035446188"
        rpy="0 0 0" />
      <mass
        value="0.448539615819603" />
      <inertia
        ixx="0.00148436919411102"
        ixy="2.29187023974564E-05"
        ixz="0.000131477003903541"
        iyy="0.00177802513573774"
        iyz="-7.48524907415416E-06"
        izz="0.000394727717573666" />
    </inertial>
    <visual>
      <origin
        xyz="0 0 0"
        rpy="0 0 0" />
      <geometry>
        <mesh
          filename="./meshes/r_leg_pitch.STL" />
      </geometry>
      <material
        name="">
        <color
          rgba="0.807843137254902 0.843137254901961 0.905882352941176 1" />
      </material>
    </visual>
    <collision>
      <origin
        xyz="0 0 0"
        rpy="0 0 0" />
      <geometry>
        <mesh
          filename="./meshes/r_leg_pitch.STL" />
      </geometry>
    </collision>
  </link>
  <joint
    name="r_leg_pitch"
    type="continuous">
    <origin
      xyz="0 -0.094 -0.13645"
      rpy="0 0 0" />
    <parent
      link="r_leg_yaw" />
    <child
      link="r_leg_pitch" />
    <axis
      xyz="0 -1 0" />
  </joint>
  <link
    name="r_knee">
    <inertial>
      <origin
        xyz="0.000566315767979653 -0.000357175271787927 -0.138852368476045"
        rpy="0 0 0" />
      <mass
        value="0.345443991337626" />
      <inertia
        ixx="0.00281310613866549"
        ixy="1.11070732712115E-08"
        ixz="-2.80899108975025E-05"
        iyy="0.00291126127187274"
        iyz="2.42218525823218E-05"
        izz="0.000171958211692171" />
    </inertial>
    <visual>
      <origin
        xyz="0 0 0"
        rpy="0 0 0" />
      <geometry>
        <mesh
          filename="./meshes/r_knee.STL" />
      </geometry>
      <material
        name="">
        <color
          rgba="0.807843137254902 0.843137254901961 0.905882352941176 1" />
      </material>
    </visual>
    <collision>
      <origin
        xyz="0 0 0"
        rpy="0 0 0" />
      <geometry>
        <mesh
          filename="./meshes/r_knee.STL" />
      </geometry>
    </collision>
  </link>
  <joint
    name="r_knee"
    type="continuous">
    <origin
      xyz="0.00413596009601069 0.0685500000000013 -0.249965785326798"
      rpy="0 0 0" />
    <parent
      link="r_leg_pitch" />
    <child
      link="r_knee" />
    <axis
      xyz="0 -1 0" />
  </joint>
  <link
    name="r_foot_pitch">
    <inertial>
      <origin
        xyz="-2.20949154776037E-07 0.0210002209491547 -1.11022302462516E-16"
        rpy="0 0 0" />
      <mass
        value="0.00898868764931501" />
      <inertia
        ixx="8.64757693496473E-07"
        ixy="-4.38813261088375E-16"
        ixz="-3.4939561888581E-11"
        iyy="8.64757693496477E-07"
        iyz="-3.44750077743079E-11"
        izz="1.52124214524266E-06" />
    </inertial>
    <visual>
      <origin
        xyz="0 0 0"
        rpy="0 0 0" />
      <geometry>
        <mesh
          filename="./meshes/r_foot_pitch.STL" />
      </geometry>
      <material
        name="">
        <color
          rgba="0.807843137254902 0.843137254901961 0.905882352941176 1" />
      </material>
    </visual>
    <collision>
      <origin
        xyz="0 0 0"
        rpy="0 0 0" />
      <geometry>
        <mesh
          filename="./meshes/r_foot_pitch.STL" />
      </geometry>
    </collision>
  </link>
  <joint
    name="r_foot_pitch"
    type="continuous">
    <origin
      xyz="0 -0.021 -0.346000000000001"
      rpy="0 0 0" />
    <parent
      link="r_knee" />
    <child
      link="r_foot_pitch" />
    <axis
      xyz="0 -1 0" />
  </joint>
  <link
    name="r_foot_roll">
    <inertial>
      <origin
        xyz="-0.0480333310327909 6.50581714088661E-06 -0.0208399753329805"
        rpy="0 0 0" />
      <mass
        value="0.235882377040623" />
      <inertia
        ixx="7.44704948330087E-05"
        ixy="-1.32306351261624E-08"
        ixz="2.64137221389746E-06"
        iyy="0.000241939144027172"
        iyz="-4.67780047970378E-09"
        izz="0.000291936005980864" />
    </inertial>
    <visual>
      <origin
        xyz="0 0 0"
        rpy="0 0 0" />
      <geometry>
        <mesh
          filename="./meshes/r_foot_roll.STL" />
      </geometry>
      <material
        name="">
        <color
          rgba="0.807843137254902 0.843137254901961 0.905882352941176 1" />
      </material>
    </visual>
    <collision>
      <origin
        xyz="0 0 0"
        rpy="0 0 0" />
      <geometry>
        <mesh
          filename="./meshes/r_foot_roll.STL" />
      </geometry>
    </collision>
  </link>
  <joint
    name="r_foot_roll"
    type="continuous">
    <origin
      xyz="0.021 0.0209999999999999 0"
      rpy="0 0 0" />
    <parent
      link="r_foot_pitch" />
    <child
      link="r_foot_roll" />
    <axis
      xyz="-1 0 0" />
  </joint>
  <link
    name="r_r_bar">
    <inertial>
      <origin
        xyz="-0.0181620509501376 -0.0054502400147324 0.00188897513882791"
        rpy="0 0 0" />
      <mass
        value="0.00874829774758129" />
      <inertia
        ixx="1.10769527904973E-06"
        ixy="5.91415050956591E-07"
        ixz="4.29488315443609E-07"
        iyy="5.99983036821144E-06"
        iyz="-6.15112771413719E-08"
        izz="5.19245168309842E-06" />
    </inertial>
    <visual>
      <origin
        xyz="0 0 0"
        rpy="0 0 0" />
      <geometry>
        <mesh
          filename="./meshes/r_r_bar.STL" />
      </geometry>
      <material
        name="">
        <color
          rgba="0.807843137254902 0.843137254901961 0.905882352941176 1" />
      </material>
    </visual>
    <collision>
      <origin
        xyz="0 0 0"
        rpy="0 0 0" />
      <geometry>
        <mesh
          filename="./meshes/r_r_bar.STL" />
      </geometry>
    </collision>
  </link>
  <joint
    name="r_r_bar"
    type="continuous">
    <origin
      xyz="0 -0.0294999999999999 -0.0900000000000002"
      rpy="0 0 0" />
    <parent
      link="r_knee" />
    <child
      link="r_r_bar" />
    <axis
      xyz="0 -1 0" />
  </joint>
  <link
    name="r_r_tendon">
    <inertial>
      <origin
        xyz="0.000958289233327532 -8.67055798317584E-06 -0.188485184943548"
        rpy="0 0 0" />
      <mass
        value="0.053802691494778" />
      <inertia
        ixx="0.000105952067897388"
        ixy="-6.66037719249754E-13"
        ixz="3.21302195385029E-09"
        iyy="0.000105645697160704"
        iyz="5.12952984445406E-08"
        izz="2.0950392625887E-06" />
    </inertial>
    <visual>
      <origin
        xyz="0 0 0"
        rpy="0 0 0" />
      <geometry>
        <mesh
          filename="./meshes/r_r_tendon.STL" />
      </geometry>
      <material
        name="">
        <color
          rgba="0.807843137254902 0.843137254901961 0.905882352941176 1" />
      </material>
    </visual>
    <collision>
      <origin
        xyz="0 0 0"
        rpy="0 0 0" />
      <geometry>
        <mesh
          filename="./meshes/r_r_tendon.STL" />
      </geometry>
    </collision>
  </link>
  <joint
    name="r_r_tendon"
    type="continuous">
    <origin
      xyz="-0.0576888204074261 0.00450000000000034 0.00599999999999878"
      rpy="0 0 0" />
    <parent
      link="r_r_bar" />
    <child
      link="r_r_tendon" />
    <axis
      xyz="0 1 0" />
  </joint>
  <link
    name="r_l_bar">
    <inertial>
      <origin
        xyz="-0.018162043904016 0.00326676157003555 0.00188895977905879"
        rpy="0 0 0" />
      <mass
        value="0.00874829521108898" />
      <inertia
        ixx="1.10769435536613E-06"
        ixy="-5.91414611386556E-07"
        ixz="4.29484364884761E-07"
        iyy="5.99982796081405E-06"
        iyz="6.15104069682222E-08"
        izz="5.19245005096644E-06" />
    </inertial>
    <visual>
      <origin
        xyz="0 0 0"
        rpy="0 0 0" />
      <geometry>
        <mesh
          filename="./meshes/r_l_bar.STL" />
      </geometry>
      <material
        name="">
        <color
          rgba="0.807843137254902 0.843137254901961 0.905882352941176 1" />
      </material>
    </visual>
    <collision>
      <origin
        xyz="0 0 0"
        rpy="0 0 0" />
      <geometry>
        <mesh
          filename="./meshes/r_l_bar.STL" />
      </geometry>
    </collision>
  </link>
  <joint
    name="r_l_bar"
    type="continuous">
    <origin
      xyz="0 0.0294999999999999 -0.153000000000001"
      rpy="0 0 0" />
    <parent
      link="r_knee" />
    <child
      link="r_l_bar" />
    <axis
      xyz="0 -1 0" />
  </joint>
  <link
    name="r_l_tendon">
    <inertial>
      <origin
        xyz="0.00106510158954519 9.64944022313619E-06 -0.144838777247632"
        rpy="0 0 0" />
      <mass
        value="0.0483474436719092" />
      <inertia
        ixx="4.37091223763635E-05"
        ixy="-9.08749132597724E-13"
        ixz="-2.70856208055644E-09"
        iyy="4.35208260635416E-05"
        iyz="-3.66615376299583E-08"
        izz="1.91327900390017E-06" />
    </inertial>
    <visual>
      <origin
        xyz="0 0 0"
        rpy="0 0 0" />
      <geometry>
        <mesh
          filename="./meshes/r_l_tendon.STL" />
      </geometry>
      <material
        name="">
        <color
          rgba="0.807843137254902 0.843137254901961 0.905882352941176 1" />
      </material>
    </visual>
    <collision>
      <origin
        xyz="0 0 0"
        rpy="0 0 0" />
      <geometry>
        <mesh
          filename="./meshes/r_l_tendon.STL" />
      </geometry>
    </collision>
  </link>
  <joint
    name="r_l_tendon"
    type="continuous">
    <origin
      xyz="-0.0576888204074239 -0.00449999999999988 0.00600000000000001"
      rpy="0 0 0" />
    <parent
      link="r_l_bar" />
    <child
      link="r_l_tendon" />
    <axis
      xyz="0 1 0" />
  </joint>
  <link
    name="l_arm_pitch">
    <inertial>
      <origin
        xyz="0.0214306014937492 0.0894803474436048 0.000615912525740503"
        rpy="0 0 0" />
      <mass
        value="0.0855565384250596" />
      <inertia
        ixx="0.000130680980046145"
        ixy="-2.8051476508872E-05"
        ixz="-4.43154983770371E-08"
        iyy="6.72732423481097E-05"
        iyz="-1.04235209424077E-06"
        izz="0.000113833719965484" />
    </inertial>
    <visual>
      <origin
        xyz="0 0 0"
        rpy="0 0 0" />
      <geometry>
        <mesh
          filename="./meshes/l_arm_pitch.STL" />
      </geometry>
      <material
        name="">
        <color
          rgba="1 1 1 1" />
      </material>
    </visual>
    <collision>
      <origin
        xyz="0 0 0"
        rpy="0 0 0" />
      <geometry>
        <mesh
          filename="./meshes/l_arm_pitch.STL" />
      </geometry>
    </collision>
  </link>
  <joint
    name="l_arm_pitch"
    type="continuous">
    <origin
      xyz="-0.0174998525199999 0.121 0.3145"
      rpy="0 0 0" />
    <parent
      link="base_link" />
    <child
      link="l_arm_pitch" />
    <axis
      xyz="0 1 0" />
  </joint>
  <link
    name="l_arm_roll">
    <inertial>
      <origin
        xyz="-0.035737115963316 0.000637394005623571 -0.00293587457508399"
        rpy="0 0 0" />
      <mass
        value="0.243859089022774" />
      <inertia
        ixx="0.000128360157970662"
        ixy="6.10295766830323E-06"
        ixz="-1.04763903813656E-05"
        iyy="0.000190119380770336"
        iyz="1.1072652385836E-06"
        izz="0.000178903820792462" />
    </inertial>
    <visual>
      <origin
        xyz="0 0 0"
        rpy="0 0 0" />
      <geometry>
        <mesh
          filename="./meshes/l_arm_roll.STL" />
      </geometry>
      <material
        name="">
        <color
          rgba="1 1 1 1" />
      </material>
    </visual>
    <collision>
      <origin
        xyz="0 0 0"
        rpy="0 0 0" />
      <geometry>
        <mesh
          filename="./meshes/l_arm_roll.STL" />
      </geometry>
    </collision>
  </link>
  <joint
    name="l_arm_roll"
    type="continuous">
    <origin
      xyz="0.0638750000000005 0.143475 0"
      rpy="0 0 0" />
    <parent
      link="l_arm_pitch" />
    <child
      link="l_arm_roll" />
    <axis
      xyz="-1 0 0" />
  </joint>
  <link
    name="l_arm_yaw">
    <inertial>
      <origin
        xyz="-0.000196754553523828 -0.00200221985054488 -0.0822363960198868"
        rpy="0 0 0" />
      <mass
        value="0.231645925727573" />
      <inertia
        ixx="7.15763821808342E-05"
        ixy="-7.20357840527445E-07"
        ixz="1.2879634524044E-07"
        iyy="0.000116064001916274"
        iyz="-3.24539663479111E-06"
        izz="0.000102450224641922" />
    </inertial>
    <visual>
      <origin
        xyz="0 0 0"
        rpy="0 0 0" />
      <geometry>
        <mesh
          filename="./meshes/l_arm_yaw.STL" />
      </geometry>
      <material
        name="">
        <color
          rgba="1 1 1 1" />
      </material>
    </visual>
    <collision>
      <origin
        xyz="0 0 0"
        rpy="0 0 0" />
      <geometry>
        <mesh
          filename="./meshes/l_arm_yaw.STL" />
      </geometry>
    </collision>
  </link>
  <joint
    name="l_arm_yaw"
    type="continuous">
    <origin
      xyz="-0.0436732904500001 -0.000228544867618807 -0.0507499999999994"
      rpy="0 0 0" />
    <parent
      link="l_arm_roll" />
    <child
      link="l_arm_yaw" />
    <axis
      xyz="0 0.0045033014816499 0.999989860086474" />
  </joint>
  <link
    name="l_forearm_pitch">
    <inertial>
      <origin
        xyz="-1.76621857590764E-09 0.0247675246684128 -0.070263864959373"
        rpy="0 0 0" />
      <mass
        value="0.100717925891199" />
      <inertia
        ixx="6.81753177964767E-05"
        ixy="-1.3166203212202E-12"
        ixz="-2.01946859234465E-12"
        iyy="6.38358674774755E-05"
        iyz="1.22265699624491E-05"
        izz="7.39768830554407E-05" />
    </inertial>
    <visual>
      <origin
        xyz="0 0 0"
        rpy="0 0 0" />
      <geometry>
        <mesh
          filename="./meshes/l_forearm_pitch.STL" />
      </geometry>
      <material
        name="">
        <color
          rgba="1 1 1 1" />
      </material>
    </visual>
    <collision>
      <origin
        xyz="0 0 0"
        rpy="0 0 0" />
      <geometry>
        <mesh
          filename="./meshes/l_forearm_pitch.STL" />
      </geometry>
    </collision>
  </link>
  <joint
    name="l_forearm_pitch"
    type="continuous">
    <origin
      xyz="0 -0.0300214551323814 -0.1357"
      rpy="0 0 0" />
    <parent
      link="l_arm_yaw" />
    <child
      link="l_forearm_pitch" />
    <axis
      xyz="0 1 0" />
  </joint>
  <link
    name="l_forearm_yaw">
    <inertial>
      <origin
        xyz="-0.00399570091504528 2.98471488309193E-05 -0.0656133809823523"
        rpy="0 0 0" />
      <mass
        value="0.156174407901059" />
      <inertia
        ixx="7.01872239868571E-05"
        ixy="-1.62696734264376E-07"
        ixz="-4.54392258182991E-07"
        iyy="7.29165229929418E-05"
        iyz="-7.2325873682261E-09"
        izz="6.87979464480365E-05" />
    </inertial>
    <visual>
      <origin
        xyz="0 0 0"
        rpy="0 0 0" />
      <geometry>
        <mesh
          filename="./meshes/l_forearm_yaw.STL" />
      </geometry>
      <material
        name="">
        <color
          rgba="1 1 1 1" />
      </material>
    </visual>
    <collision>
      <origin
        xyz="0 0 0"
        rpy="0 0 0" />
      <geometry>
        <mesh
          filename="./meshes/l_forearm_yaw.STL" />
      </geometry>
    </collision>
  </link>
  <joint
    name="l_forearm_yaw"
    type="continuous">
    <origin
      xyz="0 0.0302500000000002 -0.0915499999999999"
      rpy="0 0 0" />
    <parent
      link="l_forearm_pitch" />
    <child
      link="l_forearm_yaw" />
    <axis
      xyz="0 0 -1" />
  </joint>
  <link
    name="l_hand_roll">
    <inertial>
      <origin
        xyz="0.0166010838376317 1.21699082866744E-07 1.73724289204147E-07"
        rpy="0 0 0" />
      <mass
        value="0.00225080087545489" />
      <inertia
        ixx="1.93486939049626E-07"
        ixy="1.34751407910019E-12"
        ixz="-9.12379114183907E-13"
        iyy="1.3659940311531E-07"
        iyz="2.34311788925342E-12"
        izz="3.17250990444323E-07" />
    </inertial>
    <visual>
      <origin
        xyz="0 0 0"
        rpy="0 0 0" />
      <geometry>
        <mesh
          filename="./meshes/l_hand_roll.STL" />
      </geometry>
      <material
        name="">
        <color
          rgba="1 1 1 1" />
      </material>
    </visual>
    <collision>
      <origin
        xyz="0 0 0"
        rpy="0 0 0" />
      <geometry>
        <mesh
          filename="./meshes/l_hand_roll.STL" />
      </geometry>
    </collision>
  </link>
  <joint
    name="l_hand_roll"
    type="continuous">
    <origin
      xyz="-0.025322 0 -0.1575"
      rpy="0 0 0" />
    <parent
      link="l_forearm_yaw" />
    <child
      link="l_hand_roll" />
    <axis
      xyz="-1 0 0" />
  </joint>
  <link
    name="l_hand_pitch">
    <inertial>
      <origin
        xyz="0.00216452934621551 -6.77719551251399E-05 -0.0859772405742664"
        rpy="0 0 0" />
      <mass
        value="0.0531311255846087" />
      <inertia
        ixx="1.140633456061E-05"
        ixy="-1.76559662166693E-10"
        ixz="2.91544414425806E-07"
        iyy="1.10990606835989E-05"
        iyz="-7.83300192322812E-10"
        izz="8.19218367742265E-06" />
    </inertial>
    <visual>
      <origin
        xyz="0 0 0"
        rpy="0 0 0" />
      <geometry>
        <mesh
          filename="./meshes/l_hand_pitch.STL" />
      </geometry>
      <material
        name="">
        <color
          rgba="1 1 1 1" />
      </material>
    </visual>
    <collision>
      <origin
        xyz="0 0 0"
        rpy="0 0 0" />
      <geometry>
        <mesh
          filename="./meshes/l_hand_pitch.STL" />
      </geometry>
    </collision>
  </link>
  <joint
    name="l_hand_pitch"
    type="continuous">
    <origin
      xyz="0.02137 0 0"
      rpy="0 0 0" />
    <parent
      link="l_hand_roll" />
    <child
      link="l_hand_pitch" />
    <axis
      xyz="-1 0 0" />
  </joint>
  <link
    name="l_l_arm_bar">
    <inertial>
      <origin
        xyz="-0.00554151988939612 -0.00107110718268377 8.01142280862713E-05"
        rpy="0 0 0" />
      <mass
        value="0.000933425350872019" />
      <inertia
        ixx="1.3843779735052E-08"
        ixy="5.67273670990801E-09"
        ixz="5.77608583056801E-10"
        iyy="6.06871251723769E-08"
        iyz="-8.20112615845596E-11"
        izz="5.37887818257275E-08" />
    </inertial>
    <visual>
      <origin
        xyz="0 0 0"
        rpy="0 0 0" />
      <geometry>
        <mesh
          filename="./meshes/l_l_arm_bar.STL" />
      </geometry>
      <material
        name="">
        <color
          rgba="1 1 1 1" />
      </material>
    </visual>
    <collision>
      <origin
        xyz="0 0 0"
        rpy="0 0 0" />
      <geometry>
        <mesh
          filename="./meshes/l_l_arm_bar.STL" />
      </geometry>
    </collision>
  </link>
  <joint
    name="l_l_arm_bar"
    type="continuous">
    <origin
      xyz="0.011299999998424 0.024140000000002 -0.0759999999999971"
      rpy="0 0 0" />
    <parent
      link="l_forearm_yaw" />
    <child
      link="l_l_arm_bar" />
    <axis
      xyz="0 -1 0" />
  </joint>
  <link
    name="l_l_arm_tendon">
    <inertial>
      <origin
        xyz="-0.00762563841089457 -0.000122279190808594 -0.0407419941889383"
        rpy="0 0 0" />
      <mass
        value="0.00374681809424582" />
      <inertia
        ixx="2.52757930323661E-06"
        ixy="-7.66111459785821E-10"
        ixz="-4.64401918338811E-07"
        iyy="2.64303514729516E-06"
        iyz="-4.31242332569496E-09"
        izz="1.3308429935593E-07" />
    </inertial>
    <visual>
      <origin
        xyz="0 0 0"
        rpy="0 0 0" />
      <geometry>
        <mesh
          filename="./meshes/l_l_arm_tendon.STL" />
      </geometry>
      <material
        name="">
        <color
          rgba="1 1 1 1" />
      </material>
    </visual>
    <collision>
      <origin
        xyz="0 0 0"
        rpy="0 0 0" />
      <geometry>
        <mesh
          filename="./meshes/l_l_arm_tendon.STL" />
      </geometry>
    </collision>
  </link>
  <joint
    name="l_l_arm_tendon"
    type="continuous">
    <origin
      xyz="-0.0159983282022835 0.0040000013363603 0.000231289282113974"
      rpy="0 0 0" />
    <parent
      link="l_l_arm_bar" />
    <child
      link="l_l_arm_tendon" />
    <axis
      xyz="0 1 0" />
  </joint>
  <link
    name="l_r_arm_bar">
    <inertial>
      <origin
        xyz="-0.00554152091378026 0.00107110716137979 8.00466218583845E-05"
        rpy="0 0 0" />
      <mass
        value="0.00093342533722621" />
      <inertia
        ixx="1.38437655830521E-08"
        ixy="-5.67273763127159E-09"
        ixz="5.77122731416829E-10"
        iyy="6.06871249427678E-08"
        iyz="8.19421766658822E-11"
        izz="5.37887956605657E-08" />
    </inertial>
    <visual>
      <origin
        xyz="0 0 0"
        rpy="0 0 0" />
      <geometry>
        <mesh
          filename="./meshes/l_r_arm_bar.STL" />
      </geometry>
      <material
        name="">
        <color
          rgba="1 1 1 1" />
      </material>
    </visual>
    <collision>
      <origin
        xyz="0 0 0"
        rpy="0 0 0" />
      <geometry>
        <mesh
          filename="./meshes/l_r_arm_bar.STL" />
      </geometry>
    </collision>
  </link>
  <joint
    name="l_r_arm_bar"
    type="continuous">
    <origin
      xyz="0.011300000004892 -0.024139999999997 -0.1145"
      rpy="0 0 0" />
    <parent
      link="l_forearm_yaw" />
    <child
      link="l_r_arm_bar" />
    <axis
      xyz="0 1 0" />
  </joint>
  <link
    name="l_r_arm_tendon">
    <inertial>
      <origin
        xyz="-0.00762833305911307 0.000142795973133963 -0.021488685180072"
        rpy="0 0 0" />
      <mass
        value="0.00269247094438198" />
      <inertia
        ixx="5.94953509692986E-07"
        ixy="9.09691856035781E-10"
        ixz="-1.9636524665428E-07"
        iyy="6.93164854255937E-07"
        iyz="1.78985741267607E-09"
        izz="1.11074492400416E-07" />
    </inertial>
    <visual>
      <origin
        xyz="0 0 0"
        rpy="0 0 0" />
      <geometry>
        <mesh
          filename="./meshes/l_r_arm_tendon.STL" />
      </geometry>
      <material
        name="">
        <color
          rgba="1 1 1 1" />
      </material>
    </visual>
    <collision>
      <origin
        xyz="0 0 0"
        rpy="0 0 0" />
      <geometry>
        <mesh
          filename="./meshes/l_r_arm_tendon.STL" />
      </geometry>
    </collision>
  </link>
  <joint
    name="l_r_arm_tendon"
    type="continuous">
    <origin
      xyz="-0.0159983310229197 -0.00400002806712421 0.000231094095741222"
      rpy="0 0 0" />
    <parent
      link="l_r_arm_bar" />
    <child
      link="l_r_arm_tendon" />
    <axis
      xyz="0 -1 0" />
  </joint>
  <link
    name="r_arm_pitch">
    <inertial>
      <origin
        xyz="0.0214306041026405 -0.0844803465442086 0.00061581470811356"
        rpy="0 0 0" />
      <mass
        value="0.0855564935505709" />
      <inertia
        ixx="0.000130680921242486"
        ixy="2.80514667713823E-05"
        ixz="-4.43612197682304E-08"
        iyy="6.72732085095452E-05"
        iyz="1.04250551958736E-06"
        izz="0.000113833677598239" />
    </inertial>
    <visual>
      <origin
        xyz="0 0 0"
        rpy="0 0 0" />
      <geometry>
        <mesh
          filename="./meshes/r_arm_pitch.STL" />
      </geometry>
      <material
        name="">
        <color
          rgba="1 1 1 1" />
      </material>
    </visual>
    <collision>
      <origin
        xyz="0 0 0"
        rpy="0 0 0" />
      <geometry>
        <mesh
          filename="./meshes/r_arm_pitch.STL" />
      </geometry>
    </collision>
  </link>
  <joint
    name="r_arm_pitch"
    type="continuous">
    <origin
      xyz="-0.0174998525199999 -0.126 0.3145"
      rpy="0 0 0" />
    <parent
      link="base_link" />
    <child
      link="r_arm_pitch" />
    <axis
      xyz="0 -1 0" />
  </joint>
  <link
    name="r_arm_roll">
    <inertial>
      <origin
        xyz="-0.0357371168973825 -0.000637394797891544 -0.00293587513361748"
        rpy="0 0 0" />
      <mass
        value="0.24385908133804" />
      <inertia
        ixx="0.000128360143073782"
        ixy="-6.10295800980191E-06"
        ixz="-1.0476390047817E-05"
        iyy="0.000190119367974024"
        iyz="-1.10726166060552E-06"
        izz="0.000178903821203388" />
    </inertial>
    <visual>
      <origin
        xyz="0 0 0"
        rpy="0 0 0" />
      <geometry>
        <mesh
          filename="./meshes/r_arm_roll.STL" />
      </geometry>
      <material
        name="">
        <color
          rgba="1 1 1 1" />
      </material>
    </visual>
    <collision>
      <origin
        xyz="0 0 0"
        rpy="0 0 0" />
      <geometry>
        <mesh
          filename="./meshes/r_arm_roll.STL" />
      </geometry>
    </collision>
  </link>
  <joint
    name="r_arm_roll"
    type="continuous">
    <origin
      xyz="0.0638750000000006 -0.138475 0"
      rpy="0 0 0" />
    <parent
      link="r_arm_pitch" />
    <child
      link="r_arm_roll" />
    <axis
      xyz="-1 0 0" />
  </joint>
  <link
    name="r_arm_yaw">
    <inertial>
      <origin
        xyz="-0.000194980244391281 0.00223075394549077 -0.0832363148203375"
        rpy="0 0 0" />
      <mass
        value="0.231645950350007" />
      <inertia
        ixx="7.15747672025054E-05"
        ixy="7.20299540431296E-07"
        ixz="1.30045936565256E-07"
        iyy="0.00011606243891087"
        iyz="3.24540546737595E-06"
        izz="0.000102450220317482" />
    </inertial>
    <visual>
      <origin
        xyz="0 0 0"
        rpy="0 0 0" />
      <geometry>
        <mesh
          filename="./meshes/r_arm_yaw.STL" />
      </geometry>
      <material
        name="">
        <color
          rgba="1 1 1 1" />
      </material>
    </visual>
    <collision>
      <origin
        xyz="0 0 0"
        rpy="0 0 0" />
      <geometry>
        <mesh
          filename="./meshes/r_arm_yaw.STL" />
      </geometry>
    </collision>
  </link>
  <joint
    name="r_arm_yaw"
    type="continuous">
    <origin
      xyz="-0.0436749999999998 0 -0.0497499999999998"
      rpy="0 0 0" />
    <parent
      link="r_arm_roll" />
    <child
      link="r_arm_yaw" />
    <axis
      xyz="0 0 -1" />
  </joint>
  <link
    name="r_forearm_pitch">
    <inertial>
      <origin
        xyz="7.1803206297405E-09 -0.0235362732742576 -0.0656063288648233"
        rpy="0 0 0" />
      <mass
        value="0.082246913288193" />
      <inertia
        ixx="6.24507314646795E-05"
        ixy="-6.49100177668853E-12"
        ixz="3.722894079977E-12"
        iyy="5.81112784382459E-05"
        iyz="-1.22265695808957E-05"
        izz="6.2829761531135E-05" />
    </inertial>
    <visual>
      <origin
        xyz="0 0 0"
        rpy="0 0 0" />
      <geometry>
        <mesh
          filename="./meshes/r_forearm_pitch.STL" />
      </geometry>
      <material
        name="">
        <color
          rgba="1 1 1 1" />
      </material>
    </visual>
    <collision>
      <origin
        xyz="0 0 0"
        rpy="0 0 0" />
      <geometry>
        <mesh
          filename="./meshes/r_forearm_pitch.STL" />
      </geometry>
    </collision>
  </link>
  <joint
    name="r_forearm_pitch"
    type="continuous">
    <origin
      xyz="0 0.0302500000000003 -0.1377"
      rpy="0 0 0" />
    <parent
      link="r_arm_yaw" />
    <child
      link="r_forearm_pitch" />
    <axis
      xyz="0 -1 0" />
  </joint>
  <link
    name="r_forearm_yaw">
    <inertial>
      <origin
        xyz="-0.00399571587295026 -2.98574044384492E-05 -0.0656134416270269"
        rpy="0 0 0" />
      <mass
        value="0.156174142689454" />
      <inertia
        ixx="7.01871005830262E-05"
        ixy="1.62591814390724E-07"
        ixz="-4.54374332575993E-07"
        iyy="7.29165016216887E-05"
        iyz="7.3578843890099E-09"
        izz="6.87978478315219E-05" />
    </inertial>
    <visual>
      <origin
        xyz="0 0 0"
        rpy="0 0 0" />
      <geometry>
        <mesh
          filename="./meshes/r_forearm_yaw.STL" />
      </geometry>
      <material
        name="">
        <color
          rgba="1 1 1 1" />
      </material>
    </visual>
    <collision>
      <origin
        xyz="0 0 0"
        rpy="0 0 0" />
      <geometry>
        <mesh
          filename="./meshes/r_forearm_yaw.STL" />
      </geometry>
    </collision>
  </link>
  <joint
    name="r_forearm_yaw"
    type="continuous">
    <origin
      xyz="0 -0.0302500000000002 -0.0905499999999999"
      rpy="0 0 0" />
    <parent
      link="r_forearm_pitch" />
    <child
      link="r_forearm_yaw" />
    <axis
      xyz="0 0 1" />
  </joint>
  <link
    name="r_hand_roll">
    <inertial>
      <origin
        xyz="0.0166010838484253 -1.21914575379467E-07 -1.70258151493963E-07"
        rpy="0 0 0" />
      <mass
        value="0.00225080086305129" />
      <inertia
        ixx="1.93486938959377E-07"
        ixy="-1.35418412773771E-12"
        ixz="9.16670576988079E-13"
        iyy="1.36599402900294E-07"
        iyz="2.34295717847431E-12"
        izz="3.17250989285096E-07" />
    </inertial>
    <visual>
      <origin
        xyz="0 0 0"
        rpy="0 0 0" />
      <geometry>
        <mesh
          filename="./meshes/r_hand_roll.STL" />
      </geometry>
      <material
        name="">
        <color
          rgba="1 1 1 1" />
      </material>
    </visual>
    <collision>
      <origin
        xyz="0 0 0"
        rpy="0 0 0" />
      <geometry>
        <mesh
          filename="./meshes/r_hand_roll.STL" />
      </geometry>
    </collision>
  </link>
  <joint
    name="r_hand_roll"
    type="continuous">
    <origin
      xyz="-0.025322 0 -0.1575"
      rpy="0 0 0" />
    <parent
      link="r_forearm_yaw" />
    <child
      link="r_hand_roll" />
    <axis
      xyz="-1 0 0" />
  </joint>
  <link
    name="r_hand_pitch">
    <inertial>
      <origin
        xyz="0.00214702310217297 -7.83584216464961E-05 -0.0852818706514631"
        rpy="0 0 0" />
      <mass
        value="0.0535643416316945" />
      <inertia
        ixx="1.14121247582596E-05"
        ixy="1.76471512895622E-10"
        ixz="2.91544422581543E-07"
        iyy="1.11095803968485E-05"
        iyz="7.83308829804773E-10"
        izz="8.19797394000677E-06" />
    </inertial>
    <visual>
      <origin
        xyz="0 0 0"
        rpy="0 0 0" />
      <geometry>
        <mesh
          filename="./meshes/r_hand_pitch.STL" />
      </geometry>
      <material
        name="">
        <color
          rgba="1 1 1 1" />
      </material>
    </visual>
    <collision>
      <origin
        xyz="0 0 0"
        rpy="0 0 0" />
      <geometry>
        <mesh
          filename="./meshes/r_hand_pitch.STL" />
      </geometry>
    </collision>
  </link>
  <joint
    name="r_hand_pitch"
    type="continuous">
    <origin
      xyz="0.02137 0 0"
      rpy="0 0 0" />
    <parent
      link="r_hand_roll" />
    <child
      link="r_hand_pitch" />
    <axis
      xyz="0 1 0" />
  </joint>
  <link
    name="r_r_arm_bar">
    <inertial>
      <origin
        xyz="-0.00554151967108991 0.00107110730201643 8.01148413552277E-05"
        rpy="0 0 0" />
      <mass
        value="0.000933425431007405" />
      <inertia
        ixx="1.38437799892514E-08"
        ixy="-5.67273704047732E-09"
        ixz="5.77606254446982E-10"
        iyy="6.06871256289307E-08"
        iyz="8.20102664432749E-11"
        izz="5.37887825241999E-08" />
    </inertial>
    <visual>
      <origin
        xyz="0 0 0"
        rpy="0 0 0" />
      <geometry>
        <mesh
          filename="./meshes/r_r_arm_bar.STL" />
      </geometry>
      <material
        name="">
        <color
          rgba="1 1 1 1" />
      </material>
    </visual>
    <collision>
      <origin
        xyz="0 0 0"
        rpy="0 0 0" />
      <geometry>
        <mesh
          filename="./meshes/r_r_arm_bar.STL" />
      </geometry>
    </collision>
  </link>
  <joint
    name="r_r_arm_bar"
    type="continuous">
    <origin
      xyz="0.0112999999984239 -0.024140000000002 -0.0759999999999971"
      rpy="0 0 0" />
    <parent
      link="r_forearm_yaw" />
    <child
      link="r_r_arm_bar" />
    <axis
      xyz="0 1 0" />
  </joint>
  <link
    name="r_r_arm_tendon">
    <inertial>
      <origin
        xyz="-0.00765635531259815 0.000132036112088063 -0.0409092469907192"
        rpy="0 0 0" />
      <mass
        value="0.00373178797597326" />
      <inertia
        ixx="2.52754726727089E-06"
        ixy="7.66038091816824E-10"
        ixz="-4.64401938883845E-07"
        iyy="2.64294079486177E-06"
        iyz="4.31244533041838E-09"
        izz="1.33020958334864E-07" />
    </inertial>
    <visual>
      <origin
        xyz="0 0 0"
        rpy="0 0 0" />
      <geometry>
        <mesh
          filename="./meshes/r_r_arm_tendon.STL" />
      </geometry>
      <material
        name="">
        <color
          rgba="1 1 1 1" />
      </material>
    </visual>
    <collision>
      <origin
        xyz="0 0 0"
        rpy="0 0 0" />
      <geometry>
        <mesh
          filename="./meshes/r_r_arm_tendon.STL" />
      </geometry>
    </collision>
  </link>
  <joint
    name="r_r_arm_tendon"
    type="continuous">
    <origin
      xyz="-0.0159983282022835 -0.0040000013363603 0.000231289282113974"
      rpy="0 0 0" />
    <parent
      link="r_r_arm_bar" />
    <child
      link="r_r_arm_tendon" />
    <axis
      xyz="0 1 0" />
  </joint>
  <link
    name="r_l_arm_bar">
    <inertial>
      <origin
        xyz="-0.00554152066507212 -0.00107110729779245 8.00460209587489E-05"
        rpy="0 0 0" />
      <mass
        value="0.000933425428650283" />
      <inertia
        ixx="1.38437660740365E-08"
        ixy="5.67273800803533E-09"
        ixz="5.77125012060783E-10"
        iyy="6.06871256776918E-08"
        iyz="-8.19431480269537E-11"
        izz="5.37887964707832E-08" />
    </inertial>
    <visual>
      <origin
        xyz="0 0 0"
        rpy="0 0 0" />
      <geometry>
        <mesh
          filename="./meshes/r_l_arm_bar.STL" />
      </geometry>
      <material
        name="">
        <color
          rgba="1 1 1 1" />
      </material>
    </visual>
    <collision>
      <origin
        xyz="0 0 0"
        rpy="0 0 0" />
      <geometry>
        <mesh
          filename="./meshes/r_l_arm_bar.STL" />
      </geometry>
    </collision>
  </link>
  <joint
    name="r_l_arm_bar"
    type="continuous">
    <origin
      xyz="0.0113000000048921 0.024139999999997 -0.1145"
      rpy="0 0 0" />
    <parent
      link="r_forearm_yaw" />
    <child
      link="r_l_arm_bar" />
    <axis
      xyz="0 -1 0" />
  </joint>
  <link
    name="r_l_arm_tendon">
    <inertial>
      <origin
        xyz="-0.00762999220333973 -0.000169588775282475 -0.0214971867253593"
        rpy="0 0 0" />
      <mass
        value="0.0026624084343365" />
      <inertia
        ixx="5.94886471341227E-07"
        ixy="-9.09725188142654E-10"
        ixz="-1.96376428049484E-07"
        iyy="6.92975761839731E-07"
        iyz="-1.78984774648677E-09"
        izz="1.1095058280343E-07" />
    </inertial>
    <visual>
      <origin
        xyz="0 0 0"
        rpy="0 0 0" />
      <geometry>
        <mesh
          filename="./meshes/r_l_arm_tendon.STL" />
      </geometry>
      <material
        name="">
        <color
          rgba="1 1 1 1" />
      </material>
    </visual>
    <collision>
      <origin
        xyz="0 0 0"
        rpy="0 0 0" />
      <geometry>
        <mesh
          filename="./meshes/r_l_arm_tendon.STL" />
      </geometry>
    </collision>
  </link>
  <joint
    name="r_l_arm_tendon"
    type="continuous">
    <origin
      xyz="-0.0159983310229197 0.00400002806712421 0.000231094095741222"
      rpy="0 0 0" />
    <parent
      link="r_l_arm_bar" />
    <child
      link="r_l_arm_tendon" />
    <axis
      xyz="0 -1 0" />
  </joint>
  <link
    name="real_camera_link">
    <inertial>
      <origin
        xyz="-0.00921266315655753 -0.00134236481905095 -0.000223201290186881"
        rpy="0 0 0" />
      <mass
        value="0.0173287679990781" />
      <inertia
        ixx="1.14349973374258E-05"
        ixy="-1.05355726979727E-07"
        ixz="-1.05868132715497E-08"
        iyy="9.5531115778752E-07"
        iyz="-1.61190264385732E-08"
        izz="1.07055967101248E-05" />
    </inertial>
    <visual>
      <origin
        xyz="0 0 0"
        rpy="0 0 0" />
      <geometry>
        <mesh
          filename="./meshes/real_camera_link.STL" />
      </geometry>
      <material
        name="">
        <color
          rgba="0.8 0.2 0.2 1" />
      </material>
    </visual>
    <collision>
      <origin
        xyz="0 0 0"
        rpy="0 0 0" />
      <geometry>
        <mesh
          filename="./meshes/real_camera_link.STL" />
      </geometry>
    </collision>
  </link>
  <joint
    name="camera_joint"
    type="fixed">
    <origin
      xyz="0.078507 0.0026635 0.47328"
      rpy="0 0.61087 0" />
    <parent
      link="base_link" />
    <child
      link="real_camera_link" />
    <axis
      xyz="0 0 0" />
  </joint>
</robot>